Workbook
Name DeuNom: 'DEUDAS'!$C$8:$C$17
Name DeuSal: 'DEUDAS'!$P$8:$P$17
Name DeuCuota: 'DEUDAS'!$Q$8:$Q$17
Name RankA: 'DEUDAS'!$R$8:$R$17
Name RankB: 'DEUDAS'!$S$8:$S$17
Name DeuTasa: 'DEUDAS'!$T$8:$T$17
Name PresTot: 'DEUDAS'!$H$21
Name NombrePlan: 'AJUSTES'!$C$7
Name Moneda: 'AJUSTES'!$C$8
Name InicioEf: 'AJUSTES'!$C$10
Name ListaTipo: 'AJUSTES'!$B$14:$B$21
Name Estrat: 'PANEL'!$C$6
Name Extra: 'PANEL'!$H$6
Name EstrN: 'PANEL'!$P$6
Name MesesSel: 'PANEL'!$P$7
Name IntSel: 'PANEL'!$P$8
Name IntMin: 'PANEL'!$P$9
Name MesesMin: 'PANEL'!$P$10

Sheet PANEL
F1: PLANIFICADOR PARA SALIR DE DEUDAS
B2: Herramientas inteligentes que simplifican tu vida. | F2: Tu camino hacia cero, de un vistazo
C4: Cargá tus deudas en DEUDAS. Acá elegís la estrategia y el pago extra, y el panel te muestra cuándo quedás libre.
B5: + Anotar deudas | E5: Vencimientos | G5: Plan mes a mes | I5: Ajustes | K5: Ayuda
B6: Estrategia: | C6: Avalancha (tasa más alta) | F6: Pago extra por mes: | H6: 0 | J6: ← probá subir el extra y mirá cuánto adelantás | P6: =IF(LEFT(C6,2)="Av",1,2)
P7: =CHOOSE(EstrN,SIM_AVALANCHA!$AN$2,SIM_BOLA!$AN$2)
B8: DEUDA TOTAL HOY | E8: PAGO MENSUAL TOTAL | H8: LIBRE DE DEUDAS EN | K8: AHORRO EN INTERESES | P8: =CHOOSE(EstrN,SIM_AVALANCHA!$AN$3,SIM_BOLA!$AN$3)
B9: =SUM(DeuSal) | E9: =PresTot | H9: =IF(SUM(DeuSal)<=0,"-",IF(MesesSel>=999,"+10 años",DATE(YEAR(InicioEf),MONTH(InicioEf)+MesesSel-1,1))) | K9: =IF(OR(SUM(DeuSal)<=0,MesesMin>=999),"-",MAX(0,IntMin-IntSel)) | P9: =SIM_MINIMOS!$AN$3
B10: =Moneda | E10: cuotas + pago extra | H10: =IF(SUM(DeuSal)<=0,"",IF(MesesSel>=999,"con este pago no alcanza","en "&MesesSel&" mes(es)")) | K10: =IF(MesesMin>=999,"tus cuotas solas no terminan la deuda","frente a pagar solo los mínimos") | P10: =SIM_MINIMOS!$AN$2
B12: INTERESES DE ESTE MES | E12: TASA PROMEDIO ANUAL | H12: PRÓXIMO VENCIMIENTO | K12: PROGRESO
B13: =SUMPRODUCT(DeuSal,DeuTasa)/12 | E13: =IFERROR(SUMPRODUCT(DeuSal,DeuTasa)/SUM(DeuSal),0) | H13: =IF(COUNT(DEUDAS!$U$8:$U$17)=0,"-",INDEX(DeuNom,MATCH(MIN(DEUDAS!$U$8:$U$17),DEUDAS!$U$8:$U$17,0))&" · "&DAY(MIN(DEUDAS!$U$8:$U$17))&"/"&MONTH(MIN(DEUDAS!$U$8:$U$17))) | K13: =IF(SUM(DEUDAS!$E$8:$E$17)<=0,"-",MAX(0,1-SUMIFS(DEUDAS!$F$8:$F$17,DEUDAS!$E$8:$E$17,">0")/SUM(DEUDAS!$E$8:$E$17)))
B14: lo que te cobran por mes | E14: ponderada por saldo | H14: =IF(COUNT(DEUDAS!$U$8:$U$17)=0,"","en "&(MIN(DEUDAS!$U$8:$U$17)-TODAY())&" día(s)") | K14: de tus deudas ya está pagado
B16: =IF(SUM(DeuSal)<=0,"Cargá tus deudas en la hoja DEUDAS para ver tu plan.",IF(COUNTIF(DEUDAS!$M$8:$M$17,"⚠*")>0,"⚠ Revisá DEUDAS: hay una cuota que no cubre el interés o que falta cargar. Subí la cuota o el pago extra.",IF(MesesSel>=999,"⚠ Con este pago no terminás de pagar en 10 años. Probá subir el pago extra.","✔ Con este plan quedás libre de deudas en "&MesesSel&" mes(es)."&IF(MesesMin>=999,""," Ahorrás "&FIXED(MAX(0,IntMin-IntSel),0)&" "&Moneda&" en intereses frente a pagar solo los mínimos."))))
B18: TRES FORMAS DE PAGAR · compará cuánto tardás y cuánto pagás de intereses
B19: Forma de pagar | E19: Meses | F19: Libre de deudas | H19: Intereses totales | J19: Total pagado | L19: Ahorro de intereses
B20: Avalancha (tasa más alta primero) | E20: =IF(SUM(DeuSal)<=0,"-",IF(SIM_AVALANCHA!$AN$2>=999,"+120",SIM_AVALANCHA!$AN$2)) | F20: =IF(SUM(DeuSal)<=0,"-",IF(SIM_AVALANCHA!$AN$2>=999,"+10 años",DATE(YEAR(InicioEf),MONTH(InicioEf)+SIM_AVALANCHA!$AN$2-1,1))) | H20: =SIM_AVALANCHA!$AN$3 | J20: =SIM_AVALANCHA!$AN$4 | L20: =IF(SIM_MINIMOS!$AN$2>=999,"-",MAX(0,SIM_MINIMOS!$AN$3-SIM_AVALANCHA!$AN$3))
B21: Bola de nieve (deuda más chica primero) | E21: =IF(SUM(DeuSal)<=0,"-",IF(SIM_BOLA!$AN$2>=999,"+120",SIM_BOLA!$AN$2)) | F21: =IF(SUM(DeuSal)<=0,"-",IF(SIM_BOLA!$AN$2>=999,"+10 años",DATE(YEAR(InicioEf),MONTH(InicioEf)+SIM_BOLA!$AN$2-1,1))) | H21: =SIM_BOLA!$AN$3 | J21: =SIM_BOLA!$AN$4 | L21: =IF(SIM_MINIMOS!$AN$2>=999,"-",MAX(0,SIM_MINIMOS!$AN$3-SIM_BOLA!$AN$3))
B22: Solo pagar los mínimos | E22: =IF(SUM(DeuSal)<=0,"-",IF(SIM_MINIMOS!$AN$2>=999,"+120",SIM_MINIMOS!$AN$2)) | F22: =IF(SUM(DeuSal)<=0,"-",IF(SIM_MINIMOS!$AN$2>=999,"+10 años",DATE(YEAR(InicioEf),MONTH(InicioEf)+SIM_MINIMOS!$AN$2-1,1))) | H22: =SIM_MINIMOS!$AN$3 | J22: =SIM_MINIMOS!$AN$4 | L22: -
B23: La fila en verde es la estrategia que elegiste arriba. Si «Solo mínimos» marca +10 años, esas cuotas no alcanzan para terminar de pagar.
B40: ="ORDEN DE PAGO · "&IF(EstrN=1,"Avalancha","Bola de nieve")
B41: Prio. | C41: Deuda | E41: Saldo | F41: Tasa | G41: Termina en
B42: =IF(OR($P42=0,N(INDEX(DeuSal,MAX(1,$P42)))<=0),"",1) | C42: =IF($B42="","",INDEX(DeuNom,$P42)&"") | E42: =IF($B42="","",INDEX(DeuSal,$P42)) | F42: =IF($B42="","",INDEX(DeuTasa,$P42)) | G42: =IF($B42="","",IF(CHOOSE(EstrN,SIM_AVALANCHA!C$8,SIM_BOLA!C$8)>=999,"+10 años","mes "&CHOOSE(EstrN,SIM_AVALANCHA!C$8,SIM_BOLA!C$8))) | P42: =CHOOSE(EstrN,SIM_AVALANCHA!C$3,SIM_BOLA!C$3)
B43: =IF(OR($P43=0,N(INDEX(DeuSal,MAX(1,$P43)))<=0),"",2) | C43: =IF($B43="","",INDEX(DeuNom,$P43)&"") | E43: =IF($B43="","",INDEX(DeuSal,$P43)) | F43: =IF($B43="","",INDEX(DeuTasa,$P43)) | G43: =IF($B43="","",IF(CHOOSE(EstrN,SIM_AVALANCHA!D$8,SIM_BOLA!D$8)>=999,"+10 años","mes "&CHOOSE(EstrN,SIM_AVALANCHA!D$8,SIM_BOLA!D$8))) | P43: =CHOOSE(EstrN,SIM_AVALANCHA!D$3,SIM_BOLA!D$3)
B44: =IF(OR($P44=0,N(INDEX(DeuSal,MAX(1,$P44)))<=0),"",3) | C44: =IF($B44="","",INDEX(DeuNom,$P44)&"") | E44: =IF($B44="","",INDEX(DeuSal,$P44)) | F44: =IF($B44="","",INDEX(DeuTasa,$P44)) | G44: =IF($B44="","",IF(CHOOSE(EstrN,SIM_AVALANCHA!E$8,SIM_BOLA!E$8)>=999,"+10 años","mes "&CHOOSE(EstrN,SIM_AVALANCHA!E$8,SIM_BOLA!E$8))) | P44: =CHOOSE(EstrN,SIM_AVALANCHA!E$3,SIM_BOLA!E$3)
B45: =IF(OR($P45=0,N(INDEX(DeuSal,MAX(1,$P45)))<=0),"",4) | C45: =IF($B45="","",INDEX(DeuNom,$P45)&"") | E45: =IF($B45="","",INDEX(DeuSal,$P45)) | F45: =IF($B45="","",INDEX(DeuTasa,$P45)) | G45: =IF($B45="","",IF(CHOOSE(EstrN,SIM_AVALANCHA!F$8,SIM_BOLA!F$8)>=999,"+10 años","mes "&CHOOSE(EstrN,SIM_AVALANCHA!F$8,SIM_BOLA!F$8))) | P45: =CHOOSE(EstrN,SIM_AVALANCHA!F$3,SIM_BOLA!F$3)
B46: =IF(OR($P46=0,N(INDEX(DeuSal,MAX(1,$P46)))<=0),"",5) | C46: =IF($B46="","",INDEX(DeuNom,$P46)&"") | E46: =IF($B46="","",INDEX(DeuSal,$P46)) | F46: =IF($B46="","",INDEX(DeuTasa,$P46)) | G46: =IF($B46="","",IF(CHOOSE(EstrN,SIM_AVALANCHA!G$8,SIM_BOLA!G$8)>=999,"+10 años","mes "&CHOOSE(EstrN,SIM_AVALANCHA!G$8,SIM_BOLA!G$8))) | P46: =CHOOSE(EstrN,SIM_AVALANCHA!G$3,SIM_BOLA!G$3)
B47: =IF(OR($P47=0,N(INDEX(DeuSal,MAX(1,$P47)))<=0),"",6) | C47: =IF($B47="","",INDEX(DeuNom,$P47)&"") | E47: =IF($B47="","",INDEX(DeuSal,$P47)) | F47: =IF($B47="","",INDEX(DeuTasa,$P47)) | G47: =IF($B47="","",IF(CHOOSE(EstrN,SIM_AVALANCHA!H$8,SIM_BOLA!H$8)>=999,"+10 años","mes "&CHOOSE(EstrN,SIM_AVALANCHA!H$8,SIM_BOLA!H$8))) | P47: =CHOOSE(EstrN,SIM_AVALANCHA!H$3,SIM_BOLA!H$3)
B48: =IF(OR($P48=0,N(INDEX(DeuSal,MAX(1,$P48)))<=0),"",7) | C48: =IF($B48="","",INDEX(DeuNom,$P48)&"") | E48: =IF($B48="","",INDEX(DeuSal,$P48)) | F48: =IF($B48="","",INDEX(DeuTasa,$P48)) | G48: =IF($B48="","",IF(CHOOSE(EstrN,SIM_AVALANCHA!I$8,SIM_BOLA!I$8)>=999,"+10 años","mes "&CHOOSE(EstrN,SIM_AVALANCHA!I$8,SIM_BOLA!I$8))) | P48: =CHOOSE(EstrN,SIM_AVALANCHA!I$3,SIM_BOLA!I$3)
B49: =IF(OR($P49=0,N(INDEX(DeuSal,MAX(1,$P49)))<=0),"",8) | C49: =IF($B49="","",INDEX(DeuNom,$P49)&"") | E49: =IF($B49="","",INDEX(DeuSal,$P49)) | F49: =IF($B49="","",INDEX(DeuTasa,$P49)) | G49: =IF($B49="","",IF(CHOOSE(EstrN,SIM_AVALANCHA!J$8,SIM_BOLA!J$8)>=999,"+10 años","mes "&CHOOSE(EstrN,SIM_AVALANCHA!J$8,SIM_BOLA!J$8))) | P49: =CHOOSE(EstrN,SIM_AVALANCHA!J$3,SIM_BOLA!J$3)
B50: =IF(OR($P50=0,N(INDEX(DeuSal,MAX(1,$P50)))<=0),"",9) | C50: =IF($B50="","",INDEX(DeuNom,$P50)&"") | E50: =IF($B50="","",INDEX(DeuSal,$P50)) | F50: =IF($B50="","",INDEX(DeuTasa,$P50)) | G50: =IF($B50="","",IF(CHOOSE(EstrN,SIM_AVALANCHA!K$8,SIM_BOLA!K$8)>=999,"+10 años","mes "&CHOOSE(EstrN,SIM_AVALANCHA!K$8,SIM_BOLA!K$8))) | P50: =CHOOSE(EstrN,SIM_AVALANCHA!K$3,SIM_BOLA!K$3)
B51: =IF(OR($P51=0,N(INDEX(DeuSal,MAX(1,$P51)))<=0),"",10) | C51: =IF($B51="","",INDEX(DeuNom,$P51)&"") | E51: =IF($B51="","",INDEX(DeuSal,$P51)) | F51: =IF($B51="","",INDEX(DeuTasa,$P51)) | G51: =IF($B51="","",IF(CHOOSE(EstrN,SIM_AVALANCHA!L$8,SIM_BOLA!L$8)>=999,"+10 años","mes "&CHOOSE(EstrN,SIM_AVALANCHA!L$8,SIM_BOLA!L$8))) | P51: =CHOOSE(EstrN,SIM_AVALANCHA!L$3,SIM_BOLA!L$3)
B52: TOTAL | E52: =SUM(E42:E51)
B54: Avalancha: te ahorra más intereses. Bola de nieve: cerrás deudas chicas rápido y eso motiva. Las dos funcionan: la mejor es la que vas a sostener.
B57: MIX SHOP DIGITAL · Herramientas inteligentes que simplifican tu vida.
B58: Versión gratuita · Más herramientas gratuitas para tu vida diaria → mixshopdigital.com.py

Sheet DEUDAS
E1: DEUDAS
B2: Herramientas inteligentes que simplifican tu vida. | E2: Anotá todo lo que debés
C4: Una fila por deuda. Completá las celdas amarillas: el saldo, la tasa y la cuota alcanzan para armar tu plan.
B5: ← Volver al PANEL | E5: Vencimientos | G5: Ajustes
B7: N° | C7: Deuda | D7: Tipo | E7: Monto original (opcional) | F7: Saldo actual (lo que debés hoy) | G7: Tasa anual | H7: Cuota mínima por mes | I7: Vence el día | J7: ¿Pagaste este mes? | K7: Interés de este mes | L7: Meses con solo la cuota | M7: Aviso
B8: 1 | K8: =IF($P8>0,ROUND($P8*$T8/12,0),"") | L8: =IF($P8<=0,"",IF($Q8<=0,"Sin cuota",IF($Q8<=$P8*$T8/12,"No termina",IF($T8=0,ROUNDUP($P8/$Q8,0),ROUNDUP(-LN(1-$P8*($T8/12)/$Q8)/LN(1+$T8/12),0))))) | M8: =IF(AND($C8="",$P8<=0),"",IF($P8<=0,"Sin saldo: no se tiene en cuenta",IF($Q8<=0,"⚠ Falta la cuota mínima",IF($Q8<=$P8*$T8/12,"⚠ La cuota no cubre el interés","✔ Listo")))) | P8: =N(F8) | Q8: =IF(P8>0,N(H8),0) | R8: =IF(P8>0,1+COUNTIFS($P$8:$P$17,">0",$T$8:$T$17,">"&T8)+COUNTIFS($P$8:$P$17,">0",$T$8:$T$17,T8,$B$8:$B$17,"<"&B8),COUNTIF($P$8:$P$17,">0")+COUNTIFS($P$8:$P$17,"<=0",$B$8:$B$17,"<="&B8)) | S8: =IF(P8>0,1+COUNTIFS($P$8:$P$17,">0",$P$8:$P$17,"<"&P8)+COUNTIFS($P$8:$P$17,P8,$B$8:$B$17,"<"&B8),COUNTIF($P$8:$P$17,">0")+COUNTIFS($P$8:$P$17,"<=0",$B$8:$B$17,"<="&B8)) | T8: =N(G8) | U8: =IF(OR(P8<=0,N(I8)<=0),"",IF(DATE(YEAR(TODAY()),MONTH(TODAY()),MIN(I8,DAY(DATE(YEAR(TODAY()),MONTH(TODAY())+1,0))))>=TODAY(),DATE(YEAR(TODAY()),MONTH(TODAY()),MIN(I8,DAY(DATE(YEAR(TODAY()),MONTH(TODAY())+1,0)))),DATE(YEAR(TODAY()),MONTH(TODAY())+1,MIN(I8,DAY(DATE(YEAR(TODAY()),MONTH(TODAY())+2,0))))))
B9: 2 | K9: =IF($P9>0,ROUND($P9*$T9/12,0),"") | L9: =IF($P9<=0,"",IF($Q9<=0,"Sin cuota",IF($Q9<=$P9*$T9/12,"No termina",IF($T9=0,ROUNDUP($P9/$Q9,0),ROUNDUP(-LN(1-$P9*($T9/12)/$Q9)/LN(1+$T9/12),0))))) | M9: =IF(AND($C9="",$P9<=0),"",IF($P9<=0,"Sin saldo: no se tiene en cuenta",IF($Q9<=0,"⚠ Falta la cuota mínima",IF($Q9<=$P9*$T9/12,"⚠ La cuota no cubre el interés","✔ Listo")))) | P9: =N(F9) | Q9: =IF(P9>0,N(H9),0) | R9: =IF(P9>0,1+COUNTIFS($P$8:$P$17,">0",$T$8:$T$17,">"&T9)+COUNTIFS($P$8:$P$17,">0",$T$8:$T$17,T9,$B$8:$B$17,"<"&B9),COUNTIF($P$8:$P$17,">0")+COUNTIFS($P$8:$P$17,"<=0",$B$8:$B$17,"<="&B9)) | S9: =IF(P9>0,1+COUNTIFS($P$8:$P$17,">0",$P$8:$P$17,"<"&P9)+COUNTIFS($P$8:$P$17,P9,$B$8:$B$17,"<"&B9),COUNTIF($P$8:$P$17,">0")+COUNTIFS($P$8:$P$17,"<=0",$B$8:$B$17,"<="&B9)) | T9: =N(G9) | U9: =IF(OR(P9<=0,N(I9)<=0),"",IF(DATE(YEAR(TODAY()),MONTH(TODAY()),MIN(I9,DAY(DATE(YEAR(TODAY()),MONTH(TODAY())+1,0))))>=TODAY(),DATE(YEAR(TODAY()),MONTH(TODAY()),MIN(I9,DAY(DATE(YEAR(TODAY()),MONTH(TODAY())+1,0)))),DATE(YEAR(TODAY()),MONTH(TODAY())+1,MIN(I9,DAY(DATE(YEAR(TODAY()),MONTH(TODAY())+2,0))))))
B10: 3 | K10: =IF($P10>0,ROUND($P10*$T10/12,0),"") | L10: =IF($P10<=0,"",IF($Q10<=0,"Sin cuota",IF($Q10<=$P10*$T10/12,"No termina",IF($T10=0,ROUNDUP($P10/$Q10,0),ROUNDUP(-LN(1-$P10*($T10/12)/$Q10)/LN(1+$T10/12),0))))) | M10: =IF(AND($C10="",$P10<=0),"",IF($P10<=0,"Sin saldo: no se tiene en cuenta",IF($Q10<=0,"⚠ Falta la cuota mínima",IF($Q10<=$P10*$T10/12,"⚠ La cuota no cubre el interés","✔ Listo")))) | P10: =N(F10) | Q10: =IF(P10>0,N(H10),0) | R10: =IF(P10>0,1+COUNTIFS($P$8:$P$17,">0",$T$8:$T$17,">"&T10)+COUNTIFS($P$8:$P$17,">0",$T$8:$T$17,T10,$B$8:$B$17,"<"&B10),COUNTIF($P$8:$P$17,">0")+COUNTIFS($P$8:$P$17,"<=0",$B$8:$B$17,"<="&B10)) | S10: =IF(P10>0,1+COUNTIFS($P$8:$P$17,">0",$P$8:$P$17,"<"&P10)+COUNTIFS($P$8:$P$17,P10,$B$8:$B$17,"<"&B10),COUNTIF($P$8:$P$17,">0")+COUNTIFS($P$8:$P$17,"<=0",$B$8:$B$17,"<="&B10)) | T10: =N(G10) | U10: =IF(OR(P10<=0,N(I10)<=0),"",IF(DATE(YEAR(TODAY()),MONTH(TODAY()),MIN(I10,DAY(DATE(YEAR(TODAY()),MONTH(TODAY())+1,0))))>=TODAY(),DATE(YEAR(TODAY()),MONTH(TODAY()),MIN(I10,DAY(DATE(YEAR(TODAY()),MONTH(TODAY())+1,0)))),DATE(YEAR(TODAY()),MONTH(TODAY())+1,MIN(I10,DAY(DATE(YEAR(TODAY()),MONTH(TODAY())+2,0))))))
B11: 4 | K11: =IF($P11>0,ROUND($P11*$T11/12,0),"") | L11: =IF($P11<=0,"",IF($Q11<=0,"Sin cuota",IF($Q11<=$P11*$T11/12,"No termina",IF($T11=0,ROUNDUP($P11/$Q11,0),ROUNDUP(-LN(1-$P11*($T11/12)/$Q11)/LN(1+$T11/12),0))))) | M11: =IF(AND($C11="",$P11<=0),"",IF($P11<=0,"Sin saldo: no se tiene en cuenta",IF($Q11<=0,"⚠ Falta la cuota mínima",IF($Q11<=$P11*$T11/12,"⚠ La cuota no cubre el interés","✔ Listo")))) | P11: =N(F11) | Q11: =IF(P11>0,N(H11),0) | R11: =IF(P11>0,1+COUNTIFS($P$8:$P$17,">0",$T$8:$T$17,">"&T11)+COUNTIFS($P$8:$P$17,">0",$T$8:$T$17,T11,$B$8:$B$17,"<"&B11),COUNTIF($P$8:$P$17,">0")+COUNTIFS($P$8:$P$17,"<=0",$B$8:$B$17,"<="&B11)) | S11: =IF(P11>0,1+COUNTIFS($P$8:$P$17,">0",$P$8:$P$17,"<"&P11)+COUNTIFS($P$8:$P$17,P11,$B$8:$B$17,"<"&B11),COUNTIF($P$8:$P$17,">0")+COUNTIFS($P$8:$P$17,"<=0",$B$8:$B$17,"<="&B11)) | T11: =N(G11) | U11: =IF(OR(P11<=0,N(I11)<=0),"",IF(DATE(YEAR(TODAY()),MONTH(TODAY()),MIN(I11,DAY(DATE(YEAR(TODAY()),MONTH(TODAY())+1,0))))>=TODAY(),DATE(YEAR(TODAY()),MONTH(TODAY()),MIN(I11,DAY(DATE(YEAR(TODAY()),MONTH(TODAY())+1,0)))),DATE(YEAR(TODAY()),MONTH(TODAY())+1,MIN(I11,DAY(DATE(YEAR(TODAY()),MONTH(TODAY())+2,0))))))
B12: 5 | K12: =IF($P12>0,ROUND($P12*$T12/12,0),"") | L12: =IF($P12<=0,"",IF($Q12<=0,"Sin cuota",IF($Q12<=$P12*$T12/12,"No termina",IF($T12=0,ROUNDUP($P12/$Q12,0),ROUNDUP(-LN(1-$P12*($T12/12)/$Q12)/LN(1+$T12/12),0))))) | M12: =IF(AND($C12="",$P12<=0),"",IF($P12<=0,"Sin saldo: no se tiene en cuenta",IF($Q12<=0,"⚠ Falta la cuota mínima",IF($Q12<=$P12*$T12/12,"⚠ La cuota no cubre el interés","✔ Listo")))) | P12: =N(F12) | Q12: =IF(P12>0,N(H12),0) | R12: =IF(P12>0,1+COUNTIFS($P$8:$P$17,">0",$T$8:$T$17,">"&T12)+COUNTIFS($P$8:$P$17,">0",$T$8:$T$17,T12,$B$8:$B$17,"<"&B12),COUNTIF($P$8:$P$17,">0")+COUNTIFS($P$8:$P$17,"<=0",$B$8:$B$17,"<="&B12)) | S12: =IF(P12>0,1+COUNTIFS($P$8:$P$17,">0",$P$8:$P$17,"<"&P12)+COUNTIFS($P$8:$P$17,P12,$B$8:$B$17,"<"&B12),COUNTIF($P$8:$P$17,">0")+COUNTIFS($P$8:$P$17,"<=0",$B$8:$B$17,"<="&B12)) | T12: =N(G12) | U12: =IF(OR(P12<=0,N(I12)<=0),"",IF(DATE(YEAR(TODAY()),MONTH(TODAY()),MIN(I12,DAY(DATE(YEAR(TODAY()),MONTH(TODAY())+1,0))))>=TODAY(),DATE(YEAR(TODAY()),MONTH(TODAY()),MIN(I12,DAY(DATE(YEAR(TODAY()),MONTH(TODAY())+1,0)))),DATE(YEAR(TODAY()),MONTH(TODAY())+1,MIN(I12,DAY(DATE(YEAR(TODAY()),MONTH(TODAY())+2,0))))))
B13: 6 | K13: =IF($P13>0,ROUND($P13*$T13/12,0),"") | L13: =IF($P13<=0,"",IF($Q13<=0,"Sin cuota",IF($Q13<=$P13*$T13/12,"No termina",IF($T13=0,ROUNDUP($P13/$Q13,0),ROUNDUP(-LN(1-$P13*($T13/12)/$Q13)/LN(1+$T13/12),0))))) | M13: =IF(AND($C13="",$P13<=0),"",IF($P13<=0,"Sin saldo: no se tiene en cuenta",IF($Q13<=0,"⚠ Falta la cuota mínima",IF($Q13<=$P13*$T13/12,"⚠ La cuota no cubre el interés","✔ Listo")))) | P13: =N(F13) | Q13: =IF(P13>0,N(H13),0) | R13: =IF(P13>0,1+COUNTIFS($P$8:$P$17,">0",$T$8:$T$17,">"&T13)+COUNTIFS($P$8:$P$17,">0",$T$8:$T$17,T13,$B$8:$B$17,"<"&B13),COUNTIF($P$8:$P$17,">0")+COUNTIFS($P$8:$P$17,"<=0",$B$8:$B$17,"<="&B13)) | S13: =IF(P13>0,1+COUNTIFS($P$8:$P$17,">0",$P$8:$P$17,"<"&P13)+COUNTIFS($P$8:$P$17,P13,$B$8:$B$17,"<"&B13),COUNTIF($P$8:$P$17,">0")+COUNTIFS($P$8:$P$17,"<=0",$B$8:$B$17,"<="&B13)) | T13: =N(G13) | U13: =IF(OR(P13<=0,N(I13)<=0),"",IF(DATE(YEAR(TODAY()),MONTH(TODAY()),MIN(I13,DAY(DATE(YEAR(TODAY()),MONTH(TODAY())+1,0))))>=TODAY(),DATE(YEAR(TODAY()),MONTH(TODAY()),MIN(I13,DAY(DATE(YEAR(TODAY()),MONTH(TODAY())+1,0)))),DATE(YEAR(TODAY()),MONTH(TODAY())+1,MIN(I13,DAY(DATE(YEAR(TODAY()),MONTH(TODAY())+2,0))))))
B14: 7 | K14: =IF($P14>0,ROUND($P14*$T14/12,0),"") | L14: =IF($P14<=0,"",IF($Q14<=0,"Sin cuota",IF($Q14<=$P14*$T14/12,"No termina",IF($T14=0,ROUNDUP($P14/$Q14,0),ROUNDUP(-LN(1-$P14*($T14/12)/$Q14)/LN(1+$T14/12),0))))) | M14: =IF(AND($C14="",$P14<=0),"",IF($P14<=0,"Sin saldo: no se tiene en cuenta",IF($Q14<=0,"⚠ Falta la cuota mínima",IF($Q14<=$P14*$T14/12,"⚠ La cuota no cubre el interés","✔ Listo")))) | P14: =N(F14) | Q14: =IF(P14>0,N(H14),0) | R14: =IF(P14>0,1+COUNTIFS($P$8:$P$17,">0",$T$8:$T$17,">"&T14)+COUNTIFS($P$8:$P$17,">0",$T$8:$T$17,T14,$B$8:$B$17,"<"&B14),COUNTIF($P$8:$P$17,">0")+COUNTIFS($P$8:$P$17,"<=0",$B$8:$B$17,"<="&B14)) | S14: =IF(P14>0,1+COUNTIFS($P$8:$P$17,">0",$P$8:$P$17,"<"&P14)+COUNTIFS($P$8:$P$17,P14,$B$8:$B$17,"<"&B14),COUNTIF($P$8:$P$17,">0")+COUNTIFS($P$8:$P$17,"<=0",$B$8:$B$17,"<="&B14)) | T14: =N(G14) | U14: =IF(OR(P14<=0,N(I14)<=0),"",IF(DATE(YEAR(TODAY()),MONTH(TODAY()),MIN(I14,DAY(DATE(YEAR(TODAY()),MONTH(TODAY())+1,0))))>=TODAY(),DATE(YEAR(TODAY()),MONTH(TODAY()),MIN(I14,DAY(DATE(YEAR(TODAY()),MONTH(TODAY())+1,0)))),DATE(YEAR(TODAY()),MONTH(TODAY())+1,MIN(I14,DAY(DATE(YEAR(TODAY()),MONTH(TODAY())+2,0))))))
B15: 8 | K15: =IF($P15>0,ROUND($P15*$T15/12,0),"") | L15: =IF($P15<=0,"",IF($Q15<=0,"Sin cuota",IF($Q15<=$P15*$T15/12,"No termina",IF($T15=0,ROUNDUP($P15/$Q15,0),ROUNDUP(-LN(1-$P15*($T15/12)/$Q15)/LN(1+$T15/12),0))))) | M15: =IF(AND($C15="",$P15<=0),"",IF($P15<=0,"Sin saldo: no se tiene en cuenta",IF($Q15<=0,"⚠ Falta la cuota mínima",IF($Q15<=$P15*$T15/12,"⚠ La cuota no cubre el interés","✔ Listo")))) | P15: =N(F15) | Q15: =IF(P15>0,N(H15),0) | R15: =IF(P15>0,1+COUNTIFS($P$8:$P$17,">0",$T$8:$T$17,">"&T15)+COUNTIFS($P$8:$P$17,">0",$T$8:$T$17,T15,$B$8:$B$17,"<"&B15),COUNTIF($P$8:$P$17,">0")+COUNTIFS($P$8:$P$17,"<=0",$B$8:$B$17,"<="&B15)) | S15: =IF(P15>0,1+COUNTIFS($P$8:$P$17,">0",$P$8:$P$17,"<"&P15)+COUNTIFS($P$8:$P$17,P15,$B$8:$B$17,"<"&B15),COUNTIF($P$8:$P$17,">0")+COUNTIFS($P$8:$P$17,"<=0",$B$8:$B$17,"<="&B15)) | T15: =N(G15) | U15: =IF(OR(P15<=0,N(I15)<=0),"",IF(DATE(YEAR(TODAY()),MONTH(TODAY()),MIN(I15,DAY(DATE(YEAR(TODAY()),MONTH(TODAY())+1,0))))>=TODAY(),DATE(YEAR(TODAY()),MONTH(TODAY()),MIN(I15,DAY(DATE(YEAR(TODAY()),MONTH(TODAY())+1,0)))),DATE(YEAR(TODAY()),MONTH(TODAY())+1,MIN(I15,DAY(DATE(YEAR(TODAY()),MONTH(TODAY())+2,0))))))
B16: 9 | K16: =IF($P16>0,ROUND($P16*$T16/12,0),"") | L16: =IF($P16<=0,"",IF($Q16<=0,"Sin cuota",IF($Q16<=$P16*$T16/12,"No termina",IF($T16=0,ROUNDUP($P16/$Q16,0),ROUNDUP(-LN(1-$P16*($T16/12)/$Q16)/LN(1+$T16/12),0))))) | M16: =IF(AND($C16="",$P16<=0),"",IF($P16<=0,"Sin saldo: no se tiene en cuenta",IF($Q16<=0,"⚠ Falta la cuota mínima",IF($Q16<=$P16*$T16/12,"⚠ La cuota no cubre el interés","✔ Listo")))) | P16: =N(F16) | Q16: =IF(P16>0,N(H16),0) | R16: =IF(P16>0,1+COUNTIFS($P$8:$P$17,">0",$T$8:$T$17,">"&T16)+COUNTIFS($P$8:$P$17,">0",$T$8:$T$17,T16,$B$8:$B$17,"<"&B16),COUNTIF($P$8:$P$17,">0")+COUNTIFS($P$8:$P$17,"<=0",$B$8:$B$17,"<="&B16)) | S16: =IF(P16>0,1+COUNTIFS($P$8:$P$17,">0",$P$8:$P$17,"<"&P16)+COUNTIFS($P$8:$P$17,P16,$B$8:$B$17,"<"&B16),COUNTIF($P$8:$P$17,">0")+COUNTIFS($P$8:$P$17,"<=0",$B$8:$B$17,"<="&B16)) | T16: =N(G16) | U16: =IF(OR(P16<=0,N(I16)<=0),"",IF(DATE(YEAR(TODAY()),MONTH(TODAY()),MIN(I16,DAY(DATE(YEAR(TODAY()),MONTH(TODAY())+1,0))))>=TODAY(),DATE(YEAR(TODAY()),MONTH(TODAY()),MIN(I16,DAY(DATE(YEAR(TODAY()),MONTH(TODAY())+1,0)))),DATE(YEAR(TODAY()),MONTH(TODAY())+1,MIN(I16,DAY(DATE(YEAR(TODAY()),MONTH(TODAY())+2,0))))))
B17: 10 | K17: =IF($P17>0,ROUND($P17*$T17/12,0),"") | L17: =IF($P17<=0,"",IF($Q17<=0,"Sin cuota",IF($Q17<=$P17*$T17/12,"No termina",IF($T17=0,ROUNDUP($P17/$Q17,0),ROUNDUP(-LN(1-$P17*($T17/12)/$Q17)/LN(1+$T17/12),0))))) | M17: =IF(AND($C17="",$P17<=0),"",IF($P17<=0,"Sin saldo: no se tiene en cuenta",IF($Q17<=0,"⚠ Falta la cuota mínima",IF($Q17<=$P17*$T17/12,"⚠ La cuota no cubre el interés","✔ Listo")))) | P17: =N(F17) | Q17: =IF(P17>0,N(H17),0) | R17: =IF(P17>0,1+COUNTIFS($P$8:$P$17,">0",$T$8:$T$17,">"&T17)+COUNTIFS($P$8:$P$17,">0",$T$8:$T$17,T17,$B$8:$B$17,"<"&B17),COUNTIF($P$8:$P$17,">0")+COUNTIFS($P$8:$P$17,"<=0",$B$8:$B$17,"<="&B17)) | S17: =IF(P17>0,1+COUNTIFS($P$8:$P$17,">0",$P$8:$P$17,"<"&P17)+COUNTIFS($P$8:$P$17,P17,$B$8:$B$17,"<"&B17),COUNTIF($P$8:$P$17,">0")+COUNTIFS($P$8:$P$17,"<=0",$B$8:$B$17,"<="&B17)) | T17: =N(G17) | U17: =IF(OR(P17<=0,N(I17)<=0),"",IF(DATE(YEAR(TODAY()),MONTH(TODAY()),MIN(I17,DAY(DATE(YEAR(TODAY()),MONTH(TODAY())+1,0))))>=TODAY(),DATE(YEAR(TODAY()),MONTH(TODAY()),MIN(I17,DAY(DATE(YEAR(TODAY()),MONTH(TODAY())+1,0)))),DATE(YEAR(TODAY()),MONTH(TODAY())+1,MIN(I17,DAY(DATE(YEAR(TODAY()),MONTH(TODAY())+2,0))))))
B18: TOTAL | E18: =SUM(E8:E17) | F18: =SUM(F8:F17) | G18: =IFERROR(SUMPRODUCT(P8:P17,T8:T17)/SUM(P8:P17),0) | H18: =SUM(Q8:Q17) | K18: =SUM(K8:K17)
B20: Pago extra por mes (lo elegís en el PANEL): | H20: =Extra
B21: PAGO MENSUAL TOTAL (cuotas + extra): | H21: =SUM(Q8:Q17)+N(Extra)
B23: La tasa anual la encontrás en tu contrato o estado de cuenta (ej.: 36 %). Si no cobran interés, escribí 0 %. Los cálculos son estimados: tu banco puede aplicar comisiones o seguros que acá no figuran.
B27: MIX SHOP DIGITAL · Herramientas inteligentes que simplifican tu vida.
B28: Versión gratuita · Más herramientas gratuitas para tu vida diaria → mixshopdigital.com.py

Sheet VENCIMIENTOS
D1: VENCIMIENTOS
B2: Herramientas inteligentes que simplifican tu vida. | D2: ¿Qué tenés que pagar este mes?
C4: Marcá «Sí» en DEUDAS cuando pagues cada cuota. Acá ves qué está pagado, qué vence pronto y qué ya venció.
B5: ← Volver al PANEL | D5: Anotar pagos
B7: PAGADAS ESTE MES | D7: PENDIENTES | F7: TE FALTA PAGAR
B8: =COUNTIF(G11:G20,"✔*") | D8: =COUNTIF(B11:B20,"?*")-B8 | F8: =SUMIFS(E11:E20,G11:G20,"<>✔ Pagado")
B9: ="de "&COUNTIF(B11:B20,"?*")&" deudas" | D9: todavía sin pagar | F9: suma de cuotas pendientes
B10: Deuda | C10: Tipo | D10: Vence | E10: Cuota mínima | F10: ¿Pagaste? | G10: Estado
B11: =IF(OR(DEUDAS!P8<=0,DEUDAS!C8=""),"",DEUDAS!C8) | C11: =IF(B11="","",DEUDAS!D8&"") | D11: =IF(OR(B11="",N(DEUDAS!I8)=0),"",DATE(YEAR(TODAY()),MONTH(TODAY()),MIN(DEUDAS!I8,DAY(DATE(YEAR(TODAY()),MONTH(TODAY())+1,0))))) | E11: =IF(B11="","",DEUDAS!Q8) | F11: =IF(B11="","",IF(DEUDAS!J8="Sí","Sí","No")) | G11: =IF(B11="","",IF(F11="Sí","✔ Pagado",IF(D11="","Sin día de vencimiento",IF(D11<TODAY(),"✖ Vencido",IF(D11=TODAY(),"⚠ Vence hoy",IF(D11-TODAY()<=5,"⚠ Vence en "&(D11-TODAY())&" día(s)","Pendiente"))))))
B12: =IF(OR(DEUDAS!P9<=0,DEUDAS!C9=""),"",DEUDAS!C9) | C12: =IF(B12="","",DEUDAS!D9&"") | D12: =IF(OR(B12="",N(DEUDAS!I9)=0),"",DATE(YEAR(TODAY()),MONTH(TODAY()),MIN(DEUDAS!I9,DAY(DATE(YEAR(TODAY()),MONTH(TODAY())+1,0))))) | E12: =IF(B12="","",DEUDAS!Q9) | F12: =IF(B12="","",IF(DEUDAS!J9="Sí","Sí","No")) | G12: =IF(B12="","",IF(F12="Sí","✔ Pagado",IF(D12="","Sin día de vencimiento",IF(D12<TODAY(),"✖ Vencido",IF(D12=TODAY(),"⚠ Vence hoy",IF(D12-TODAY()<=5,"⚠ Vence en "&(D12-TODAY())&" día(s)","Pendiente"))))))
B13: =IF(OR(DEUDAS!P10<=0,DEUDAS!C10=""),"",DEUDAS!C10) | C13: =IF(B13="","",DEUDAS!D10&"") | D13: =IF(OR(B13="",N(DEUDAS!I10)=0),"",DATE(YEAR(TODAY()),MONTH(TODAY()),MIN(DEUDAS!I10,DAY(DATE(YEAR(TODAY()),MONTH(TODAY())+1,0))))) | E13: =IF(B13="","",DEUDAS!Q10) | F13: =IF(B13="","",IF(DEUDAS!J10="Sí","Sí","No")) | G13: =IF(B13="","",IF(F13="Sí","✔ Pagado",IF(D13="","Sin día de vencimiento",IF(D13<TODAY(),"✖ Vencido",IF(D13=TODAY(),"⚠ Vence hoy",IF(D13-TODAY()<=5,"⚠ Vence en "&(D13-TODAY())&" día(s)","Pendiente"))))))
B14: =IF(OR(DEUDAS!P11<=0,DEUDAS!C11=""),"",DEUDAS!C11) | C14: =IF(B14="","",DEUDAS!D11&"") | D14: =IF(OR(B14="",N(DEUDAS!I11)=0),"",DATE(YEAR(TODAY()),MONTH(TODAY()),MIN(DEUDAS!I11,DAY(DATE(YEAR(TODAY()),MONTH(TODAY())+1,0))))) | E14: =IF(B14="","",DEUDAS!Q11) | F14: =IF(B14="","",IF(DEUDAS!J11="Sí","Sí","No")) | G14: =IF(B14="","",IF(F14="Sí","✔ Pagado",IF(D14="","Sin día de vencimiento",IF(D14<TODAY(),"✖ Vencido",IF(D14=TODAY(),"⚠ Vence hoy",IF(D14-TODAY()<=5,"⚠ Vence en "&(D14-TODAY())&" día(s)","Pendiente"))))))
B15: =IF(OR(DEUDAS!P12<=0,DEUDAS!C12=""),"",DEUDAS!C12) | C15: =IF(B15="","",DEUDAS!D12&"") | D15: =IF(OR(B15="",N(DEUDAS!I12)=0),"",DATE(YEAR(TODAY()),MONTH(TODAY()),MIN(DEUDAS!I12,DAY(DATE(YEAR(TODAY()),MONTH(TODAY())+1,0))))) | E15: =IF(B15="","",DEUDAS!Q12) | F15: =IF(B15="","",IF(DEUDAS!J12="Sí","Sí","No")) | G15: =IF(B15="","",IF(F15="Sí","✔ Pagado",IF(D15="","Sin día de vencimiento",IF(D15<TODAY(),"✖ Vencido",IF(D15=TODAY(),"⚠ Vence hoy",IF(D15-TODAY()<=5,"⚠ Vence en "&(D15-TODAY())&" día(s)","Pendiente"))))))
B16: =IF(OR(DEUDAS!P13<=0,DEUDAS!C13=""),"",DEUDAS!C13) | C16: =IF(B16="","",DEUDAS!D13&"") | D16: =IF(OR(B16="",N(DEUDAS!I13)=0),"",DATE(YEAR(TODAY()),MONTH(TODAY()),MIN(DEUDAS!I13,DAY(DATE(YEAR(TODAY()),MONTH(TODAY())+1,0))))) | E16: =IF(B16="","",DEUDAS!Q13) | F16: =IF(B16="","",IF(DEUDAS!J13="Sí","Sí","No")) | G16: =IF(B16="","",IF(F16="Sí","✔ Pagado",IF(D16="","Sin día de vencimiento",IF(D16<TODAY(),"✖ Vencido",IF(D16=TODAY(),"⚠ Vence hoy",IF(D16-TODAY()<=5,"⚠ Vence en "&(D16-TODAY())&" día(s)","Pendiente"))))))
B17: =IF(OR(DEUDAS!P14<=0,DEUDAS!C14=""),"",DEUDAS!C14) | C17: =IF(B17="","",DEUDAS!D14&"") | D17: =IF(OR(B17="",N(DEUDAS!I14)=0),"",DATE(YEAR(TODAY()),MONTH(TODAY()),MIN(DEUDAS!I14,DAY(DATE(YEAR(TODAY()),MONTH(TODAY())+1,0))))) | E17: =IF(B17="","",DEUDAS!Q14) | F17: =IF(B17="","",IF(DEUDAS!J14="Sí","Sí","No")) | G17: =IF(B17="","",IF(F17="Sí","✔ Pagado",IF(D17="","Sin día de vencimiento",IF(D17<TODAY(),"✖ Vencido",IF(D17=TODAY(),"⚠ Vence hoy",IF(D17-TODAY()<=5,"⚠ Vence en "&(D17-TODAY())&" día(s)","Pendiente"))))))
B18: =IF(OR(DEUDAS!P15<=0,DEUDAS!C15=""),"",DEUDAS!C15) | C18: =IF(B18="","",DEUDAS!D15&"") | D18: =IF(OR(B18="",N(DEUDAS!I15)=0),"",DATE(YEAR(TODAY()),MONTH(TODAY()),MIN(DEUDAS!I15,DAY(DATE(YEAR(TODAY()),MONTH(TODAY())+1,0))))) | E18: =IF(B18="","",DEUDAS!Q15) | F18: =IF(B18="","",IF(DEUDAS!J15="Sí","Sí","No")) | G18: =IF(B18="","",IF(F18="Sí","✔ Pagado",IF(D18="","Sin día de vencimiento",IF(D18<TODAY(),"✖ Vencido",IF(D18=TODAY(),"⚠ Vence hoy",IF(D18-TODAY()<=5,"⚠ Vence en "&(D18-TODAY())&" día(s)","Pendiente"))))))
B19: =IF(OR(DEUDAS!P16<=0,DEUDAS!C16=""),"",DEUDAS!C16) | C19: =IF(B19="","",DEUDAS!D16&"") | D19: =IF(OR(B19="",N(DEUDAS!I16)=0),"",DATE(YEAR(TODAY()),MONTH(TODAY()),MIN(DEUDAS!I16,DAY(DATE(YEAR(TODAY()),MONTH(TODAY())+1,0))))) | E19: =IF(B19="","",DEUDAS!Q16) | F19: =IF(B19="","",IF(DEUDAS!J16="Sí","Sí","No")) | G19: =IF(B19="","",IF(F19="Sí","✔ Pagado",IF(D19="","Sin día de vencimiento",IF(D19<TODAY(),"✖ Vencido",IF(D19=TODAY(),"⚠ Vence hoy",IF(D19-TODAY()<=5,"⚠ Vence en "&(D19-TODAY())&" día(s)","Pendiente"))))))
B20: =IF(OR(DEUDAS!P17<=0,DEUDAS!C17=""),"",DEUDAS!C17) | C20: =IF(B20="","",DEUDAS!D17&"") | D20: =IF(OR(B20="",N(DEUDAS!I17)=0),"",DATE(YEAR(TODAY()),MONTH(TODAY()),MIN(DEUDAS!I17,DAY(DATE(YEAR(TODAY()),MONTH(TODAY())+1,0))))) | E20: =IF(B20="","",DEUDAS!Q17) | F20: =IF(B20="","",IF(DEUDAS!J17="Sí","Sí","No")) | G20: =IF(B20="","",IF(F20="Sí","✔ Pagado",IF(D20="","Sin día de vencimiento",IF(D20<TODAY(),"✖ Vencido",IF(D20=TODAY(),"⚠ Vence hoy",IF(D20-TODAY()<=5,"⚠ Vence en "&(D20-TODAY())&" día(s)","Pendiente"))))))
B22: Cada mes volvé a poner «No» en la columna «¿Pagaste este mes?» de DEUDAS, así el aviso empieza de nuevo.
B25: MIX SHOP DIGITAL · Herramientas inteligentes que simplifican tu vida.
B26: Versión gratuita · Más herramientas gratuitas para tu vida diaria → mixshopdigital.com.py

Sheet PLAN
D1: PLAN MES A MES
B2: Herramientas inteligentes que simplifican tu vida. | D2: Tu camino hacia cero
C4: Muestra los primeros 3 años de la estrategia que elegiste en el PANEL: cuánto pagás, cuánto es interés y cuánto te queda.
B5: ← Volver al PANEL | D5: ="Estrategia: "&Estrat&" · pago extra: "&FIXED(N(Extra),0)&" "&Moneda
B7: Mes | C7: Fecha | D7: Pago total | E7: Intereses | F7: Capital (baja la deuda) | G7: Te queda por pagar | H7: Pagás de más a
B8: =IF(CHOOSE(EstrN,SIM_AVALANCHA!AI10,SIM_BOLA!AI10)<=0,"",1) | C8: =IF($B8="","",CHOOSE(EstrN,SIM_AVALANCHA!B11,SIM_BOLA!B11)) | D8: =IF($B8="","",CHOOSE(EstrN,SIM_AVALANCHA!AH11,SIM_BOLA!AH11)) | E8: =IF($B8="","",CHOOSE(EstrN,SIM_AVALANCHA!AG11,SIM_BOLA!AG11)) | F8: =IF($B8="","",D8-E8) | G8: =IF($B8="","",CHOOSE(EstrN,SIM_AVALANCHA!AI11,SIM_BOLA!AI11)) | H8: =IF($B8="","",IF(CHOOSE(EstrN,SIM_AVALANCHA!AJ11,SIM_BOLA!AJ11)<=0,"-",IF(CHOOSE(EstrN,SIM_AVALANCHA!AK11,SIM_BOLA!AK11)=0,"",CHOOSE(EstrN,INDEX(SIM_AVALANCHA!$C$7:$L$7,SIM_AVALANCHA!AK11),INDEX(SIM_BOLA!$C$7:$L$7,SIM_BOLA!AK11)))))
B9: =IF(CHOOSE(EstrN,SIM_AVALANCHA!AI11,SIM_BOLA!AI11)<=0,"",2) | C9: =IF($B9="","",CHOOSE(EstrN,SIM_AVALANCHA!B12,SIM_BOLA!B12)) | D9: =IF($B9="","",CHOOSE(EstrN,SIM_AVALANCHA!AH12,SIM_BOLA!AH12)) | E9: =IF($B9="","",CHOOSE(EstrN,SIM_AVALANCHA!AG12,SIM_BOLA!AG12)) | F9: =IF($B9="","",D9-E9) | G9: =IF($B9="","",CHOOSE(EstrN,SIM_AVALANCHA!AI12,SIM_BOLA!AI12)) | H9: =IF($B9="","",IF(CHOOSE(EstrN,SIM_AVALANCHA!AJ12,SIM_BOLA!AJ12)<=0,"-",IF(CHOOSE(EstrN,SIM_AVALANCHA!AK12,SIM_BOLA!AK12)=0,"",CHOOSE(EstrN,INDEX(SIM_AVALANCHA!$C$7:$L$7,SIM_AVALANCHA!AK12),INDEX(SIM_BOLA!$C$7:$L$7,SIM_BOLA!AK12)))))
B10: =IF(CHOOSE(EstrN,SIM_AVALANCHA!AI12,SIM_BOLA!AI12)<=0,"",3) | C10: =IF($B10="","",CHOOSE(EstrN,SIM_AVALANCHA!B13,SIM_BOLA!B13)) | D10: =IF($B10="","",CHOOSE(EstrN,SIM_AVALANCHA!AH13,SIM_BOLA!AH13)) | E10: =IF($B10="","",CHOOSE(EstrN,SIM_AVALANCHA!AG13,SIM_BOLA!AG13)) | F10: =IF($B10="","",D10-E10) | G10: =IF($B10="","",CHOOSE(EstrN,SIM_AVALANCHA!AI13,SIM_BOLA!AI13)) | H10: =IF($B10="","",IF(CHOOSE(EstrN,SIM_AVALANCHA!AJ13,SIM_BOLA!AJ13)<=0,"-",IF(CHOOSE(EstrN,SIM_AVALANCHA!AK13,SIM_BOLA!AK13)=0,"",CHOOSE(EstrN,INDEX(SIM_AVALANCHA!$C$7:$L$7,SIM_AVALANCHA!AK13),INDEX(SIM_BOLA!$C$7:$L$7,SIM_BOLA!AK13)))))
B11: =IF(CHOOSE(EstrN,SIM_AVALANCHA!AI13,SIM_BOLA!AI13)<=0,"",4) | C11: =IF($B11="","",CHOOSE(EstrN,SIM_AVALANCHA!B14,SIM_BOLA!B14)) | D11: =IF($B11="","",CHOOSE(EstrN,SIM_AVALANCHA!AH14,SIM_BOLA!AH14)) | E11: =IF($B11="","",CHOOSE(EstrN,SIM_AVALANCHA!AG14,SIM_BOLA!AG14)) | F11: =IF($B11="","",D11-E11) | G11: =IF($B11="","",CHOOSE(EstrN,SIM_AVALANCHA!AI14,SIM_BOLA!AI14)) | H11: =IF($B11="","",IF(CHOOSE(EstrN,SIM_AVALANCHA!AJ14,SIM_BOLA!AJ14)<=0,"-",IF(CHOOSE(EstrN,SIM_AVALANCHA!AK14,SIM_BOLA!AK14)=0,"",CHOOSE(EstrN,INDEX(SIM_AVALANCHA!$C$7:$L$7,SIM_AVALANCHA!AK14),INDEX(SIM_BOLA!$C$7:$L$7,SIM_BOLA!AK14)))))
B12: =IF(CHOOSE(EstrN,SIM_AVALANCHA!AI14,SIM_BOLA!AI14)<=0,"",5) | C12: =IF($B12="","",CHOOSE(EstrN,SIM_AVALANCHA!B15,SIM_BOLA!B15)) | D12: =IF($B12="","",CHOOSE(EstrN,SIM_AVALANCHA!AH15,SIM_BOLA!AH15)) | E12: =IF($B12="","",CHOOSE(EstrN,SIM_AVALANCHA!AG15,SIM_BOLA!AG15)) | F12: =IF($B12="","",D12-E12) | G12: =IF($B12="","",CHOOSE(EstrN,SIM_AVALANCHA!AI15,SIM_BOLA!AI15)) | H12: =IF($B12="","",IF(CHOOSE(EstrN,SIM_AVALANCHA!AJ15,SIM_BOLA!AJ15)<=0,"-",IF(CHOOSE(EstrN,SIM_AVALANCHA!AK15,SIM_BOLA!AK15)=0,"",CHOOSE(EstrN,INDEX(SIM_AVALANCHA!$C$7:$L$7,SIM_AVALANCHA!AK15),INDEX(SIM_BOLA!$C$7:$L$7,SIM_BOLA!AK15)))))
B13: =IF(CHOOSE(EstrN,SIM_AVALANCHA!AI15,SIM_BOLA!AI15)<=0,"",6) | C13: =IF($B13="","",CHOOSE(EstrN,SIM_AVALANCHA!B16,SIM_BOLA!B16)) | D13: =IF($B13="","",CHOOSE(EstrN,SIM_AVALANCHA!AH16,SIM_BOLA!AH16)) | E13: =IF($B13="","",CHOOSE(EstrN,SIM_AVALANCHA!AG16,SIM_BOLA!AG16)) | F13: =IF($B13="","",D13-E13) | G13: =IF($B13="","",CHOOSE(EstrN,SIM_AVALANCHA!AI16,SIM_BOLA!AI16)) | H13: =IF($B13="","",IF(CHOOSE(EstrN,SIM_AVALANCHA!AJ16,SIM_BOLA!AJ16)<=0,"-",IF(CHOOSE(EstrN,SIM_AVALANCHA!AK16,SIM_BOLA!AK16)=0,"",CHOOSE(EstrN,INDEX(SIM_AVALANCHA!$C$7:$L$7,SIM_AVALANCHA!AK16),INDEX(SIM_BOLA!$C$7:$L$7,SIM_BOLA!AK16)))))
B14: =IF(CHOOSE(EstrN,SIM_AVALANCHA!AI16,SIM_BOLA!AI16)<=0,"",7) | C14: =IF($B14="","",CHOOSE(EstrN,SIM_AVALANCHA!B17,SIM_BOLA!B17)) | D14: =IF($B14="","",CHOOSE(EstrN,SIM_AVALANCHA!AH17,SIM_BOLA!AH17)) | E14: =IF($B14="","",CHOOSE(EstrN,SIM_AVALANCHA!AG17,SIM_BOLA!AG17)) | F14: =IF($B14="","",D14-E14) | G14: =IF($B14="","",CHOOSE(EstrN,SIM_AVALANCHA!AI17,SIM_BOLA!AI17)) | H14: =IF($B14="","",IF(CHOOSE(EstrN,SIM_AVALANCHA!AJ17,SIM_BOLA!AJ17)<=0,"-",IF(CHOOSE(EstrN,SIM_AVALANCHA!AK17,SIM_BOLA!AK17)=0,"",CHOOSE(EstrN,INDEX(SIM_AVALANCHA!$C$7:$L$7,SIM_AVALANCHA!AK17),INDEX(SIM_BOLA!$C$7:$L$7,SIM_BOLA!AK17)))))
B15: =IF(CHOOSE(EstrN,SIM_AVALANCHA!AI17,SIM_BOLA!AI17)<=0,"",8) | C15: =IF($B15="","",CHOOSE(EstrN,SIM_AVALANCHA!B18,SIM_BOLA!B18)) | D15: =IF($B15="","",CHOOSE(EstrN,SIM_AVALANCHA!AH18,SIM_BOLA!AH18)) | E15: =IF($B15="","",CHOOSE(EstrN,SIM_AVALANCHA!AG18,SIM_BOLA!AG18)) | F15: =IF($B15="","",D15-E15) | G15: =IF($B15="","",CHOOSE(EstrN,SIM_AVALANCHA!AI18,SIM_BOLA!AI18)) | H15: =IF($B15="","",IF(CHOOSE(EstrN,SIM_AVALANCHA!AJ18,SIM_BOLA!AJ18)<=0,"-",IF(CHOOSE(EstrN,SIM_AVALANCHA!AK18,SIM_BOLA!AK18)=0,"",CHOOSE(EstrN,INDEX(SIM_AVALANCHA!$C$7:$L$7,SIM_AVALANCHA!AK18),INDEX(SIM_BOLA!$C$7:$L$7,SIM_BOLA!AK18)))))
B16: =IF(CHOOSE(EstrN,SIM_AVALANCHA!AI18,SIM_BOLA!AI18)<=0,"",9) | C16: =IF($B16="","",CHOOSE(EstrN,SIM_AVALANCHA!B19,SIM_BOLA!B19)) | D16: =IF($B16="","",CHOOSE(EstrN,SIM_AVALANCHA!AH19,SIM_BOLA!AH19)) | E16: =IF($B16="","",CHOOSE(EstrN,SIM_AVALANCHA!AG19,SIM_BOLA!AG19)) | F16: =IF($B16="","",D16-E16) | G16: =IF($B16="","",CHOOSE(EstrN,SIM_AVALANCHA!AI19,SIM_BOLA!AI19)) | H16: =IF($B16="","",IF(CHOOSE(EstrN,SIM_AVALANCHA!AJ19,SIM_BOLA!AJ19)<=0,"-",IF(CHOOSE(EstrN,SIM_AVALANCHA!AK19,SIM_BOLA!AK19)=0,"",CHOOSE(EstrN,INDEX(SIM_AVALANCHA!$C$7:$L$7,SIM_AVALANCHA!AK19),INDEX(SIM_BOLA!$C$7:$L$7,SIM_BOLA!AK19)))))
B17: =IF(CHOOSE(EstrN,SIM_AVALANCHA!AI19,SIM_BOLA!AI19)<=0,"",10) | C17: =IF($B17="","",CHOOSE(EstrN,SIM_AVALANCHA!B20,SIM_BOLA!B20)) | D17: =IF($B17="","",CHOOSE(EstrN,SIM_AVALANCHA!AH20,SIM_BOLA!AH20)) | E17: =IF($B17="","",CHOOSE(EstrN,SIM_AVALANCHA!AG20,SIM_BOLA!AG20)) | F17: =IF($B17="","",D17-E17) | G17: =IF($B17="","",CHOOSE(EstrN,SIM_AVALANCHA!AI20,SIM_BOLA!AI20)) | H17: =IF($B17="","",IF(CHOOSE(EstrN,SIM_AVALANCHA!AJ20,SIM_BOLA!AJ20)<=0,"-",IF(CHOOSE(EstrN,SIM_AVALANCHA!AK20,SIM_BOLA!AK20)=0,"",CHOOSE(EstrN,INDEX(SIM_AVALANCHA!$C$7:$L$7,SIM_AVALANCHA!AK20),INDEX(SIM_BOLA!$C$7:$L$7,SIM_BOLA!AK20)))))
B18: =IF(CHOOSE(EstrN,SIM_AVALANCHA!AI20,SIM_BOLA!AI20)<=0,"",11) | C18: =IF($B18="","",CHOOSE(EstrN,SIM_AVALANCHA!B21,SIM_BOLA!B21)) | D18: =IF($B18="","",CHOOSE(EstrN,SIM_AVALANCHA!AH21,SIM_BOLA!AH21)) | E18: =IF($B18="","",CHOOSE(EstrN,SIM_AVALANCHA!AG21,SIM_BOLA!AG21)) | F18: =IF($B18="","",D18-E18) | G18: =IF($B18="","",CHOOSE(EstrN,SIM_AVALANCHA!AI21,SIM_BOLA!AI21)) | H18: =IF($B18="","",IF(CHOOSE(EstrN,SIM_AVALANCHA!AJ21,SIM_BOLA!AJ21)<=0,"-",IF(CHOOSE(EstrN,SIM_AVALANCHA!AK21,SIM_BOLA!AK21)=0,"",CHOOSE(EstrN,INDEX(SIM_AVALANCHA!$C$7:$L$7,SIM_AVALANCHA!AK21),INDEX(SIM_BOLA!$C$7:$L$7,SIM_BOLA!AK21)))))
B19: =IF(CHOOSE(EstrN,SIM_AVALANCHA!AI21,SIM_BOLA!AI21)<=0,"",12) | C19: =IF($B19="","",CHOOSE(EstrN,SIM_AVALANCHA!B22,SIM_BOLA!B22)) | D19: =IF($B19="","",CHOOSE(EstrN,SIM_AVALANCHA!AH22,SIM_BOLA!AH22)) | E19: =IF($B19="","",CHOOSE(EstrN,SIM_AVALANCHA!AG22,SIM_BOLA!AG22)) | F19: =IF($B19="","",D19-E19) | G19: =IF($B19="","",CHOOSE(EstrN,SIM_AVALANCHA!AI22,SIM_BOLA!AI22)) | H19: =IF($B19="","",IF(CHOOSE(EstrN,SIM_AVALANCHA!AJ22,SIM_BOLA!AJ22)<=0,"-",IF(CHOOSE(EstrN,SIM_AVALANCHA!AK22,SIM_BOLA!AK22)=0,"",CHOOSE(EstrN,INDEX(SIM_AVALANCHA!$C$7:$L$7,SIM_AVALANCHA!AK22),INDEX(SIM_BOLA!$C$7:$L$7,SIM_BOLA!AK22)))))
B20: =IF(CHOOSE(EstrN,SIM_AVALANCHA!AI22,SIM_BOLA!AI22)<=0,"",13) | C20: =IF($B20="","",CHOOSE(EstrN,SIM_AVALANCHA!B23,SIM_BOLA!B23)) | D20: =IF($B20="","",CHOOSE(EstrN,SIM_AVALANCHA!AH23,SIM_BOLA!AH23)) | E20: =IF($B20="","",CHOOSE(EstrN,SIM_AVALANCHA!AG23,SIM_BOLA!AG23)) | F20: =IF($B20="","",D20-E20) | G20: =IF($B20="","",CHOOSE(EstrN,SIM_AVALANCHA!AI23,SIM_BOLA!AI23)) | H20: =IF($B20="","",IF(CHOOSE(EstrN,SIM_AVALANCHA!AJ23,SIM_BOLA!AJ23)<=0,"-",IF(CHOOSE(EstrN,SIM_AVALANCHA!AK23,SIM_BOLA!AK23)=0,"",CHOOSE(EstrN,INDEX(SIM_AVALANCHA!$C$7:$L$7,SIM_AVALANCHA!AK23),INDEX(SIM_BOLA!$C$7:$L$7,SIM_BOLA!AK23)))))
B21: =IF(CHOOSE(EstrN,SIM_AVALANCHA!AI23,SIM_BOLA!AI23)<=0,"",14) | C21: =IF($B21="","",CHOOSE(EstrN,SIM_AVALANCHA!B24,SIM_BOLA!B24)) | D21: =IF($B21="","",CHOOSE(EstrN,SIM_AVALANCHA!AH24,SIM_BOLA!AH24)) | E21: =IF($B21="","",CHOOSE(EstrN,SIM_AVALANCHA!AG24,SIM_BOLA!AG24)) | F21: =IF($B21="","",D21-E21) | G21: =IF($B21="","",CHOOSE(EstrN,SIM_AVALANCHA!AI24,SIM_BOLA!AI24)) | H21: =IF($B21="","",IF(CHOOSE(EstrN,SIM_AVALANCHA!AJ24,SIM_BOLA!AJ24)<=0,"-",IF(CHOOSE(EstrN,SIM_AVALANCHA!AK24,SIM_BOLA!AK24)=0,"",CHOOSE(EstrN,INDEX(SIM_AVALANCHA!$C$7:$L$7,SIM_AVALANCHA!AK24),INDEX(SIM_BOLA!$C$7:$L$7,SIM_BOLA!AK24)))))
B22: =IF(CHOOSE(EstrN,SIM_AVALANCHA!AI24,SIM_BOLA!AI24)<=0,"",15) | C22: =IF($B22="","",CHOOSE(EstrN,SIM_AVALANCHA!B25,SIM_BOLA!B25)) | D22: =IF($B22="","",CHOOSE(EstrN,SIM_AVALANCHA!AH25,SIM_BOLA!AH25)) | E22: =IF($B22="","",CHOOSE(EstrN,SIM_AVALANCHA!AG25,SIM_BOLA!AG25)) | F22: =IF($B22="","",D22-E22) | G22: =IF($B22="","",CHOOSE(EstrN,SIM_AVALANCHA!AI25,SIM_BOLA!AI25)) | H22: =IF($B22="","",IF(CHOOSE(EstrN,SIM_AVALANCHA!AJ25,SIM_BOLA!AJ25)<=0,"-",IF(CHOOSE(EstrN,SIM_AVALANCHA!AK25,SIM_BOLA!AK25)=0,"",CHOOSE(EstrN,INDEX(SIM_AVALANCHA!$C$7:$L$7,SIM_AVALANCHA!AK25),INDEX(SIM_BOLA!$C$7:$L$7,SIM_BOLA!AK25)))))
B23: =IF(CHOOSE(EstrN,SIM_AVALANCHA!AI25,SIM_BOLA!AI25)<=0,"",16) | C23: =IF($B23="","",CHOOSE(EstrN,SIM_AVALANCHA!B26,SIM_BOLA!B26)) | D23: =IF($B23="","",CHOOSE(EstrN,SIM_AVALANCHA!AH26,SIM_BOLA!AH26)) | E23: =IF($B23="","",CHOOSE(EstrN,SIM_AVALANCHA!AG26,SIM_BOLA!AG26)) | F23: =IF($B23="","",D23-E23) | G23: =IF($B23="","",CHOOSE(EstrN,SIM_AVALANCHA!AI26,SIM_BOLA!AI26)) | H23: =IF($B23="","",IF(CHOOSE(EstrN,SIM_AVALANCHA!AJ26,SIM_BOLA!AJ26)<=0,"-",IF(CHOOSE(EstrN,SIM_AVALANCHA!AK26,SIM_BOLA!AK26)=0,"",CHOOSE(EstrN,INDEX(SIM_AVALANCHA!$C$7:$L$7,SIM_AVALANCHA!AK26),INDEX(SIM_BOLA!$C$7:$L$7,SIM_BOLA!AK26)))))
B24: =IF(CHOOSE(EstrN,SIM_AVALANCHA!AI26,SIM_BOLA!AI26)<=0,"",17) | C24: =IF($B24="","",CHOOSE(EstrN,SIM_AVALANCHA!B27,SIM_BOLA!B27)) | D24: =IF($B24="","",CHOOSE(EstrN,SIM_AVALANCHA!AH27,SIM_BOLA!AH27)) | E24: =IF($B24="","",CHOOSE(EstrN,SIM_AVALANCHA!AG27,SIM_BOLA!AG27)) | F24: =IF($B24="","",D24-E24) | G24: =IF($B24="","",CHOOSE(EstrN,SIM_AVALANCHA!AI27,SIM_BOLA!AI27)) | H24: =IF($B24="","",IF(CHOOSE(EstrN,SIM_AVALANCHA!AJ27,SIM_BOLA!AJ27)<=0,"-",IF(CHOOSE(EstrN,SIM_AVALANCHA!AK27,SIM_BOLA!AK27)=0,"",CHOOSE(EstrN,INDEX(SIM_AVALANCHA!$C$7:$L$7,SIM_AVALANCHA!AK27),INDEX(SIM_BOLA!$C$7:$L$7,SIM_BOLA!AK27)))))
B25: =IF(CHOOSE(EstrN,SIM_AVALANCHA!AI27,SIM_BOLA!AI27)<=0,"",18) | C25: =IF($B25="","",CHOOSE(EstrN,SIM_AVALANCHA!B28,SIM_BOLA!B28)) | D25: =IF($B25="","",CHOOSE(EstrN,SIM_AVALANCHA!AH28,SIM_BOLA!AH28)) | E25: =IF($B25="","",CHOOSE(EstrN,SIM_AVALANCHA!AG28,SIM_BOLA!AG28)) | F25: =IF($B25="","",D25-E25) | G25: =IF($B25="","",CHOOSE(EstrN,SIM_AVALANCHA!AI28,SIM_BOLA!AI28)) | H25: =IF($B25="","",IF(CHOOSE(EstrN,SIM_AVALANCHA!AJ28,SIM_BOLA!AJ28)<=0,"-",IF(CHOOSE(EstrN,SIM_AVALANCHA!AK28,SIM_BOLA!AK28)=0,"",CHOOSE(EstrN,INDEX(SIM_AVALANCHA!$C$7:$L$7,SIM_AVALANCHA!AK28),INDEX(SIM_BOLA!$C$7:$L$7,SIM_BOLA!AK28)))))
B26: =IF(CHOOSE(EstrN,SIM_AVALANCHA!AI28,SIM_BOLA!AI28)<=0,"",19) | C26: =IF($B26="","",CHOOSE(EstrN,SIM_AVALANCHA!B29,SIM_BOLA!B29)) | D26: =IF($B26="","",CHOOSE(EstrN,SIM_AVALANCHA!AH29,SIM_BOLA!AH29)) | E26: =IF($B26="","",CHOOSE(EstrN,SIM_AVALANCHA!AG29,SIM_BOLA!AG29)) | F26: =IF($B26="","",D26-E26) | G26: =IF($B26="","",CHOOSE(EstrN,SIM_AVALANCHA!AI29,SIM_BOLA!AI29)) | H26: =IF($B26="","",IF(CHOOSE(EstrN,SIM_AVALANCHA!AJ29,SIM_BOLA!AJ29)<=0,"-",IF(CHOOSE(EstrN,SIM_AVALANCHA!AK29,SIM_BOLA!AK29)=0,"",CHOOSE(EstrN,INDEX(SIM_AVALANCHA!$C$7:$L$7,SIM_AVALANCHA!AK29),INDEX(SIM_BOLA!$C$7:$L$7,SIM_BOLA!AK29)))))
B27: =IF(CHOOSE(EstrN,SIM_AVALANCHA!AI29,SIM_BOLA!AI29)<=0,"",20) | C27: =IF($B27="","",CHOOSE(EstrN,SIM_AVALANCHA!B30,SIM_BOLA!B30)) | D27: =IF($B27="","",CHOOSE(EstrN,SIM_AVALANCHA!AH30,SIM_BOLA!AH30)) | E27: =IF($B27="","",CHOOSE(EstrN,SIM_AVALANCHA!AG30,SIM_BOLA!AG30)) | F27: =IF($B27="","",D27-E27) | G27: =IF($B27="","",CHOOSE(EstrN,SIM_AVALANCHA!AI30,SIM_BOLA!AI30)) | H27: =IF($B27="","",IF(CHOOSE(EstrN,SIM_AVALANCHA!AJ30,SIM_BOLA!AJ30)<=0,"-",IF(CHOOSE(EstrN,SIM_AVALANCHA!AK30,SIM_BOLA!AK30)=0,"",CHOOSE(EstrN,INDEX(SIM_AVALANCHA!$C$7:$L$7,SIM_AVALANCHA!AK30),INDEX(SIM_BOLA!$C$7:$L$7,SIM_BOLA!AK30)))))
B28: =IF(CHOOSE(EstrN,SIM_AVALANCHA!AI30,SIM_BOLA!AI30)<=0,"",21) | C28: =IF($B28="","",CHOOSE(EstrN,SIM_AVALANCHA!B31,SIM_BOLA!B31)) | D28: =IF($B28="","",CHOOSE(EstrN,SIM_AVALANCHA!AH31,SIM_BOLA!AH31)) | E28: =IF($B28="","",CHOOSE(EstrN,SIM_AVALANCHA!AG31,SIM_BOLA!AG31)) | F28: =IF($B28="","",D28-E28) | G28: =IF($B28="","",CHOOSE(EstrN,SIM_AVALANCHA!AI31,SIM_BOLA!AI31)) | H28: =IF($B28="","",IF(CHOOSE(EstrN,SIM_AVALANCHA!AJ31,SIM_BOLA!AJ31)<=0,"-",IF(CHOOSE(EstrN,SIM_AVALANCHA!AK31,SIM_BOLA!AK31)=0,"",CHOOSE(EstrN,INDEX(SIM_AVALANCHA!$C$7:$L$7,SIM_AVALANCHA!AK31),INDEX(SIM_BOLA!$C$7:$L$7,SIM_BOLA!AK31)))))
B29: =IF(CHOOSE(EstrN,SIM_AVALANCHA!AI31,SIM_BOLA!AI31)<=0,"",22) | C29: =IF($B29="","",CHOOSE(EstrN,SIM_AVALANCHA!B32,SIM_BOLA!B32)) | D29: =IF($B29="","",CHOOSE(EstrN,SIM_AVALANCHA!AH32,SIM_BOLA!AH32)) | E29: =IF($B29="","",CHOOSE(EstrN,SIM_AVALANCHA!AG32,SIM_BOLA!AG32)) | F29: =IF($B29="","",D29-E29) | G29: =IF($B29="","",CHOOSE(EstrN,SIM_AVALANCHA!AI32,SIM_BOLA!AI32)) | H29: =IF($B29="","",IF(CHOOSE(EstrN,SIM_AVALANCHA!AJ32,SIM_BOLA!AJ32)<=0,"-",IF(CHOOSE(EstrN,SIM_AVALANCHA!AK32,SIM_BOLA!AK32)=0,"",CHOOSE(EstrN,INDEX(SIM_AVALANCHA!$C$7:$L$7,SIM_AVALANCHA!AK32),INDEX(SIM_BOLA!$C$7:$L$7,SIM_BOLA!AK32)))))
B30: =IF(CHOOSE(EstrN,SIM_AVALANCHA!AI32,SIM_BOLA!AI32)<=0,"",23) | C30: =IF($B30="","",CHOOSE(EstrN,SIM_AVALANCHA!B33,SIM_BOLA!B33)) | D30: =IF($B30="","",CHOOSE(EstrN,SIM_AVALANCHA!AH33,SIM_BOLA!AH33)) | E30: =IF($B30="","",CHOOSE(EstrN,SIM_AVALANCHA!AG33,SIM_BOLA!AG33)) | F30: =IF($B30="","",D30-E30) | G30: =IF($B30="","",CHOOSE(EstrN,SIM_AVALANCHA!AI33,SIM_BOLA!AI33)) | H30: =IF($B30="","",IF(CHOOSE(EstrN,SIM_AVALANCHA!AJ33,SIM_BOLA!AJ33)<=0,"-",IF(CHOOSE(EstrN,SIM_AVALANCHA!AK33,SIM_BOLA!AK33)=0,"",CHOOSE(EstrN,INDEX(SIM_AVALANCHA!$C$7:$L$7,SIM_AVALANCHA!AK33),INDEX(SIM_BOLA!$C$7:$L$7,SIM_BOLA!AK33)))))
B31: =IF(CHOOSE(EstrN,SIM_AVALANCHA!AI33,SIM_BOLA!AI33)<=0,"",24) | C31: =IF($B31="","",CHOOSE(EstrN,SIM_AVALANCHA!B34,SIM_BOLA!B34)) | D31: =IF($B31="","",CHOOSE(EstrN,SIM_AVALANCHA!AH34,SIM_BOLA!AH34)) | E31: =IF($B31="","",CHOOSE(EstrN,SIM_AVALANCHA!AG34,SIM_BOLA!AG34)) | F31: =IF($B31="","",D31-E31) | G31: =IF($B31="","",CHOOSE(EstrN,SIM_AVALANCHA!AI34,SIM_BOLA!AI34)) | H31: =IF($B31="","",IF(CHOOSE(EstrN,SIM_AVALANCHA!AJ34,SIM_BOLA!AJ34)<=0,"-",IF(CHOOSE(EstrN,SIM_AVALANCHA!AK34,SIM_BOLA!AK34)=0,"",CHOOSE(EstrN,INDEX(SIM_AVALANCHA!$C$7:$L$7,SIM_AVALANCHA!AK34),INDEX(SIM_BOLA!$C$7:$L$7,SIM_BOLA!AK34)))))
B32: =IF(CHOOSE(EstrN,SIM_AVALANCHA!AI34,SIM_BOLA!AI34)<=0,"",25) | C32: =IF($B32="","",CHOOSE(EstrN,SIM_AVALANCHA!B35,SIM_BOLA!B35)) | D32: =IF($B32="","",CHOOSE(EstrN,SIM_AVALANCHA!AH35,SIM_BOLA!AH35)) | E32: =IF($B32="","",CHOOSE(EstrN,SIM_AVALANCHA!AG35,SIM_BOLA!AG35)) | F32: =IF($B32="","",D32-E32) | G32: =IF($B32="","",CHOOSE(EstrN,SIM_AVALANCHA!AI35,SIM_BOLA!AI35)) | H32: =IF($B32="","",IF(CHOOSE(EstrN,SIM_AVALANCHA!AJ35,SIM_BOLA!AJ35)<=0,"-",IF(CHOOSE(EstrN,SIM_AVALANCHA!AK35,SIM_BOLA!AK35)=0,"",CHOOSE(EstrN,INDEX(SIM_AVALANCHA!$C$7:$L$7,SIM_AVALANCHA!AK35),INDEX(SIM_BOLA!$C$7:$L$7,SIM_BOLA!AK35)))))
B33: =IF(CHOOSE(EstrN,SIM_AVALANCHA!AI35,SIM_BOLA!AI35)<=0,"",26) | C33: =IF($B33="","",CHOOSE(EstrN,SIM_AVALANCHA!B36,SIM_BOLA!B36)) | D33: =IF($B33="","",CHOOSE(EstrN,SIM_AVALANCHA!AH36,SIM_BOLA!AH36)) | E33: =IF($B33="","",CHOOSE(EstrN,SIM_AVALANCHA!AG36,SIM_BOLA!AG36)) | F33: =IF($B33="","",D33-E33) | G33: =IF($B33="","",CHOOSE(EstrN,SIM_AVALANCHA!AI36,SIM_BOLA!AI36)) | H33: =IF($B33="","",IF(CHOOSE(EstrN,SIM_AVALANCHA!AJ36,SIM_BOLA!AJ36)<=0,"-",IF(CHOOSE(EstrN,SIM_AVALANCHA!AK36,SIM_BOLA!AK36)=0,"",CHOOSE(EstrN,INDEX(SIM_AVALANCHA!$C$7:$L$7,SIM_AVALANCHA!AK36),INDEX(SIM_BOLA!$C$7:$L$7,SIM_BOLA!AK36)))))
B34: =IF(CHOOSE(EstrN,SIM_AVALANCHA!AI36,SIM_BOLA!AI36)<=0,"",27) | C34: =IF($B34="","",CHOOSE(EstrN,SIM_AVALANCHA!B37,SIM_BOLA!B37)) | D34: =IF($B34="","",CHOOSE(EstrN,SIM_AVALANCHA!AH37,SIM_BOLA!AH37)) | E34: =IF($B34="","",CHOOSE(EstrN,SIM_AVALANCHA!AG37,SIM_BOLA!AG37)) | F34: =IF($B34="","",D34-E34) | G34: =IF($B34="","",CHOOSE(EstrN,SIM_AVALANCHA!AI37,SIM_BOLA!AI37)) | H34: =IF($B34="","",IF(CHOOSE(EstrN,SIM_AVALANCHA!AJ37,SIM_BOLA!AJ37)<=0,"-",IF(CHOOSE(EstrN,SIM_AVALANCHA!AK37,SIM_BOLA!AK37)=0,"",CHOOSE(EstrN,INDEX(SIM_AVALANCHA!$C$7:$L$7,SIM_AVALANCHA!AK37),INDEX(SIM_BOLA!$C$7:$L$7,SIM_BOLA!AK37)))))
B35: =IF(CHOOSE(EstrN,SIM_AVALANCHA!AI37,SIM_BOLA!AI37)<=0,"",28) | C35: =IF($B35="","",CHOOSE(EstrN,SIM_AVALANCHA!B38,SIM_BOLA!B38)) | D35: =IF($B35="","",CHOOSE(EstrN,SIM_AVALANCHA!AH38,SIM_BOLA!AH38)) | E35: =IF($B35="","",CHOOSE(EstrN,SIM_AVALANCHA!AG38,SIM_BOLA!AG38)) | F35: =IF($B35="","",D35-E35) | G35: =IF($B35="","",CHOOSE(EstrN,SIM_AVALANCHA!AI38,SIM_BOLA!AI38)) | H35: =IF($B35="","",IF(CHOOSE(EstrN,SIM_AVALANCHA!AJ38,SIM_BOLA!AJ38)<=0,"-",IF(CHOOSE(EstrN,SIM_AVALANCHA!AK38,SIM_BOLA!AK38)=0,"",CHOOSE(EstrN,INDEX(SIM_AVALANCHA!$C$7:$L$7,SIM_AVALANCHA!AK38),INDEX(SIM_BOLA!$C$7:$L$7,SIM_BOLA!AK38)))))
B36: =IF(CHOOSE(EstrN,SIM_AVALANCHA!AI38,SIM_BOLA!AI38)<=0,"",29) | C36: =IF($B36="","",CHOOSE(EstrN,SIM_AVALANCHA!B39,SIM_BOLA!B39)) | D36: =IF($B36="","",CHOOSE(EstrN,SIM_AVALANCHA!AH39,SIM_BOLA!AH39)) | E36: =IF($B36="","",CHOOSE(EstrN,SIM_AVALANCHA!AG39,SIM_BOLA!AG39)) | F36: =IF($B36="","",D36-E36) | G36: =IF($B36="","",CHOOSE(EstrN,SIM_AVALANCHA!AI39,SIM_BOLA!AI39)) | H36: =IF($B36="","",IF(CHOOSE(EstrN,SIM_AVALANCHA!AJ39,SIM_BOLA!AJ39)<=0,"-",IF(CHOOSE(EstrN,SIM_AVALANCHA!AK39,SIM_BOLA!AK39)=0,"",CHOOSE(EstrN,INDEX(SIM_AVALANCHA!$C$7:$L$7,SIM_AVALANCHA!AK39),INDEX(SIM_BOLA!$C$7:$L$7,SIM_BOLA!AK39)))))
B37: =IF(CHOOSE(EstrN,SIM_AVALANCHA!AI39,SIM_BOLA!AI39)<=0,"",30) | C37: =IF($B37="","",CHOOSE(EstrN,SIM_AVALANCHA!B40,SIM_BOLA!B40)) | D37: =IF($B37="","",CHOOSE(EstrN,SIM_AVALANCHA!AH40,SIM_BOLA!AH40)) | E37: =IF($B37="","",CHOOSE(EstrN,SIM_AVALANCHA!AG40,SIM_BOLA!AG40)) | F37: =IF($B37="","",D37-E37) | G37: =IF($B37="","",CHOOSE(EstrN,SIM_AVALANCHA!AI40,SIM_BOLA!AI40)) | H37: =IF($B37="","",IF(CHOOSE(EstrN,SIM_AVALANCHA!AJ40,SIM_BOLA!AJ40)<=0,"-",IF(CHOOSE(EstrN,SIM_AVALANCHA!AK40,SIM_BOLA!AK40)=0,"",CHOOSE(EstrN,INDEX(SIM_AVALANCHA!$C$7:$L$7,SIM_AVALANCHA!AK40),INDEX(SIM_BOLA!$C$7:$L$7,SIM_BOLA!AK40)))))
B38: =IF(CHOOSE(EstrN,SIM_AVALANCHA!AI40,SIM_BOLA!AI40)<=0,"",31) | C38: =IF($B38="","",CHOOSE(EstrN,SIM_AVALANCHA!B41,SIM_BOLA!B41)) | D38: =IF($B38="","",CHOOSE(EstrN,SIM_AVALANCHA!AH41,SIM_BOLA!AH41)) | E38: =IF($B38="","",CHOOSE(EstrN,SIM_AVALANCHA!AG41,SIM_BOLA!AG41)) | F38: =IF($B38="","",D38-E38) | G38: =IF($B38="","",CHOOSE(EstrN,SIM_AVALANCHA!AI41,SIM_BOLA!AI41)) | H38: =IF($B38="","",IF(CHOOSE(EstrN,SIM_AVALANCHA!AJ41,SIM_BOLA!AJ41)<=0,"-",IF(CHOOSE(EstrN,SIM_AVALANCHA!AK41,SIM_BOLA!AK41)=0,"",CHOOSE(EstrN,INDEX(SIM_AVALANCHA!$C$7:$L$7,SIM_AVALANCHA!AK41),INDEX(SIM_BOLA!$C$7:$L$7,SIM_BOLA!AK41)))))
B39: =IF(CHOOSE(EstrN,SIM_AVALANCHA!AI41,SIM_BOLA!AI41)<=0,"",32) | C39: =IF($B39="","",CHOOSE(EstrN,SIM_AVALANCHA!B42,SIM_BOLA!B42)) | D39: =IF($B39="","",CHOOSE(EstrN,SIM_AVALANCHA!AH42,SIM_BOLA!AH42)) | E39: =IF($B39="","",CHOOSE(EstrN,SIM_AVALANCHA!AG42,SIM_BOLA!AG42)) | F39: =IF($B39="","",D39-E39) | G39: =IF($B39="","",CHOOSE(EstrN,SIM_AVALANCHA!AI42,SIM_BOLA!AI42)) | H39: =IF($B39="","",IF(CHOOSE(EstrN,SIM_AVALANCHA!AJ42,SIM_BOLA!AJ42)<=0,"-",IF(CHOOSE(EstrN,SIM_AVALANCHA!AK42,SIM_BOLA!AK42)=0,"",CHOOSE(EstrN,INDEX(SIM_AVALANCHA!$C$7:$L$7,SIM_AVALANCHA!AK42),INDEX(SIM_BOLA!$C$7:$L$7,SIM_BOLA!AK42)))))
B40: =IF(CHOOSE(EstrN,SIM_AVALANCHA!AI42,SIM_BOLA!AI42)<=0,"",33) | C40: =IF($B40="","",CHOOSE(EstrN,SIM_AVALANCHA!B43,SIM_BOLA!B43)) | D40: =IF($B40="","",CHOOSE(EstrN,SIM_AVALANCHA!AH43,SIM_BOLA!AH43)) | E40: =IF($B40="","",CHOOSE(EstrN,SIM_AVALANCHA!AG43,SIM_BOLA!AG43)) | F40: =IF($B40="","",D40-E40) | G40: =IF($B40="","",CHOOSE(EstrN,SIM_AVALANCHA!AI43,SIM_BOLA!AI43)) | H40: =IF($B40="","",IF(CHOOSE(EstrN,SIM_AVALANCHA!AJ43,SIM_BOLA!AJ43)<=0,"-",IF(CHOOSE(EstrN,SIM_AVALANCHA!AK43,SIM_BOLA!AK43)=0,"",CHOOSE(EstrN,INDEX(SIM_AVALANCHA!$C$7:$L$7,SIM_AVALANCHA!AK43),INDEX(SIM_BOLA!$C$7:$L$7,SIM_BOLA!AK43)))))
B41: =IF(CHOOSE(EstrN,SIM_AVALANCHA!AI43,SIM_BOLA!AI43)<=0,"",34) | C41: =IF($B41="","",CHOOSE(EstrN,SIM_AVALANCHA!B44,SIM_BOLA!B44)) | D41: =IF($B41="","",CHOOSE(EstrN,SIM_AVALANCHA!AH44,SIM_BOLA!AH44)) | E41: =IF($B41="","",CHOOSE(EstrN,SIM_AVALANCHA!AG44,SIM_BOLA!AG44)) | F41: =IF($B41="","",D41-E41) | G41: =IF($B41="","",CHOOSE(EstrN,SIM_AVALANCHA!AI44,SIM_BOLA!AI44)) | H41: =IF($B41="","",IF(CHOOSE(EstrN,SIM_AVALANCHA!AJ44,SIM_BOLA!AJ44)<=0,"-",IF(CHOOSE(EstrN,SIM_AVALANCHA!AK44,SIM_BOLA!AK44)=0,"",CHOOSE(EstrN,INDEX(SIM_AVALANCHA!$C$7:$L$7,SIM_AVALANCHA!AK44),INDEX(SIM_BOLA!$C$7:$L$7,SIM_BOLA!AK44)))))
B42: =IF(CHOOSE(EstrN,SIM_AVALANCHA!AI44,SIM_BOLA!AI44)<=0,"",35) | C42: =IF($B42="","",CHOOSE(EstrN,SIM_AVALANCHA!B45,SIM_BOLA!B45)) | D42: =IF($B42="","",CHOOSE(EstrN,SIM_AVALANCHA!AH45,SIM_BOLA!AH45)) | E42: =IF($B42="","",CHOOSE(EstrN,SIM_AVALANCHA!AG45,SIM_BOLA!AG45)) | F42: =IF($B42="","",D42-E42) | G42: =IF($B42="","",CHOOSE(EstrN,SIM_AVALANCHA!AI45,SIM_BOLA!AI45)) | H42: =IF($B42="","",IF(CHOOSE(EstrN,SIM_AVALANCHA!AJ45,SIM_BOLA!AJ45)<=0,"-",IF(CHOOSE(EstrN,SIM_AVALANCHA!AK45,SIM_BOLA!AK45)=0,"",CHOOSE(EstrN,INDEX(SIM_AVALANCHA!$C$7:$L$7,SIM_AVALANCHA!AK45),INDEX(SIM_BOLA!$C$7:$L$7,SIM_BOLA!AK45)))))
...

Sheet AJUSTES
C1: AJUSTES
B2: Herramientas inteligentes que simplifican tu vida. | C2: Cargalos una sola vez
B4: ← VOLVER | C4: Completá solamente las celdas amarillas. Estos datos alimentan las demás hojas automáticamente.
B6: 1. TU PLAN
B7: Nombre del plan | C7: Mi plan para salir de deudas | D7: Aparece en el PANEL.
B8: Moneda | C8: Gs. | D8: Símbolo que se muestra en las hojas.
B9: Mes en que empieza el plan | D9: Primer mes en que vas a pagar con este plan. Si lo dejás vacío se usa el mes actual.
B10: Mes de inicio que se usa | C10: =IF(C9="",DATE(YEAR(TODAY()),MONTH(TODAY()),1),DATE(YEAR(C9),MONTH(C9),1)) | D10: Se calcula solo.
B12: 2. TIPOS DE DEUDA (podés renombrarlos)
B13: Se usan en la lista desplegable de DEUDAS. Cambiá el nombre, pero no dejes huecos.
B14: Tarjeta de crédito | C14: Hasta 8 tipos.
B15: Préstamo bancario
B16: Financiera
B17: Casa comercial / cuotas
B18: Préstamo personal
B19: Cooperativa
B20: Hipoteca / vivienda
B21: Otra
B25: MIX SHOP DIGITAL · Herramientas inteligentes que simplifican tu vida.
B26: Versión gratuita · Más herramientas gratuitas para tu vida diaria → mixshopdigital.com.py

Sheet AYUDA
D1: AYUDA
B2: Herramientas inteligentes que simplifican tu vida. | D2: Se aprende en 2 minutos
B4: ← VOLVER | C4: Leé esta hoja una vez. Después ya no la vas a necesitar.
B6: ¿PARA QUÉ SIRVE?
B7: Para ordenar todas tus deudas (tarjetas, préstamos, financieras, cuotas), ver cuánto interés te cobran y armar un plan para dejar de deber: en qué orden pagar, cuánto tardás y cuánto ahorrás en intereses. Sin fórmulas y sin Internet.
B9: EMPEZÁ EN 3 PASOS
B10: 1) En DEUDAS escribí una fila por cada deuda: nombre, saldo (lo que debés hoy), tasa anual y cuota mínima. El resto es opcional.
B11: 2) En el PANEL elegí la estrategia y, si podés, un pago extra por mes además de las cuotas.
B12: 3) Mirá el PANEL: cuándo quedás libre de deudas, cuánto te ahorrás en intereses y en qué orden pagar. En PLAN MES A MES ves los primeros 3 años.
B14: LAS DOS ESTRATEGIAS
B15: Avalancha: además de las cuotas, el dinero extra va a la deuda con la tasa más alta. Es la que menos intereses te cobra en total.
B16: Bola de nieve: el dinero extra va a la deuda más chica. Cerrás deudas rápido y eso motiva, aunque pagues algo más de intereses.
B17: En las dos, cuando terminás una deuda, su cuota se suma al extra y se usa para la siguiente.
B19: COLORES Y AVISOS
B20: Amarillo claro: celdas que completás vos. Gris o blanco: se calcula solo (bloqueado).
... B41: Versión gratuita · Más herramientas gratuitas para tu vida diaria → mixshopdigital.com.py

Sheet SIM_AVALANCHA
A1: AVALANCHA: se paga primero la deuda con la tasa más alta
A2: Posición | C2: 1 | D2: 2 | E2: 3 | F2: 4 | G2: 5 | H2: 6 | I2: 7 | J2: 8 | K2: 9 | L2: 10 | AM2: Meses hasta liberarte | AN2: =IF(AI10<=0,0,IFERROR(MATCH(0,AI10:AI130,0)-1,999))
A3: N° de deuda | C3: =IFERROR(MATCH(C$2,RankA,0),0) | D3: =IFERROR(MATCH(D$2,RankA,0),0) | E3: =IFERROR(MATCH(E$2,RankA,0),0) | F3: =IFERROR(MATCH(F$2,RankA,0),0) | G3: =IFERROR(MATCH(G$2,RankA,0),0) | H3: =IFERROR(MATCH(H$2,RankA,0),0) | I3: =IFERROR(MATCH(I$2,RankA,0),0) | J3: =IFERROR(MATCH(J$2,RankA,0),0) | ... L3: =IFERROR(MATCH(L$2,RankA,0),0) | AM3: Intereses totales | AN3: =SUM(AG11:AG130)
A4: Saldo hoy | C4: =IF(C$3=0,0,INDEX(DeuSal,C$3)) | D4: =IF(D$3=0,0,INDEX(DeuSal,D$3)) | E4: =IF(E$3=0,0,INDEX(DeuSal,E$3)) | F4: =IF(F$3=0,0,INDEX(DeuSal,F$3)) | G4: =IF(G$3=0,0,INDEX(DeuSal,G$3)) | H4: =IF(H$3=0,0,INDEX(DeuSal,H$3)) | I4: =IF(I$3=0,0,INDEX(DeuSal,I$3)) | J4: =IF(J$3=0,0,INDEX(DeuSal,J$3)) | ... L4: =IF(L$3=0,0,INDEX(DeuSal,L$3)) | AM4: Total pagado | AN4: =SUM(AH11:AH130)
A5: Tasa mensual | C5: =IF(C$3=0,0,INDEX(DeuTasa,C$3)/12) | D5: =IF(D$3=0,0,INDEX(DeuTasa,D$3)/12) | E5: =IF(E$3=0,0,INDEX(DeuTasa,E$3)/12) | F5: =IF(F$3=0,0,INDEX(DeuTasa,F$3)/12) | G5: =IF(G$3=0,0,INDEX(DeuTasa,G$3)/12) | H5: =IF(H$3=0,0,INDEX(DeuTasa,H$3)/12) | I5: =IF(I$3=0,0,INDEX(DeuTasa,I$3)/12) | J5: =IF(J$3=0,0,INDEX(DeuTasa,J$3)/12) | ... L5: =IF(L$3=0,0,INDEX(DeuTasa,L$3)/12)
A6: Cuota | C6: =IF(C$3=0,0,INDEX(DeuCuota,C$3)) | D6: =IF(D$3=0,0,INDEX(DeuCuota,D$3)) | E6: =IF(E$3=0,0,INDEX(DeuCuota,E$3)) | F6: =IF(F$3=0,0,INDEX(DeuCuota,F$3)) | G6: =IF(G$3=0,0,INDEX(DeuCuota,G$3)) | H6: =IF(H$3=0,0,INDEX(DeuCuota,H$3)) | I6: =IF(I$3=0,0,INDEX(DeuCuota,I$3)) | J6: =IF(J$3=0,0,INDEX(DeuCuota,J$3)) | ... L6: =IF(L$3=0,0,INDEX(DeuCuota,L$3))
A7: Deuda | C7: =IF(C$4>0,INDEX(DeuNom,C$3)&"","") | D7: =IF(D$4>0,INDEX(DeuNom,D$3)&"","") | E7: =IF(E$4>0,INDEX(DeuNom,E$3)&"","") | F7: =IF(F$4>0,INDEX(DeuNom,F$3)&"","") | G7: =IF(G$4>0,INDEX(DeuNom,G$3)&"","") | H7: =IF(H$4>0,INDEX(DeuNom,H$3)&"","") | I7: =IF(I$4>0,INDEX(DeuNom,I$3)&"","") | J7: =IF(J$4>0,INDEX(DeuNom,J$3)&"","") | ... L7: =IF(L$4>0,INDEX(DeuNom,L$3)&"","")
A8: Termina en el mes | C8: =IF(C$4<=0,0,IFERROR(MATCH(0,W$10:W$130,0)-1,999)) | D8: =IF(D$4<=0,0,IFERROR(MATCH(0,X$10:X$130,0)-1,999)) | E8: =IF(E$4<=0,0,IFERROR(MATCH(0,Y$10:Y$130,0)-1,999)) | F8: =IF(F$4<=0,0,IFERROR(MATCH(0,Z$10:Z$130,0)-1,999)) | G8: =IF(G$4<=0,0,IFERROR(MATCH(0,AA$10:AA$130,0)-1,999)) | H8: =IF(H$4<=0,0,IFERROR(MATCH(0,AB$10:AB$130,0)-1,999)) | I8: =IF(I$4<=0,0,IFERROR(MATCH(0,AC$10:AC$130,0)-1,999)) | J8: =IF(J$4<=0,0,IFERROR(MATCH(0,AD$10:AD$130,0)-1,999)) | ... L8: =IF(L$4<=0,0,IFERROR(MATCH(0,AF$10:AF$130,0)-1,999))
A9: Mes | B9: Fecha | C9: Mín 1 | D9: Mín 2 | E9: Mín 3 | F9: Mín 4 | G9: Mín 5 | H9: Mín 6 | I9: Mín 7 | J9: Mín 8 | K9: Mín 9 | L9: Mín 10 | M9: Extra 1 | N9: Extra 2 | O9: Extra 3 | P9: Extra 4 | Q9: Extra 5 | R9: Extra 6 | S9: Extra 7 | T9: Extra 8 | U9: Extra 9 | V9: Extra 10 | W9: Saldo 1 | X9: Saldo 2 | Y9: Saldo 3 | Z9: Saldo 4 | AA9: Saldo 5 | AB9: Saldo 6 | AC9: Saldo 7 | AD9: Saldo 8 | AE9: Saldo 9 | AF9: Saldo 10 | AG9: Intereses | AH9: Pago total | AI9: Saldo total | AJ9: Pozo extra | AK9: Objetivo
A10: 0 | B10: Hoy | W10: =C$4 | X10: =D$4 | Y10: =E$4 | Z10: =F$4 | AA10: =G$4 | AB10: =H$4 | AC10: =I$4 | AD10: =J$4 | ... AF10: =L$4 | AI10: =SUM(W10:AF10)
A11: 1 | B11: =DATE(YEAR(InicioEf),MONTH(InicioEf)+A11-1,1) | C11: =MIN(C$6,ROUND(W10*(1+C$5),0)) | D11: =MIN(D$6,ROUND(X10*(1+D$5),0)) | E11: =MIN(E$6,ROUND(Y10*(1+E$5),0)) | F11: =MIN(F$6,ROUND(Z10*(1+F$5),0)) | G11: =MIN(G$6,ROUND(AA10*(1+G$5),0)) | H11: =MIN(H$6,ROUND(AB10*(1+H$5),0)) | I11: =MIN(I$6,ROUND(AC10*(1+I$5),0)) | J11: =MIN(J$6,ROUND(AD10*(1+J$5),0)) | ... L11: =MIN(L$6,ROUND(AF10*(1+L$5),0)) | M11: =MAX(0,MIN(ROUND(W10*(1+C$5),0)-C11,$AJ11-0)) | N11: =MAX(0,MIN(ROUND(X10*(1+D$5),0)-D11,$AJ11-SUM($M11:M11))) | O11: =MAX(0,MIN(ROUND(Y10*(1+E$5),0)-E11,$AJ11-SUM($M11:N11))) | P11: =MAX(0,MIN(ROUND(Z10*(1+F$5),0)-F11,$AJ11-SUM($M11:O11))) | Q11: =MAX(0,MIN(ROUND(AA10*(1+G$5),0)-G11,$AJ11-SUM($M11:P11))) | R11: =MAX(0,MIN(ROUND(AB10*(1+H$5),0)-H11,$AJ11-SUM($M11:Q11))) | S11: =MAX(0,MIN(ROUND(AC10*(1+I$5),0)-I11,$AJ11-SUM($M11:R11))) | T11: =MAX(0,MIN(ROUND(AD10*(1+J$5),0)-J11,$AJ11-SUM($M11:S11))) | U11: =MAX(0,MIN(ROUND(AE10*(1+K$5),0)-K11,$AJ11-SUM($M11:T11))) | V11: =MAX(0,MIN(ROUND(AF10*(1+L$5),0)-L11,$AJ11-SUM($M11:U11))) | W11: =MAX(0,ROUND(W10*(1+C$5),0)-C11-M11) | X11: =MAX(0,ROUND(X10*(1+D$5),0)-D11-N11) | Y11: =MAX(0,ROUND(Y10*(1+E$5),0)-E11-O11) | Z11: =MAX(0,ROUND(Z10*(1+F$5),0)-F11-P11) | AA11: =MAX(0,ROUND(AA10*(1+G$5),0)-G11-Q11) | AB11: =MAX(0,ROUND(AB10*(1+H$5),0)-H11-R11) | AC11: =MAX(0,ROUND(AC10*(1+I$5),0)-I11-S11) | AD11: =MAX(0,ROUND(AD10*(1+J$5),0)-J11-T11) | ... AF11: =MAX(0,ROUND(AF10*(1+L$5),0)-L11-V11) | AG11: =AH11-(AI10-AI11) | AH11: =SUM(C11:V11) | AI11: =SUM(W11:AF11) | AJ11: =MAX(0,PresTot-SUM(C11:L11)) | AK11: =IF(AI10<=0,0,11-SUMPRODUCT(MAX((W10:AF10>0)*(11-(COLUMN(W10:AF10)-COLUMN($V10))))))
A12: 2 | B12: =DATE(YEAR(InicioEf),MONTH(InicioEf)+A12-1,1) | C12: =MIN(C$6,ROUND(W11*(1+C$5),0)) | D12: =MIN(D$6,ROUND(X11*(1+D$5),0)) | E12: =MIN(E$6,ROUND(Y11*(1+E$5),0)) | F12: =MIN(F$6,ROUND(Z11*(1+F$5),0)) | G12: =MIN(G$6,ROUND(AA11*(1+G$5),0)) | H12: =MIN(H$6,ROUND(AB11*(1+H$5),0)) | I12: =MIN(I$6,ROUND(AC11*(1+I$5),0)) | J12: =MIN(J$6,ROUND(AD11*(1+J$5),0)) | ... L12: =MIN(L$6,ROUND(AF11*(1+L$5),0)) | M12: =MAX(0,MIN(ROUND(W11*(1+C$5),0)-C12,$AJ12-0)) | N12: =MAX(0,MIN(ROUND(X11*(1+D$5),0)-D12,$AJ12-SUM($M12:M12))) | O12: =MAX(0,MIN(ROUND(Y11*(1+E$5),0)-E12,$AJ12-SUM($M12:N12))) | P12: =MAX(0,MIN(ROUND(Z11*(1+F$5),0)-F12,$AJ12-SUM($M12:O12))) | Q12: =MAX(0,MIN(ROUND(AA11*(1+G$5),0)-G12,$AJ12-SUM($M12:P12))) | R12: =MAX(0,MIN(ROUND(AB11*(1+H$5),0)-H12,$AJ12-SUM($M12:Q12))) | S12: =MAX(0,MIN(ROUND(AC11*(1+I$5),0)-I12,$AJ12-SUM($M12:R12))) | T12: =MAX(0,MIN(ROUND(AD11*(1+J$5),0)-J12,$AJ12-SUM($M12:S12))) | U12: =MAX(0,MIN(ROUND(AE11*(1+K$5),0)-K12,$AJ12-SUM($M12:T12))) | V12: =MAX(0,MIN(ROUND(AF11*(1+L$5),0)-L12,$AJ12-SUM($M12:U12))) | W12: =MAX(0,ROUND(W11*(1+C$5),0)-C12-M12) | X12: =MAX(0,ROUND(X11*(1+D$5),0)-D12-N12) | Y12: =MAX(0,ROUND(Y11*(1+E$5),0)-E12-O12) | Z12: =MAX(0,ROUND(Z11*(1+F$5),0)-F12-P12) | AA12: =MAX(0,ROUND(AA11*(1+G$5),0)-G12-Q12) | AB12: =MAX(0,ROUND(AB11*(1+H$5),0)-H12-R12) | AC12: =MAX(0,ROUND(AC11*(1+I$5),0)-I12-S12) | AD12: =MAX(0,ROUND(AD11*(1+J$5),0)-J12-T12) | ... AF12: =MAX(0,ROUND(AF11*(1+L$5),0)-L12-V12) | AG12: =AH12-(AI11-AI12) | AH12: =SUM(C12:V12) | AI12: =SUM(W12:AF12) | AJ12: =MAX(0,PresTot-SUM(C12:L12)) | AK12: =IF(AI11<=0,0,11-SUMPRODUCT(MAX((W11:AF11>0)*(11-(COLUMN(W11:AF11)-COLUMN($V11))))))
