Workbook
Name NombreNegocio: 'AJUSTES'!$C$7
Name AnioCtl: 'AJUSTES'!$C$8
Name Moneda: 'AJUSTES'!$C$9
Name MetaMes: 'AJUSTES'!$C$10
Name CatIng: 'AJUSTES'!$B$15:$B$20
Name CatGas: 'AJUSTES'!$C$15:$C$24
Name MesN: 'PANEL'!$P$6
Name FIni: 'PANEL'!$P$7
Name FFin: 'PANEL'!$P$8

Sheet PANEL
B1: MIX SHOP DIGITAL | F1: CONTROL DE VENTAS Y GASTOS
B2: Herramientas inteligentes que simplifican tu vida. | F2: Tu negocio, de un vistazo
C4: El panel se arma solo con lo que anotás en MOVIMIENTOS. No hace falta escribir nada acá, salvo elegir el período.
B5: + Anotar movimientos | E5: Ajustes | G5: Ayuda
B6: Período a mirar: | C6: Todo el año | E6: ="Año de control: "&AnioCtl&" · "&NombreNegocio | P6: =IFERROR(MATCH(C6,{"Todo el año","Enero","Febrero","Marzo","Abril","Mayo","Junio","Julio","Agosto","Septiembre","Octubre","Noviembre","Diciembre"},0)-1,0)
P7: =IF(P6=0,DATE(AnioCtl,1,1),DATE(AnioCtl,P6,1))
B8: INGRESOS DEL PERÍODO | E8: GASTOS DEL PERÍODO | H8: GANANCIA | K8: MARGEN | P8: =IF(P6=0,DATE(AnioCtl+1,1,1),DATE(AnioCtl,P6+1,1))
B9: =IF(MesN=0,C29,INDEX(C17:C28,MesN)) | E9: =IF(MesN=0,D29,INDEX(D17:D28,MesN)) | H9: =B9-E9 | K9: =IF(B9=0,0,H9/B9)
B10: =Moneda | E10: =Moneda | H10: ingresos − gastos | K10: qué parte de lo que vendés es ganancia
B12: =IF(AND(B9=0,E9=0),"Anotá tus primeros movimientos en la hoja MOVIMIENTOS para ver tu panel.",IF(H9<0,"✖ Pérdida: gastaste más de lo que vendiste en este período.",IF(K9<0.1,"⚠ Ganás poco: menos del 10 % de lo que vendés. Revisá tus gastos.","✔ Muy bien: te quedó el "&ROUND(K9*100,1)&" % de lo que vendiste.")))
B13: Tu meta: | C13: =IF(MesN=0,MetaMes*12,MetaMes) | E13: =IF(C13<=0,0,MAX(0,MIN(1,H9/C13)))
B15: MES A MES
B16: Mes | C16: Ingresos | D16: Gastos | E16: Ganancia | F16: Acumulado
B17: Enero | C17: =SUMIFS('MOVIMIENTOS'!$F$7:$F$406,'MOVIMIENTOS'!$C$7:$C$406,"Ingreso",'MOVIMIENTOS'!$B$7:$B$406,">="&DATE(AnioCtl,1,1),'MOVIMIENTOS'!$B$7:$B$406,"<"&DATE(AnioCtl,2,1)) | D17: =SUMIFS('MOVIMIENTOS'!$F$7:$F$406,'MOVIMIENTOS'!$C$7:$C$406,"Gasto",'MOVIMIENTOS'!$B$7:$B$406,">="&DATE(AnioCtl,1,1),'MOVIMIENTOS'!$B$7:$B$406,"<"&DATE(AnioCtl,2,1)) | E17: =C17-D17 | F17: =SUM($E$17:E17)
B18: Febrero | C18: =SUMIFS('MOVIMIENTOS'!$F$7:$F$406,'MOVIMIENTOS'!$C$7:$C$406,"Ingreso",'MOVIMIENTOS'!$B$7:$B$406,">="&DATE(AnioCtl,2,1),'MOVIMIENTOS'!$B$7:$B$406,"<"&DATE(AnioCtl,3,1)) | D18: =SUMIFS('MOVIMIENTOS'!$F$7:$F$406,'MOVIMIENTOS'!$C$7:$C$406,"Gasto",'MOVIMIENTOS'!$B$7:$B$406,">="&DATE(AnioCtl,2,1),'MOVIMIENTOS'!$B$7:$B$406,"<"&DATE(AnioCtl,3,1)) | E18: =C18-D18 | F18: =SUM($E$17:E18)
B19: Marzo | C19: =SUMIFS('MOVIMIENTOS'!$F$7:$F$406,'MOVIMIENTOS'!$C$7:$C$406,"Ingreso",'MOVIMIENTOS'!$B$7:$B$406,">="&DATE(AnioCtl,3,1),'MOVIMIENTOS'!$B$7:$B$406,"<"&DATE(AnioCtl,4,1)) | D19: =SUMIFS('MOVIMIENTOS'!$F$7:$F$406,'MOVIMIENTOS'!$C$7:$C$406,"Gasto",'MOVIMIENTOS'!$B$7:$B$406,">="&DATE(AnioCtl,3,1),'MOVIMIENTOS'!$B$7:$B$406,"<"&DATE(AnioCtl,4,1)) | E19: =C19-D19 | F19: =SUM($E$17:E19)
B20: Abril | C20: =SUMIFS('MOVIMIENTOS'!$F$7:$F$406,'MOVIMIENTOS'!$C$7:$C$406,"Ingreso",'MOVIMIENTOS'!$B$7:$B$406,">="&DATE(AnioCtl,4,1),'MOVIMIENTOS'!$B$7:$B$406,"<"&DATE(AnioCtl,5,1)) | D20: =SUMIFS('MOVIMIENTOS'!$F$7:$F$406,'MOVIMIENTOS'!$C$7:$C$406,"Gasto",'MOVIMIENTOS'!$B$7:$B$406,">="&DATE(AnioCtl,4,1),'MOVIMIENTOS'!$B$7:$B$406,"<"&DATE(AnioCtl,5,1)) | E20: =C20-D20 | F20: =SUM($E$17:E20)
B21: Mayo | C21: =SUMIFS('MOVIMIENTOS'!$F$7:$F$406,'MOVIMIENTOS'!$C$7:$C$406,"Ingreso",'MOVIMIENTOS'!$B$7:$B$406,">="&DATE(AnioCtl,5,1),'MOVIMIENTOS'!$B$7:$B$406,"<"&DATE(AnioCtl,6,1)) | D21: =SUMIFS('MOVIMIENTOS'!$F$7:$F$406,'MOVIMIENTOS'!$C$7:$C$406,"Gasto",'MOVIMIENTOS'!$B$7:$B$406,">="&DATE(AnioCtl,5,1),'MOVIMIENTOS'!$B$7:$B$406,"<"&DATE(AnioCtl,6,1)) | E21: =C21-D21 | F21: =SUM($E$17:E21)
B22: Junio | C22: =SUMIFS('MOVIMIENTOS'!$F$7:$F$406,'MOVIMIENTOS'!$C$7:$C$406,"Ingreso",'MOVIMIENTOS'!$B$7:$B$406,">="&DATE(AnioCtl,6,1),'MOVIMIENTOS'!$B$7:$B$406,"<"&DATE(AnioCtl,7,1)) | D22: =SUMIFS('MOVIMIENTOS'!$F$7:$F$406,'MOVIMIENTOS'!$C$7:$C$406,"Gasto",'MOVIMIENTOS'!$B$7:$B$406,">="&DATE(AnioCtl,6,1),'MOVIMIENTOS'!$B$7:$B$406,"<"&DATE(AnioCtl,7,1)) | E22: =C22-D22 | F22: =SUM($E$17:E22)
B23: Julio | C23: =SUMIFS('MOVIMIENTOS'!$F$7:$F$406,'MOVIMIENTOS'!$C$7:$C$406,"Ingreso",'MOVIMIENTOS'!$B$7:$B$406,">="&DATE(AnioCtl,7,1),'MOVIMIENTOS'!$B$7:$B$406,"<"&DATE(AnioCtl,8,1)) | D23: =SUMIFS('MOVIMIENTOS'!$F$7:$F$406,'MOVIMIENTOS'!$C$7:$C$406,"Gasto",'MOVIMIENTOS'!$B$7:$B$406,">="&DATE(AnioCtl,7,1),'MOVIMIENTOS'!$B$7:$B$406,"<"&DATE(AnioCtl,8,1)) | E23: =C23-D23 | F23: =SUM($E$17:E23)
B24: Agosto | C24: =SUMIFS('MOVIMIENTOS'!$F$7:$F$406,'MOVIMIENTOS'!$C$7:$C$406,"Ingreso",'MOVIMIENTOS'!$B$7:$B$406,">="&DATE(AnioCtl,8,1),'MOVIMIENTOS'!$B$7:$B$406,"<"&DATE(AnioCtl,9,1)) | D24: =SUMIFS('MOVIMIENTOS'!$F$7:$F$406,'MOVIMIENTOS'!$C$7:$C$406,"Gasto",'MOVIMIENTOS'!$B$7:$B$406,">="&DATE(AnioCtl,8,1),'MOVIMIENTOS'!$B$7:$B$406,"<"&DATE(AnioCtl,9,1)) | E24: =C24-D24 | F24: =SUM($E$17:E24)
B25: Septiembre | C25: =SUMIFS('MOVIMIENTOS'!$F$7:$F$406,'MOVIMIENTOS'!$C$7:$C$406,"Ingreso",'MOVIMIENTOS'!$B$7:$B$406,">="&DATE(AnioCtl,9,1),'MOVIMIENTOS'!$B$7:$B$406,"<"&DATE(AnioCtl,10,1)) | D25: =SUMIFS('MOVIMIENTOS'!$F$7:$F$406,'MOVIMIENTOS'!$C$7:$C$406,"Gasto",'MOVIMIENTOS'!$B$7:$B$406,">="&DATE(AnioCtl,9,1),'MOVIMIENTOS'!$B$7:$B$406,"<"&DATE(AnioCtl,10,1)) | E25: =C25-D25 | F25: =SUM($E$17:E25)
B26: Octubre | C26: =SUMIFS('MOVIMIENTOS'!$F$7:$F$406,'MOVIMIENTOS'!$C$7:$C$406,"Ingreso",'MOVIMIENTOS'!$B$7:$B$406,">="&DATE(AnioCtl,10,1),'MOVIMIENTOS'!$B$7:$B$406,"<"&DATE(AnioCtl,11,1)) | D26: =SUMIFS('MOVIMIENTOS'!$F$7:$F$406,'MOVIMIENTOS'!$C$7:$C$406,"Gasto",'MOVIMIENTOS'!$B$7:$B$406,">="&DATE(AnioCtl,10,1),'MOVIMIENTOS'!$B$7:$B$406,"<"&DATE(AnioCtl,11,1)) | E26: =C26-D26 | F26: =SUM($E$17:E26)
B27: Noviembre | C27: =SUMIFS('MOVIMIENTOS'!$F$7:$F$406,'MOVIMIENTOS'!$C$7:$C$406,"Ingreso",'MOVIMIENTOS'!$B$7:$B$406,">="&DATE(AnioCtl,11,1),'MOVIMIENTOS'!$B$7:$B$406,"<"&DATE(AnioCtl,12,1)) | D27: =SUMIFS('MOVIMIENTOS'!$F$7:$F$406,'MOVIMIENTOS'!$C$7:$C$406,"Gasto",'MOVIMIENTOS'!$B$7:$B$406,">="&DATE(AnioCtl,11,1),'MOVIMIENTOS'!$B$7:$B$406,"<"&DATE(AnioCtl,12,1)) | E27: =C27-D27 | F27: =SUM($E$17:E27)
B28: Diciembre | C28: =SUMIFS('MOVIMIENTOS'!$F$7:$F$406,'MOVIMIENTOS'!$C$7:$C$406,"Ingreso",'MOVIMIENTOS'!$B$7:$B$406,">="&DATE(AnioCtl,12,1),'MOVIMIENTOS'!$B$7:$B$406,"<"&DATE(AnioCtl,13,1)) | D28: =SUMIFS('MOVIMIENTOS'!$F$7:$F$406,'MOVIMIENTOS'!$C$7:$C$406,"Gasto",'MOVIMIENTOS'!$B$7:$B$406,">="&DATE(AnioCtl,12,1),'MOVIMIENTOS'!$B$7:$B$406,"<"&DATE(AnioCtl,13,1)) | E28: =C28-D28 | F28: =SUM($E$17:E28)
B29: TOTAL | C29: =SUM(C17:C28) | D29: =SUM(D17:D28) | E29: =SUM(E17:E28) | F29: =F28
B31: ¿EN QUÉ SE VA TU PLATA? (gastos del período elegido)
B32: Categoría de gasto | D32: Monto | E32: %
B33: =IF('AJUSTES'!$C$15="","",'AJUSTES'!$C$15) | D33: =IF(B33="",0,SUMIFS('MOVIMIENTOS'!$F$7:$F$406,'MOVIMIENTOS'!$C$7:$C$406,"Gasto",'MOVIMIENTOS'!$D$7:$D$406,B33,'MOVIMIENTOS'!$B$7:$B$406,">="&FIni,'MOVIMIENTOS'!$B$7:$B$406,"<"&FFin)) | E33: =IF($E$9=0,0,D33/$E$9)
B34: =IF('AJUSTES'!$C$16="","",'AJUSTES'!$C$16) | D34: =IF(B34="",0,SUMIFS('MOVIMIENTOS'!$F$7:$F$406,'MOVIMIENTOS'!$C$7:$C$406,"Gasto",'MOVIMIENTOS'!$D$7:$D$406,B34,'MOVIMIENTOS'!$B$7:$B$406,">="&FIni,'MOVIMIENTOS'!$B$7:$B$406,"<"&FFin)) | E34: =IF($E$9=0,0,D34/$E$9)
B35: =IF('AJUSTES'!$C$17="","",'AJUSTES'!$C$17) | D35: =IF(B35="",0,SUMIFS('MOVIMIENTOS'!$F$7:$F$406,'MOVIMIENTOS'!$C$7:$C$406,"Gasto",'MOVIMIENTOS'!$D$7:$D$406,B35,'MOVIMIENTOS'!$B$7:$B$406,">="&FIni,'MOVIMIENTOS'!$B$7:$B$406,"<"&FFin)) | E35: =IF($E$9=0,0,D35/$E$9)
B36: =IF('AJUSTES'!$C$18="","",'AJUSTES'!$C$18) | D36: =IF(B36="",0,SUMIFS('MOVIMIENTOS'!$F$7:$F$406,'MOVIMIENTOS'!$C$7:$C$406,"Gasto",'MOVIMIENTOS'!$D$7:$D$406,B36,'MOVIMIENTOS'!$B$7:$B$406,">="&FIni,'MOVIMIENTOS'!$B$7:$B$406,"<"&FFin)) | E36: =IF($E$9=0,0,D36/$E$9)
B37: =IF('AJUSTES'!$C$19="","",'AJUSTES'!$C$19) | D37: =IF(B37="",0,SUMIFS('MOVIMIENTOS'!$F$7:$F$406,'MOVIMIENTOS'!$C$7:$C$406,"Gasto",'MOVIMIENTOS'!$D$7:$D$406,B37,'MOVIMIENTOS'!$B$7:$B$406,">="&FIni,'MOVIMIENTOS'!$B$7:$B$406,"<"&FFin)) | E37: =IF($E$9=0,0,D37/$E$9)
B38: =IF('AJUSTES'!$C$20="","",'AJUSTES'!$C$20) | D38: =IF(B38="",0,SUMIFS('MOVIMIENTOS'!$F$7:$F$406,'MOVIMIENTOS'!$C$7:$C$406,"Gasto",'MOVIMIENTOS'!$D$7:$D$406,B38,'MOVIMIENTOS'!$B$7:$B$406,">="&FIni,'MOVIMIENTOS'!$B$7:$B$406,"<"&FFin)) | E38: =IF($E$9=0,0,D38/$E$9)
B39: =IF('AJUSTES'!$C$21="","",'AJUSTES'!$C$21) | D39: =IF(B39="",0,SUMIFS('MOVIMIENTOS'!$F$7:$F$406,'MOVIMIENTOS'!$C$7:$C$406,"Gasto",'MOVIMIENTOS'!$D$7:$D$406,B39,'MOVIMIENTOS'!$B$7:$B$406,">="&FIni,'MOVIMIENTOS'!$B$7:$B$406,"<"&FFin)) | E39: =IF($E$9=0,0,D39/$E$9)
B40: =IF('AJUSTES'!$C$22="","",'AJUSTES'!$C$22) | D40: =IF(B40="",0,SUMIFS('MOVIMIENTOS'!$F$7:$F$406,'MOVIMIENTOS'!$C$7:$C$406,"Gasto",'MOVIMIENTOS'!$D$7:$D$406,B40,'MOVIMIENTOS'!$B$7:$B$406,">="&FIni,'MOVIMIENTOS'!$B$7:$B$406,"<"&FFin)) | E40: =IF($E$9=0,0,D40/$E$9)
B41: =IF('AJUSTES'!$C$23="","",'AJUSTES'!$C$23) | D41: =IF(B41="",0,SUMIFS('MOVIMIENTOS'!$F$7:$F$406,'MOVIMIENTOS'!$C$7:$C$406,"Gasto",'MOVIMIENTOS'!$D$7:$D$406,B41,'MOVIMIENTOS'!$B$7:$B$406,">="&FIni,'MOVIMIENTOS'!$B$7:$B$406,"<"&FFin)) | E41: =IF($E$9=0,0,D41/$E$9)
B42: =IF('AJUSTES'!$C$24="","",'AJUSTES'!$C$24) | D42: =IF(B42="",0,SUMIFS('MOVIMIENTOS'!$F$7:$F$406,'MOVIMIENTOS'!$C$7:$C$406,"Gasto",'MOVIMIENTOS'!$D$7:$D$406,B42,'MOVIMIENTOS'!$B$7:$B$406,">="&FIni,'MOVIMIENTOS'!$B$7:$B$406,"<"&FFin)) | E42: =IF($E$9=0,0,D42/$E$9)
B43: Sin categoría / otras | D43: =MAX(0,E9-SUM(D33:D42)) | E43: =IF($E$9=0,0,D43/$E$9)
B44: TOTAL | D44: =SUM(D33:D43) | E44: =SUM(E33:E43)
...

Sheet MOVIMIENTOS
B1: MIX SHOP DIGITAL | D1: MOVIMIENTOS
B2: Herramientas inteligentes que simplifican tu vida. | D2: Anotá cada venta y cada gasto
B4: ← PANEL | C4: Una fila por movimiento. Completá solamente las celdas amarillas. Podés ordenar y filtrar con la fila de títulos.
B5: ="Registros cargados: "&COUNT(F7:F406)&" de 400 · Ingresos del año: "&FIXED(PANEL!C29,0)&" · Gastos del año: "&FIXED(PANEL!D29,0)&" "&Moneda
B6: Fecha | C6: Tipo | D6: Categoría | E6: Detalle (opcional) | F6: Monto
B7: 46023 | C7: Gasto | D7: Publicidad | E7: Ejemplo: anuncios en redes | F7: 600000
B8: 46024 | C8: Gasto | D8: Alquiler | E8: Ejemplo: alquiler del local | F8: 1500000
B9: 46028 | C9: Ingreso | D9: Ventas de servicios | E9: Ejemplo: venta | F9: 1110000
B10: 46029 | C10: Gasto | D10: Servicios (luz, agua, internet) | E10: Ejemplo: luz, agua e internet | F10: 420000
B11: 46030 | C11: Gasto | D11: Sueldos y mano de obra | E11: Ejemplo: ayudante | F11: 2200000
B12: 46032 | C12: Ingreso | D12: Ventas de productos | E12: Ejemplo: venta | F12: 1530000
B13: 46037 | C13: Ingreso | D13: Ventas online | E13: Ejemplo: venta | F13: 675000
B14: 46037 | C14: Gasto | D14: Comisiones y bancos | E14: Ejemplo: comisión de tarjeta | F14: 50000
B15: 46040 | C15: Ingreso | D15: Ventas de productos | E15: Ejemplo: venta | F15: 1000000
B16: 46042 | C16: Ingreso | D16: Ventas de servicios | E16: Ejemplo: venta | F16: 1140000
B17: 46042 | C17: Gasto | D17: Mercadería e insumos | E17: Ejemplo: compra de mercadería | F17: 2925000
B18: 46043 | C18: Ingreso | D18: Ventas de productos | E18: Ejemplo: venta | F18: 985000
... B150: 46322 | C150: Gasto | D150: Sueldos y mano de obra | E150: Ejemplo: ayudante | F150: 2200000
B409: MIX SHOP DIGITAL · Herramientas inteligentes que simplifican tu vida.
B410: Versión gratuita · Para gestionar todo tu negocio en un solo lugar, conocé Mi Negocio PY → mixshopdigital.com.py

Sheet AJUSTES
B1: MIX SHOP DIGITAL | C1: AJUSTES
B2: Herramientas inteligentes que simplifican tu vida. | C2: Cargalos una sola vez
B4: ← PANEL | C4: Completá solamente las celdas amarillas. Estos datos alimentan el PANEL automáticamente.
B6: 1. TU NEGOCIO
B7: Nombre del negocio | C7: Tienda de María (EJEMPLO) | D7: Aparece en el PANEL.
B8: Año a controlar | C8: 2026 | D8: El PANEL muestra los 12 meses de este año. Los movimientos de otros años se ignoran.
B9: Moneda | C9: Gs. | D9: Símbolo que se muestra en el PANEL.
B10: Meta de ganancia por mes | C10: 3000000 | D10: Cuánto querés ganar por mes. El PANEL te muestra cuánto te falta. Si no tenés meta, dejala en 0.
B12: 2. TUS CATEGORÍAS (podés renombrarlas)
B13: Se usan en las listas desplegables de MOVIMIENTOS. Cambiá el nombre, pero no dejes huecos entre medio.
B14: Categorías de INGRESO | C14: Categorías de GASTO
B15: Ventas de productos | C15: Mercadería e insumos | D15: Ingresos: hasta 6 categorías.
B16: Ventas de servicios | C16: Alquiler | D16: Gastos: hasta 10 categorías (el PANEL las muestra todas).
B17: Ventas online | C17: Servicios (luz, agua, internet)
B18: Otros ingresos | C18: Sueldos y mano de obra
C19: Publicidad
C20: Transporte y envíos
C21: Impuestos
C22: Comisiones y bancos
C23: Mantenimiento
C24: Otros gastos
B28: MIX SHOP DIGITAL · Herramientas inteligentes que simplifican tu vida.
B29: Versión gratuita · Para gestionar todo tu negocio en un solo lugar, conocé Mi Negocio PY → mixshopdigital.com.py

Sheet AYUDA
B1: MIX SHOP DIGITAL | D1: AYUDA
B2: Herramientas inteligentes que simplifican tu vida. | D2: Se aprende en 2 minutos
B4: ← PANEL | C4: Leé esta hoja una vez. Después ya no la vas a necesitar.
B6: ¿PARA QUÉ SIRVE?
B7: Para saber cuánto vendés, cuánto gastás y cuánto te queda, mes por mes. Sin fórmulas, sin Internet y sin saber Excel.
B9: EMPEZÁ EN 3 PASOS
B10: 1) En AJUSTES poné el nombre de tu negocio, el año que querés controlar y tu meta de ganancia mensual.
B11: 2) En MOVIMIENTOS anotá cada venta (Ingreso) y cada gasto (Gasto): fecha, tipo, categoría y monto. Una fila por movimiento.
B12: 3) Mirá el PANEL: se actualiza solo con tarjetas, gráficos y un mensaje que te dice cómo vas.
B14: COLORES
B15: Amarillo: celdas que completás vos. Gris o blanco: se calcula solo (bloqueado). Verde: ganancia. Coral: gastos. Rojo: pérdida.
B17: PREGUNTAS FRECUENTES
B18: • Veo todo en cero: hacé clic en «Habilitar edición» en la barra amarilla de Excel.
B19: • ¿El monto de un gasto va con signo menos? No. Escribí siempre el monto en positivo; el Tipo (Ingreso o Gasto) dice si entra o sale.
B20: • ¿Por qué un movimiento no aparece? Revisá que la fecha sea del año elegido en AJUSTES y que el Tipo esté cargado. Los de otros años se ven en gris.
... B34: Versión gratuita · Para gestionar todo tu negocio en un solo lugar, conocé Mi Negocio PY → mixshopdigital.com.py
