Workbook
Name NombreNegocio: 'AJUSTES'!$C$7
Name AnioCtl: 'AJUSTES'!$C$8
Name Moneda: 'AJUSTES'!$C$9
Name DiasControl: 'AJUSTES'!$C$10
Name ListaTrat: 'AJUSTES'!$B$14:$B$23
Name ListaPac: 'PACIENTES'!$B$7:$B$206
Name MesN: 'PANEL'!$P$6
Name FIni: 'PANEL'!$P$7
Name FFin: 'PANEL'!$P$8

Sheet PANEL
B1: MIX SHOP DIGITAL | F1: FICHAS Y AGENDA DE PACIENTES
B2: Herramientas inteligentes que simplifican tu vida. | F2: Tu consultorio, de un vistazo
C4: El panel se arma solo con lo que anotás en PACIENTES y CONSULTAS. Solo elegí el período.
B5: + Anotar atención | E5: Pacientes | G5: Ajustes | I5: Ayuda
B6: Período a mirar: | C6: Todo el año | E6: ="Año de control: "&AnioCtl&" · "&NombreNegocio | P6: =IFERROR(MATCH(C6,{"Todo el año","Enero","Febrero","Marzo","Abril","Mayo","Junio","Julio","Agosto","Septiembre","Octubre","Noviembre","Diciembre"},0)-1,0)
P7: =IF(P6=0,DATE(AnioCtl,1,1),DATE(AnioCtl,P6,1))
B8: ATENCIONES DEL PERÍODO | E8: INGRESOS DEL PERÍODO | H8: PACIENTES REGISTRADOS | K8: CONTROLES PENDIENTES | P8: =IF(P6=0,DATE(AnioCtl+1,1,1),DATE(AnioCtl,P6+1,1))
B9: =IF(MesN=0,C28,INDEX(C16:C27,MesN)) | E9: =IF(MesN=0,D28,INDEX(D16:D27,MesN)) | H9: =COUNTA(PACIENTES!$B$7:$B$206) | K9: =D49
B10: consultas realizadas | E10: =Moneda | H10: en tu base | K10: ="sin visita en "&DiasControl&" días"
B12: =IF(H9=0,"Cargá tus pacientes en la hoja PACIENTES y tus atenciones en CONSULTAS para ver tu panel.",IF(K9>0,"⚠ Tenés "&K9&" paciente(s) con control pendiente. Filtrá PACIENTES por Estado y avisales.","✔ Todos tus pacientes están al día."))
B13: ="Citas en los próximos 7 días: "&COUNTIFS(PACIENTES!$I$7:$I$206,">="&TODAY(),PACIENTES!$I$7:$I$206,"<="&TODAY()+7)&" · Citas agendadas en total: "&COUNTIFS(PACIENTES!$I$7:$I$206,">="&TODAY())
B14: MES A MES (año de control)
B15: Mes | C15: Atenciones | D15: Ingresos
B16: Enero | C16: =COUNTIFS(CONSULTAS!$B$7:$B$506,">="&DATE(AnioCtl,1,1),CONSULTAS!$B$7:$B$506,"<"&DATE(AnioCtl,2,1)) | D16: =SUMIFS(CONSULTAS!$E$7:$E$506,CONSULTAS!$B$7:$B$506,">="&DATE(AnioCtl,1,1),CONSULTAS!$B$7:$B$506,"<"&DATE(AnioCtl,2,1))
B17: Febrero | C17: =COUNTIFS(CONSULTAS!$B$7:$B$506,">="&DATE(AnioCtl,2,1),CONSULTAS!$B$7:$B$506,"<"&DATE(AnioCtl,3,1)) | D17: =SUMIFS(CONSULTAS!$E$7:$E$506,CONSULTAS!$B$7:$B$506,">="&DATE(AnioCtl,2,1),CONSULTAS!$B$7:$B$506,"<"&DATE(AnioCtl,3,1))
B18: Marzo | C18: =COUNTIFS(CONSULTAS!$B$7:$B$506,">="&DATE(AnioCtl,3,1),CONSULTAS!$B$7:$B$506,"<"&DATE(AnioCtl,4,1)) | D18: =SUMIFS(CONSULTAS!$E$7:$E$506,CONSULTAS!$B$7:$B$506,">="&DATE(AnioCtl,3,1),CONSULTAS!$B$7:$B$506,"<"&DATE(AnioCtl,4,1))
B19: Abril | C19: =COUNTIFS(CONSULTAS!$B$7:$B$506,">="&DATE(AnioCtl,4,1),CONSULTAS!$B$7:$B$506,"<"&DATE(AnioCtl,5,1)) | D19: =SUMIFS(CONSULTAS!$E$7:$E$506,CONSULTAS!$B$7:$B$506,">="&DATE(AnioCtl,4,1),CONSULTAS!$B$7:$B$506,"<"&DATE(AnioCtl,5,1))
B20: Mayo | C20: =COUNTIFS(CONSULTAS!$B$7:$B$506,">="&DATE(AnioCtl,5,1),CONSULTAS!$B$7:$B$506,"<"&DATE(AnioCtl,6,1)) | D20: =SUMIFS(CONSULTAS!$E$7:$E$506,CONSULTAS!$B$7:$B$506,">="&DATE(AnioCtl,5,1),CONSULTAS!$B$7:$B$506,"<"&DATE(AnioCtl,6,1))
B21: Junio | C21: =COUNTIFS(CONSULTAS!$B$7:$B$506,">="&DATE(AnioCtl,6,1),CONSULTAS!$B$7:$B$506,"<"&DATE(AnioCtl,7,1)) | D21: =SUMIFS(CONSULTAS!$E$7:$E$506,CONSULTAS!$B$7:$B$506,">="&DATE(AnioCtl,6,1),CONSULTAS!$B$7:$B$506,"<"&DATE(AnioCtl,7,1))
B22: Julio | C22: =COUNTIFS(CONSULTAS!$B$7:$B$506,">="&DATE(AnioCtl,7,1),CONSULTAS!$B$7:$B$506,"<"&DATE(AnioCtl,8,1)) | D22: =SUMIFS(CONSULTAS!$E$7:$E$506,CONSULTAS!$B$7:$B$506,">="&DATE(AnioCtl,7,1),CONSULTAS!$B$7:$B$506,"<"&DATE(AnioCtl,8,1))
B23: Agosto | C23: =COUNTIFS(CONSULTAS!$B$7:$B$506,">="&DATE(AnioCtl,8,1),CONSULTAS!$B$7:$B$506,"<"&DATE(AnioCtl,9,1)) | D23: =SUMIFS(CONSULTAS!$E$7:$E$506,CONSULTAS!$B$7:$B$506,">="&DATE(AnioCtl,8,1),CONSULTAS!$B$7:$B$506,"<"&DATE(AnioCtl,9,1))
B24: Septiembre | C24: =COUNTIFS(CONSULTAS!$B$7:$B$506,">="&DATE(AnioCtl,9,1),CONSULTAS!$B$7:$B$506,"<"&DATE(AnioCtl,10,1)) | D24: =SUMIFS(CONSULTAS!$E$7:$E$506,CONSULTAS!$B$7:$B$506,">="&DATE(AnioCtl,9,1),CONSULTAS!$B$7:$B$506,"<"&DATE(AnioCtl,10,1))
B25: Octubre | C25: =COUNTIFS(CONSULTAS!$B$7:$B$506,">="&DATE(AnioCtl,10,1),CONSULTAS!$B$7:$B$506,"<"&DATE(AnioCtl,11,1)) | D25: =SUMIFS(CONSULTAS!$E$7:$E$506,CONSULTAS!$B$7:$B$506,">="&DATE(AnioCtl,10,1),CONSULTAS!$B$7:$B$506,"<"&DATE(AnioCtl,11,1))
B26: Noviembre | C26: =COUNTIFS(CONSULTAS!$B$7:$B$506,">="&DATE(AnioCtl,11,1),CONSULTAS!$B$7:$B$506,"<"&DATE(AnioCtl,12,1)) | D26: =SUMIFS(CONSULTAS!$E$7:$E$506,CONSULTAS!$B$7:$B$506,">="&DATE(AnioCtl,11,1),CONSULTAS!$B$7:$B$506,"<"&DATE(AnioCtl,12,1))
B27: Diciembre | C27: =COUNTIFS(CONSULTAS!$B$7:$B$506,">="&DATE(AnioCtl,12,1),CONSULTAS!$B$7:$B$506,"<"&DATE(AnioCtl,13,1)) | D27: =SUMIFS(CONSULTAS!$E$7:$E$506,CONSULTAS!$B$7:$B$506,">="&DATE(AnioCtl,12,1),CONSULTAS!$B$7:$B$506,"<"&DATE(AnioCtl,13,1))
B28: TOTAL | C28: =SUM(C16:C27) | D28: =SUM(D16:D27)
B30: TRATAMIENTOS (período elegido)
B31: Tratamiento | D31: Cant. | E31: Ingresos | F31: %
B32: =IF('AJUSTES'!$B$14="","",'AJUSTES'!$B$14) | D32: =IF(B32="",0,COUNTIFS(CONSULTAS!$D$7:$D$506,B32,CONSULTAS!$B$7:$B$506,">="&FIni,CONSULTAS!$B$7:$B$506,"<"&FFin)) | E32: =IF(B32="",0,SUMIFS(CONSULTAS!$E$7:$E$506,CONSULTAS!$D$7:$D$506,B32,CONSULTAS!$B$7:$B$506,">="&FIni,CONSULTAS!$B$7:$B$506,"<"&FFin)) | F32: =IF($D$42=0,0,D32/$D$42)
B33: =IF('AJUSTES'!$B$15="","",'AJUSTES'!$B$15) | D33: =IF(B33="",0,COUNTIFS(CONSULTAS!$D$7:$D$506,B33,CONSULTAS!$B$7:$B$506,">="&FIni,CONSULTAS!$B$7:$B$506,"<"&FFin)) | E33: =IF(B33="",0,SUMIFS(CONSULTAS!$E$7:$E$506,CONSULTAS!$D$7:$D$506,B33,CONSULTAS!$B$7:$B$506,">="&FIni,CONSULTAS!$B$7:$B$506,"<"&FFin)) | F33: =IF($D$42=0,0,D33/$D$42)
B34: =IF('AJUSTES'!$B$16="","",'AJUSTES'!$B$16) | D34: =IF(B34="",0,COUNTIFS(CONSULTAS!$D$7:$D$506,B34,CONSULTAS!$B$7:$B$506,">="&FIni,CONSULTAS!$B$7:$B$506,"<"&FFin)) | E34: =IF(B34="",0,SUMIFS(CONSULTAS!$E$7:$E$506,CONSULTAS!$D$7:$D$506,B34,CONSULTAS!$B$7:$B$506,">="&FIni,CONSULTAS!$B$7:$B$506,"<"&FFin)) | F34: =IF($D$42=0,0,D34/$D$42)
B35: =IF('AJUSTES'!$B$17="","",'AJUSTES'!$B$17) | D35: =IF(B35="",0,COUNTIFS(CONSULTAS!$D$7:$D$506,B35,CONSULTAS!$B$7:$B$506,">="&FIni,CONSULTAS!$B$7:$B$506,"<"&FFin)) | E35: =IF(B35="",0,SUMIFS(CONSULTAS!$E$7:$E$506,CONSULTAS!$D$7:$D$506,B35,CONSULTAS!$B$7:$B$506,">="&FIni,CONSULTAS!$B$7:$B$506,"<"&FFin)) | F35: =IF($D$42=0,0,D35/$D$42)
B36: =IF('AJUSTES'!$B$18="","",'AJUSTES'!$B$18) | D36: =IF(B36="",0,COUNTIFS(CONSULTAS!$D$7:$D$506,B36,CONSULTAS!$B$7:$B$506,">="&FIni,CONSULTAS!$B$7:$B$506,"<"&FFin)) | E36: =IF(B36="",0,SUMIFS(CONSULTAS!$E$7:$E$506,CONSULTAS!$D$7:$D$506,B36,CONSULTAS!$B$7:$B$506,">="&FIni,CONSULTAS!$B$7:$B$506,"<"&FFin)) | F36: =IF($D$42=0,0,D36/$D$42)
B37: =IF('AJUSTES'!$B$19="","",'AJUSTES'!$B$19) | D37: =IF(B37="",0,COUNTIFS(CONSULTAS!$D$7:$D$506,B37,CONSULTAS!$B$7:$B$506,">="&FIni,CONSULTAS!$B$7:$B$506,"<"&FFin)) | E37: =IF(B37="",0,SUMIFS(CONSULTAS!$E$7:$E$506,CONSULTAS!$D$7:$D$506,B37,CONSULTAS!$B$7:$B$506,">="&FIni,CONSULTAS!$B$7:$B$506,"<"&FFin)) | F37: =IF($D$42=0,0,D37/$D$42)
B38: =IF('AJUSTES'!$B$20="","",'AJUSTES'!$B$20) | D38: =IF(B38="",0,COUNTIFS(CONSULTAS!$D$7:$D$506,B38,CONSULTAS!$B$7:$B$506,">="&FIni,CONSULTAS!$B$7:$B$506,"<"&FFin)) | E38: =IF(B38="",0,SUMIFS(CONSULTAS!$E$7:$E$506,CONSULTAS!$D$7:$D$506,B38,CONSULTAS!$B$7:$B$506,">="&FIni,CONSULTAS!$B$7:$B$506,"<"&FFin)) | F38: =IF($D$42=0,0,D38/$D$42)
B39: =IF('AJUSTES'!$B$21="","",'AJUSTES'!$B$21) | D39: =IF(B39="",0,COUNTIFS(CONSULTAS!$D$7:$D$506,B39,CONSULTAS!$B$7:$B$506,">="&FIni,CONSULTAS!$B$7:$B$506,"<"&FFin)) | E39: =IF(B39="",0,SUMIFS(CONSULTAS!$E$7:$E$506,CONSULTAS!$D$7:$D$506,B39,CONSULTAS!$B$7:$B$506,">="&FIni,CONSULTAS!$B$7:$B$506,"<"&FFin)) | F39: =IF($D$42=0,0,D39/$D$42)
B40: =IF('AJUSTES'!$B$22="","",'AJUSTES'!$B$22) | D40: =IF(B40="",0,COUNTIFS(CONSULTAS!$D$7:$D$506,B40,CONSULTAS!$B$7:$B$506,">="&FIni,CONSULTAS!$B$7:$B$506,"<"&FFin)) | E40: =IF(B40="",0,SUMIFS(CONSULTAS!$E$7:$E$506,CONSULTAS!$D$7:$D$506,B40,CONSULTAS!$B$7:$B$506,">="&FIni,CONSULTAS!$B$7:$B$506,"<"&FFin)) | F40: =IF($D$42=0,0,D40/$D$42)
B41: =IF('AJUSTES'!$B$23="","",'AJUSTES'!$B$23) | D41: =IF(B41="",0,COUNTIFS(CONSULTAS!$D$7:$D$506,B41,CONSULTAS!$B$7:$B$506,">="&FIni,CONSULTAS!$B$7:$B$506,"<"&FFin)) | E41: =IF(B41="",0,SUMIFS(CONSULTAS!$E$7:$E$506,CONSULTAS!$D$7:$D$506,B41,CONSULTAS!$B$7:$B$506,">="&FIni,CONSULTAS!$B$7:$B$506,"<"&FFin)) | F41: =IF($D$42=0,0,D41/$D$42)
B42: TOTAL | D42: =SUM(D32:D41) | E42: =SUM(E32:E41) | F42: =SUM(F32:F41)
B45: ESTADO DE TUS PACIENTES
...

Sheet PACIENTES
B1: MIX SHOP DIGITAL | D1: PACIENTES
B2: Herramientas inteligentes que simplifican tu vida. | D2: Tu base de pacientes
B4: ← VOLVER | C4: Una fila por paciente. Completá solamente las celdas amarillas: la edad, la última visita y el estado se calculan solos.
B5: ="Pacientes: "&COUNTA(B7:B206)&" de 200 · Con control pendiente: "&COUNTIF(J7:J206,"Control pendiente")&" · Citas en los próximos 7 días: "&COUNTIFS(I7:I206,">="&TODAY(),I7:I206,"<="&TODAY()+7)
B6: Paciente (nombre y apellido) | C6: C.I. | D6: Teléfono | E6: Fecha de nacimiento | F6: Edad | G6: Alergias o avisos importantes | H6: Última visita | I6: Próxima cita | J6: Estado
B7: Carlos Benítez | C7: 4.495.358 | D7: 0981 800 144 | E7: 18844 | F7: =IF(OR($B7="",N($E7)=0),"",INT((TODAY()-$E7)/365.25)) | H7: =IF($B7="","",IF(COUNTIF(CONSULTAS!$C$7:$C$506,$B7)=0,"",SUMPRODUCT(MAX((CONSULTAS!$C$7:$C$506=$B7)*CONSULTAS!$B$7:$B$506)))) | I7: 46345 | J7: =IF($B7="","",IF(AND(N($I7)>=TODAY(),$I7<>""),"Cita agendada",IF($H7="","Sin consultas",IF(TODAY()-$H7>DiasControl,"Control pendiente","Al día"))))
B8: Ana Gómez | C8: 3.144.499 | D8: 0981 250 858 | E8: 24521 | F8: =IF(OR($B8="",N($E8)=0),"",INT((TODAY()-$E8)/365.25)) | H8: =IF($B8="","",IF(COUNTIF(CONSULTAS!$C$7:$C$506,$B8)=0,"",SUMPRODUCT(MAX((CONSULTAS!$C$7:$C$506=$B8)*CONSULTAS!$B$7:$B$506)))) | J8: =IF($B8="","",IF(AND(N($I8)>=TODAY(),$I8<>""),"Cita agendada",IF($H8="","Sin consultas",IF(TODAY()-$H8>DiasControl,"Control pendiente","Al día"))))
B9: Lucía Martínez | C9: 2.345.703 | D9: 0981 648 849 | E9: 20030 | F9: =IF(OR($B9="",N($E9)=0),"",INT((TODAY()-$E9)/365.25)) | H9: =IF($B9="","",IF(COUNTIF(CONSULTAS!$C$7:$C$506,$B9)=0,"",SUMPRODUCT(MAX((CONSULTAS!$C$7:$C$506=$B9)*CONSULTAS!$B$7:$B$506)))) | J9: =IF($B9="","",IF(AND(N($I9)>=TODAY(),$I9<>""),"Cita agendada",IF($H9="","Sin consultas",IF(TODAY()-$H9>DiasControl,"Control pendiente","Al día"))))
B10: Roberto Duarte | C10: 2.919.068 | D10: 0995 195 220 | E10: 39339 | F10: =IF(OR($B10="",N($E10)=0),"",INT((TODAY()-$E10)/365.25)) | G10: Alergia a la penicilina | H10: =IF($B10="","",IF(COUNTIF(CONSULTAS!$C$7:$C$506,$B10)=0,"",SUMPRODUCT(MAX((CONSULTAS!$C$7:$C$506=$B10)*CONSULTAS!$B$7:$B$506)))) | I10: 46335 | J10: =IF($B10="","",IF(AND(N($I10)>=TODAY(),$I10<>""),"Cita agendada",IF($H10="","Sin consultas",IF(TODAY()-$H10>DiasControl,"Control pendiente","Al día"))))
B11: Sofía Giménez | C11: 2.865.118 | D11: 0981 438 501 | E11: 19186 | F11: =IF(OR($B11="",N($E11)=0),"",INT((TODAY()-$E11)/365.25)) | H11: =IF($B11="","",IF(COUNTIF(CONSULTAS!$C$7:$C$506,$B11)=0,"",SUMPRODUCT(MAX((CONSULTAS!$C$7:$C$506=$B11)*CONSULTAS!$B$7:$B$506)))) | J11: =IF($B11="","",IF(AND(N($I11)>=TODAY(),$I11<>""),"Cita agendada",IF($H11="","Sin consultas",IF(TODAY()-$H11>DiasControl,"Control pendiente","Al día"))))
B12: Marcos Ortiz | C12: 2.964.395 | D12: 0981 526 698 | E12: 35346 | F12: =IF(OR($B12="",N($E12)=0),"",INT((TODAY()-$E12)/365.25)) | G12: Hipertensión | H12: =IF($B12="","",IF(COUNTIF(CONSULTAS!$C$7:$C$506,$B12)=0,"",SUMPRODUCT(MAX((CONSULTAS!$C$7:$C$506=$B12)*CONSULTAS!$B$7:$B$506)))) | J12: =IF($B12="","",IF(AND(N($I12)>=TODAY(),$I12<>""),"Cita agendada",IF($H12="","Sin consultas",IF(TODAY()-$H12>DiasControl,"Control pendiente","Al día"))))
B13: Elena Báez | C13: 2.709.028 | D13: 0982 237 308 | E13: 20847 | F13: =IF(OR($B13="",N($E13)=0),"",INT((TODAY()-$E13)/365.25)) | H13: =IF($B13="","",IF(COUNTIF(CONSULTAS!$C$7:$C$506,$B13)=0,"",SUMPRODUCT(MAX((CONSULTAS!$C$7:$C$506=$B13)*CONSULTAS!$B$7:$B$506)))) | I13: 46339 | J13: =IF($B13="","",IF(AND(N($I13)>=TODAY(),$I13<>""),"Cita agendada",IF($H13="","Sin consultas",IF(TODAY()-$H13>DiasControl,"Control pendiente","Al día"))))
B14: Diego Cabrera | C14: 1.922.366 | D14: 0995 989 549 | E14: 25020 | F14: =IF(OR($B14="",N($E14)=0),"",INT((TODAY()-$E14)/365.25)) | G14: Diabetes | H14: =IF($B14="","",IF(COUNTIF(CONSULTAS!$C$7:$C$506,$B14)=0,"",SUMPRODUCT(MAX((CONSULTAS!$C$7:$C$506=$B14)*CONSULTAS!$B$7:$B$506)))) | J14: =IF($B14="","",IF(AND(N($I14)>=TODAY(),$I14<>""),"Cita agendada",IF($H14="","Sin consultas",IF(TODAY()-$H14>DiasControl,"Control pendiente","Al día"))))
B15: Valeria Ríos | C15: 4.827.155 | D15: 0982 298 438 | E15: 28241 | F15: =IF(OR($B15="",N($E15)=0),"",INT((TODAY()-$E15)/365.25)) | H15: =IF($B15="","",IF(COUNTIF(CONSULTAS!$C$7:$C$506,$B15)=0,"",SUMPRODUCT(MAX((CONSULTAS!$C$7:$C$506=$B15)*CONSULTAS!$B$7:$B$506)))) | J15: =IF($B15="","",IF(AND(N($I15)>=TODAY(),$I15<>""),"Cita agendada",IF($H15="","Sin consultas",IF(TODAY()-$H15>DiasControl,"Control pendiente","Al día"))))
B16: Pablo Acosta | C16: 3.409.529 | D16: 0982 400 442 | E16: 28704 | F16: =IF(OR($B16="",N($E16)=0),"",INT((TODAY()-$E16)/365.25)) | H16: =IF($B16="","",IF(COUNTIF(CONSULTAS!$C$7:$C$506,$B16)=0,"",SUMPRODUCT(MAX((CONSULTAS!$C$7:$C$506=$B16)*CONSULTAS!$B$7:$B$506)))) | I16: 46340 | J16: =IF($B16="","",IF(AND(N($I16)>=TODAY(),$I16<>""),"Cita agendada",IF($H16="","Sin consultas",IF(TODAY()-$H16>DiasControl,"Control pendiente","Al día"))))
B17: Camila Franco | C17: 6.658.953 | D17: 0982 318 867 | E17: 36759 | F17: =IF(OR($B17="",N($E17)=0),"",INT((TODAY()-$E17)/365.25)) | G17: Alergia al látex | H17: =IF($B17="","",IF(COUNTIF(CONSULTAS!$C$7:$C$506,$B17)=0,"",SUMPRODUCT(MAX((CONSULTAS!$C$7:$C$506=$B17)*CONSULTAS!$B$7:$B$506)))) | J17: =IF($B17="","",IF(AND(N($I17)>=TODAY(),$I17<>""),"Cita agendada",IF($H17="","Sin consultas",IF(TODAY()-$H17>DiasControl,"Control pendiente","Al día"))))
B18: Julián Vera | C18: 5.896.665 | D18: 0995 658 958 | E18: 22772 | F18: =IF(OR($B18="",N($E18)=0),"",INT((TODAY()-$E18)/365.25)) | H18: =IF($B18="","",IF(COUNTIF(CONSULTAS!$C$7:$C$506,$B18)=0,"",SUMPRODUCT(MAX((CONSULTAS!$C$7:$C$506=$B18)*CONSULTAS!$B$7:$B$506)))) | J18: =IF($B18="","",IF(AND(N($I18)>=TODAY(),$I18<>""),"Cita agendada",IF($H18="","Sin consultas",IF(TODAY()-$H18>DiasControl,"Control pendiente","Al día"))))
B19: Natalia Peralta | C19: 2.817.248 | D19: 0971 912 715 | E19: 31814 | F19: =IF(OR($B19="",N($E19)=0),"",INT((TODAY()-$E19)/365.25)) | H19: =IF($B19="","",IF(COUNTIF(CONSULTAS!$C$7:$C$506,$B19)=0,"",SUMPRODUCT(MAX((CONSULTAS!$C$7:$C$506=$B19)*CONSULTAS!$B$7:$B$506)))) | I19: 46341 | J19: =IF($B19="","",IF(AND(N($I19)>=TODAY(),$I19<>""),"Cita agendada",IF($H19="","Sin consultas",IF(TODAY()-$H19>DiasControl,"Control pendiente","Al día"))))
B20: Héctor Aguilera | C20: 6.816.789 | D20: 0991 391 412 | E20: 35768 | F20: =IF(OR($B20="",N($E20)=0),"",INT((TODAY()-$E20)/365.25)) | G20: Embarazo (2.º trimestre) | H20: =IF($B20="","",IF(COUNTIF(CONSULTAS!$C$7:$C$506,$B20)=0,"",SUMPRODUCT(MAX((CONSULTAS!$C$7:$C$506=$B20)*CONSULTAS!$B$7:$B$506)))) | J20: =IF($B20="","",IF(AND(N($I20)>=TODAY(),$I20<>""),"Cita agendada",IF($H20="","Sin consultas",IF(TODAY()-$H20>DiasControl,"Control pendiente","Al día"))))
B21: Mónica Ayala | C21: 2.899.540 | D21: 0982 555 512 | E21: 27440 | F21: =IF(OR($B21="",N($E21)=0),"",INT((TODAY()-$E21)/365.25)) | H21: =IF($B21="","",IF(COUNTIF(CONSULTAS!$C$7:$C$506,$B21)=0,"",SUMPRODUCT(MAX((CONSULTAS!$C$7:$C$506=$B21)*CONSULTAS!$B$7:$B$506)))) | J21: =IF($B21="","",IF(AND(N($I21)>=TODAY(),$I21<>""),"Cita agendada",IF($H21="","Sin consultas",IF(TODAY()-$H21>DiasControl,"Control pendiente","Al día"))))
B22: Fabián Romero | C22: 2.190.168 | D22: 0982 201 994 | E22: 20721 | F22: =IF(OR($B22="",N($E22)=0),"",INT((TODAY()-$E22)/365.25)) | G22: Anticoagulantes | H22: =IF($B22="","",IF(COUNTIF(CONSULTAS!$C$7:$C$506,$B22)=0,"",SUMPRODUCT(MAX((CONSULTAS!$C$7:$C$506=$B22)*CONSULTAS!$B$7:$B$506)))) | I22: 46338 | J22: =IF($B22="","",IF(AND(N($I22)>=TODAY(),$I22<>""),"Cita agendada",IF($H22="","Sin consultas",IF(TODAY()-$H22>DiasControl,"Control pendiente","Al día"))))
B23: Gabriela Lezcano | C23: 4.011.972 | D23: 0981 830 974 | E23: 23839 | F23: =IF(OR($B23="",N($E23)=0),"",INT((TODAY()-$E23)/365.25)) | H23: =IF($B23="","",IF(COUNTIF(CONSULTAS!$C$7:$C$506,$B23)=0,"",SUMPRODUCT(MAX((CONSULTAS!$C$7:$C$506=$B23)*CONSULTAS!$B$7:$B$506)))) | J23: =IF($B23="","",IF(AND(N($I23)>=TODAY(),$I23<>""),"Cita agendada",IF($H23="","Sin consultas",IF(TODAY()-$H23>DiasControl,"Control pendiente","Al día"))))
B24: Andrés Insfrán | C24: 5.378.765 | D24: 0995 907 624 | E24: 25417 | F24: =IF(OR($B24="",N($E24)=0),"",INT((TODAY()-$E24)/365.25)) | H24: =IF($B24="","",IF(COUNTIF(CONSULTAS!$C$7:$C$506,$B24)=0,"",SUMPRODUCT(MAX((CONSULTAS!$C$7:$C$506=$B24)*CONSULTAS!$B$7:$B$506)))) | J24: =IF($B24="","",IF(AND(N($I24)>=TODAY(),$I24<>""),"Cita agendada",IF($H24="","Sin consultas",IF(TODAY()-$H24>DiasControl,"Control pendiente","Al día"))))
B25: Rosa Villalba | C25: 5.312.558 | D25: 0995 138 975 | E25: 31218 | F25: =IF(OR($B25="",N($E25)=0),"",INT((TODAY()-$E25)/365.25)) | H25: =IF($B25="","",IF(COUNTIF(CONSULTAS!$C$7:$C$506,$B25)=0,"",SUMPRODUCT(MAX((CONSULTAS!$C$7:$C$506=$B25)*CONSULTAS!$B$7:$B$506)))) | I25: 46329 | J25: =IF($B25="","",IF(AND(N($I25)>=TODAY(),$I25<>""),"Cita agendada",IF($H25="","Sin consultas",IF(TODAY()-$H25>DiasControl,"Control pendiente","Al día"))))
B26: Sergio Maidana | C26: 6.285.696 | D26: 0991 949 885 | E26: 23594 | F26: =IF(OR($B26="",N($E26)=0),"",INT((TODAY()-$E26)/365.25)) | H26: =IF($B26="","",IF(COUNTIF(CONSULTAS!$C$7:$C$506,$B26)=0,"",SUMPRODUCT(MAX((CONSULTAS!$C$7:$C$506=$B26)*CONSULTAS!$B$7:$B$506)))) | J26: =IF($B26="","",IF(AND(N($I26)>=TODAY(),$I26<>""),"Cita agendada",IF($H26="","Sin consultas",IF(TODAY()-$H26>DiasControl,"Control pendiente","Al día"))))
B27: Clara Esquivel | C27: 5.141.605 | D27: 0982 343 111 | E27: 19495 | F27: =IF(OR($B27="",N($E27)=0),"",INT((TODAY()-$E27)/365.25)) | H27: =IF($B27="","",IF(COUNTIF(CONSULTAS!$C$7:$C$506,$B27)=0,"",SUMPRODUCT(MAX((CONSULTAS!$C$7:$C$506=$B27)*CONSULTAS!$B$7:$B$506)))) | J27: =IF($B27="","",IF(AND(N($I27)>=TODAY(),$I27<>""),"Cita agendada",IF($H27="","Sin consultas",IF(TODAY()-$H27>DiasControl,"Control pendiente","Al día"))))
B28: Tomás Giménez | C28: 3.569.949 | D28: 0991 280 146 | E28: 22846 | F28: =IF(OR($B28="",N($E28)=0),"",INT((TODAY()-$E28)/365.25)) | H28: =IF($B28="","",IF(COUNTIF(CONSULTAS!$C$7:$C$506,$B28)=0,"",SUMPRODUCT(MAX((CONSULTAS!$C$7:$C$506=$B28)*CONSULTAS!$B$7:$B$506)))) | I28: 46333 | J28: =IF($B28="","",IF(AND(N($I28)>=TODAY(),$I28<>""),"Cita agendada",IF($H28="","Sin consultas",IF(TODAY()-$H28>DiasControl,"Control pendiente","Al día"))))
B29: Patricia Delvalle | C29: 6.349.308 | D29: 0971 728 311 | E29: 24157 | F29: =IF(OR($B29="",N($E29)=0),"",INT((TODAY()-$E29)/365.25)) | H29: =IF($B29="","",IF(COUNTIF(CONSULTAS!$C$7:$C$506,$B29)=0,"",SUMPRODUCT(MAX((CONSULTAS!$C$7:$C$506=$B29)*CONSULTAS!$B$7:$B$506)))) | J29: =IF($B29="","",IF(AND(N($I29)>=TODAY(),$I29<>""),"Cita agendada",IF($H29="","Sin consultas",IF(TODAY()-$H29>DiasControl,"Control pendiente","Al día"))))
B30: Ramón Ferreira | C30: 2.742.035 | D30: 0995 565 671 | E30: 27172 | F30: =IF(OR($B30="",N($E30)=0),"",INT((TODAY()-$E30)/365.25)) | G30: Alergia a la penicilina | H30: =IF($B30="","",IF(COUNTIF(CONSULTAS!$C$7:$C$506,$B30)=0,"",SUMPRODUCT(MAX((CONSULTAS!$C$7:$C$506=$B30)*CONSULTAS!$B$7:$B$506)))) | J30: =IF($B30="","",IF(AND(N($I30)>=TODAY(),$I30<>""),"Cita agendada",IF($H30="","Sin consultas",IF(TODAY()-$H30>DiasControl,"Control pendiente","Al día"))))
B31: Liz Cardozo | C31: 5.423.177 | D31: 0991 332 636 | E31: 42270 | F31: =IF(OR($B31="",N($E31)=0),"",INT((TODAY()-$E31)/365.25)) | H31: =IF($B31="","",IF(COUNTIF(CONSULTAS!$C$7:$C$506,$B31)=0,"",SUMPRODUCT(MAX((CONSULTAS!$C$7:$C$506=$B31)*CONSULTAS!$B$7:$B$506)))) | I31: 46333 | J31: =IF($B31="","",IF(AND(N($I31)>=TODAY(),$I31<>""),"Cita agendada",IF($H31="","Sin consultas",IF(TODAY()-$H31>DiasControl,"Control pendiente","Al día"))))
B32: Óscar Noguera | C32: 5.071.685 | D32: 0982 834 938 | E32: 27383 | F32: =IF(OR($B32="",N($E32)=0),"",INT((TODAY()-$E32)/365.25)) | G32: Hipertensión | H32: =IF($B32="","",IF(COUNTIF(CONSULTAS!$C$7:$C$506,$B32)=0,"",SUMPRODUCT(MAX((CONSULTAS!$C$7:$C$506=$B32)*CONSULTAS!$B$7:$B$506)))) | J32: =IF($B32="","",IF(AND(N($I32)>=TODAY(),$I32<>""),"Cita agendada",IF($H32="","Sin consultas",IF(TODAY()-$H32>DiasControl,"Control pendiente","Al día"))))
B33: Silvia Britez | C33: 4.316.990 | D33: 0971 635 901 | E33: 39969 | F33: =IF(OR($B33="",N($E33)=0),"",INT((TODAY()-$E33)/365.25)) | H33: =IF($B33="","",IF(COUNTIF(CONSULTAS!$C$7:$C$506,$B33)=0,"",SUMPRODUCT(MAX((CONSULTAS!$C$7:$C$506=$B33)*CONSULTAS!$B$7:$B$506)))) | J33: =IF($B33="","",IF(AND(N($I33)>=TODAY(),$I33<>""),"Cita agendada",IF($H33="","Sin consultas",IF(TODAY()-$H33>DiasControl,"Control pendiente","Al día"))))
B34: Daniel Samudio | C34: 3.655.394 | D34: 0991 693 891 | E34: 34675 | F34: =IF(OR($B34="",N($E34)=0),"",INT((TODAY()-$E34)/365.25)) | G34: Diabetes | H34: =IF($B34="","",IF(COUNTIF(CONSULTAS!$C$7:$C$506,$B34)=0,"",SUMPRODUCT(MAX((CONSULTAS!$C$7:$C$506=$B34)*CONSULTAS!$B$7:$B$506)))) | I34: 46345 | J34: =IF($B34="","",IF(AND(N($I34)>=TODAY(),$I34<>""),"Cita agendada",IF($H34="","Sin consultas",IF(TODAY()-$H34>DiasControl,"Control pendiente","Al día"))))
B35: Teresa Rolón | C35: 6.804.121 | D35: 0971 850 535 | E35: 25961 | F35: =IF(OR($B35="",N($E35)=0),"",INT((TODAY()-$E35)/365.25)) | H35: =IF($B35="","",IF(COUNTIF(CONSULTAS!$C$7:$C$506,$B35)=0,"",SUMPRODUCT(MAX((CONSULTAS!$C$7:$C$506=$B35)*CONSULTAS!$B$7:$B$506)))) | J35: =IF($B35="","",IF(AND(N($I35)>=TODAY(),$I35<>""),"Cita agendada",IF($H35="","Sin consultas",IF(TODAY()-$H35>DiasControl,"Control pendiente","Al día"))))
B36: Iván Sosa | C36: 4.393.552 | D36: 0982 309 535 | E36: 27827 | F36: =IF(OR($B36="",N($E36)=0),"",INT((TODAY()-$E36)/365.25)) | H36: =IF($B36="","",IF(COUNTIF(CONSULTAS!$C$7:$C$506,$B36)=0,"",SUMPRODUCT(MAX((CONSULTAS!$C$7:$C$506=$B36)*CONSULTAS!$B$7:$B$506)))) | J36: =IF($B36="","",IF(AND(N($I36)>=TODAY(),$I36<>""),"Cita agendada",IF($H36="","Sin consultas",IF(TODAY()-$H36>DiasControl,"Control pendiente","Al día"))))
F37: =IF(OR($B37="",N($E37)=0),"",INT((TODAY()-$E37)/365.25)) | H37: =IF($B37="","",IF(COUNTIF(CONSULTAS!$C$7:$C$506,$B37)=0,"",SUMPRODUCT(MAX((CONSULTAS!$C$7:$C$506=$B37)*CONSULTAS!$B$7:$B$506)))) | J37: =IF($B37="","",IF(AND(N($I37)>=TODAY(),$I37<>""),"Cita agendada",IF($H37="","Sin consultas",IF(TODAY()-$H37>DiasControl,"Control pendiente","Al día"))))
F38: =IF(OR($B38="",N($E38)=0),"",INT((TODAY()-$E38)/365.25)) | H38: =IF($B38="","",IF(COUNTIF(CONSULTAS!$C$7:$C$506,$B38)=0,"",SUMPRODUCT(MAX((CONSULTAS!$C$7:$C$506=$B38)*CONSULTAS!$B$7:$B$506)))) | J38: =IF($B38="","",IF(AND(N($I38)>=TODAY(),$I38<>""),"Cita agendada",IF($H38="","Sin consultas",IF(TODAY()-$H38>DiasControl,"Control pendiente","Al día"))))
F39: =IF(OR($B39="",N($E39)=0),"",INT((TODAY()-$E39)/365.25)) | H39: =IF($B39="","",IF(COUNTIF(CONSULTAS!$C$7:$C$506,$B39)=0,"",SUMPRODUCT(MAX((CONSULTAS!$C$7:$C$506=$B39)*CONSULTAS!$B$7:$B$506)))) | J39: =IF($B39="","",IF(AND(N($I39)>=TODAY(),$I39<>""),"Cita agendada",IF($H39="","Sin consultas",IF(TODAY()-$H39>DiasControl,"Control pendiente","Al día"))))
F40: =IF(OR($B40="",N($E40)=0),"",INT((TODAY()-$E40)/365.25)) | H40: =IF($B40="","",IF(COUNTIF(CONSULTAS!$C$7:$C$506,$B40)=0,"",SUMPRODUCT(MAX((CONSULTAS!$C$7:$C$506=$B40)*CONSULTAS!$B$7:$B$506)))) | J40: =IF($B40="","",IF(AND(N($I40)>=TODAY(),$I40<>""),"Cita agendada",IF($H40="","Sin consultas",IF(TODAY()-$H40>DiasControl,"Control pendiente","Al día"))))
F41: =IF(OR($B41="",N($E41)=0),"",INT((TODAY()-$E41)/365.25)) | H41: =IF($B41="","",IF(COUNTIF(CONSULTAS!$C$7:$C$506,$B41)=0,"",SUMPRODUCT(MAX((CONSULTAS!$C$7:$C$506=$B41)*CONSULTAS!$B$7:$B$506)))) | J41: =IF($B41="","",IF(AND(N($I41)>=TODAY(),$I41<>""),"Cita agendada",IF($H41="","Sin consultas",IF(TODAY()-$H41>DiasControl,"Control pendiente","Al día"))))
...

Sheet CONSULTAS
B1: MIX SHOP DIGITAL | D1: CONSULTAS
B2: Herramientas inteligentes que simplifican tu vida. | D2: Anotá cada atención
B4: ← VOLVER | C4: Una fila por atención. Elegí el paciente y el tratamiento de las listas. Podés ordenar y filtrar con la fila de títulos.
B5: ="Atenciones cargadas: "&COUNT(B7:B506)&" de 500 · Ingresos del año: "&FIXED(PANEL!D28,0)&" "&Moneda
B6: Fecha | C6: Paciente | D6: Tratamiento | E6: Monto cobrado | F6: Observación (opcional)
B7: 46023 | C7: Pablo Acosta | D7: Control de ortodoncia | E7: 195000
B8: 46023 | C8: Daniel Samudio | D8: Extracción | E8: 280000
B9: 46024 | C9: Óscar Noguera | D9: Control de ortodoncia | E9: 220000
B10: 46025 | C10: Óscar Noguera | D10: Obturación (arreglo) | E10: 225000
B11: 46026 | C11: Tomás Giménez | D11: Limpieza dental | E11: 200000
B12: 46029 | C12: Elena Báez | D12: Endodoncia | E12: 800000
B13: 46029 | C13: Patricia Delvalle | D13: Consulta | E13: 100000
B14: 46030 | C14: Valeria Ríos | D14: Limpieza dental | E14: 190000
B15: 46030 | C15: Natalia Peralta | D15: Urgencia | E15: 160000
B16: 46030 | C16: Liz Cardozo | D16: Urgencia | E16: 155000
B17: 46031 | C17: Andrés Insfrán | D17: Urgencia | E17: 165000
B18: 46031 | C18: Daniel Samudio | D18: Extracción | E18: 240000
... B202: 46322 | C202: Héctor Aguilera | D202: Consulta | E202: 95000
B509: MIX SHOP DIGITAL · Herramientas inteligentes que simplifican tu vida.
B510: Versión gratuita · Para gestionar todo tu consultorio en un solo lugar, conocé ODONTO SMART → mixshopdigital.com.py

Sheet AJUSTES
B1: MIX SHOP DIGITAL | C1: AJUSTES
B2: Herramientas inteligentes que simplifican tu vida. | C2: Cargalos una sola vez
B4: ← VOLVER | C4: Completá solamente las celdas amarillas. Estos datos alimentan las demás hojas automáticamente.
B6: 1. TU CONSULTORIO
B7: Nombre del consultorio | C7: Consultorio de María (EJEMPLO) | D7: Aparece en el PANEL.
B8: Año a controlar | C8: 2026 | D8: El PANEL muestra los 12 meses de este año.
B9: Moneda | C9: Gs. | D9: Símbolo que se muestra en las hojas.
B10: Días para el control | C10: 180 | D10: Si un paciente no viene hace más de estos días, aparece como «Control pendiente».
B12: 2. TUS TRATAMIENTOS (podés renombrarlos)
B13: Se usan en la lista desplegable de CONSULTAS. Cambiá el nombre, pero no dejes huecos entre medio.
B14: Consulta | C14: Hasta 10 tratamientos.
B15: Limpieza dental
B16: Obturación (arreglo)
B17: Extracción
B18: Endodoncia
B19: Control de ortodoncia
B20: Blanqueamiento
B21: Prótesis
B22: Urgencia
B23: Otro tratamiento
B27: MIX SHOP DIGITAL · Herramientas inteligentes que simplifican tu vida.
B28: Versión gratuita · Para gestionar todo tu consultorio en un solo lugar, conocé ODONTO SMART → mixshopdigital.com.py

Sheet AYUDA
B1: MIX SHOP DIGITAL | D1: AYUDA
B2: Herramientas inteligentes que simplifican tu vida. | D2: Se aprende en 2 minutos
B4: ← VOLVER | C4: Leé esta hoja una vez. Después ya no la vas a necesitar.
B6: ¿PARA QUÉ SIRVE?
B7: Para tener ordenada la base de pacientes de tu consultorio, anotar cada atención y saber a quién tenés que llamar para un control. Sin fórmulas y sin Internet.
B9: EMPEZÁ EN 3 PASOS
B10: 1) En AJUSTES poné el nombre de tu consultorio, el año y cada cuántos días querés que vuelva el paciente a control. Si querés, renombrá los tratamientos.
B11: 2) En PACIENTES cargá a cada paciente una sola vez: nombre, C.I., teléfono, fecha de nacimiento, alergias y su próxima cita.
B12: 3) En CONSULTAS anotá cada atención: fecha, paciente, tratamiento y monto cobrado. El PANEL se arma solo.
B14: COLORES Y AVISOS
B15: Amarillo/celeste claro: celdas que completás vos. Gris o blanco: se calcula solo (bloqueado). Rojo: control pendiente. Verde: cita agendada. Naranja: cita en los próximos 7 días.
B17: PREGUNTAS FRECUENTES
B18: • Veo todo en cero: hacé clic en «Habilitar edición» en la barra amarilla de Excel.
B19: • ¿Cómo sé a quién llamar? En PACIENTES filtrá la columna Estado por «Control pendiente».
B20: • Un paciente no aparece en la lista de CONSULTAS: cargalo primero en PACIENTES. Usá nombres distintos para cada paciente.
... B34: Versión gratuita · Para gestionar todo tu consultorio en un solo lugar, conocé ODONTO SMART → mixshopdigital.com.py
