Workbook
Name TituloTesis: 'AJUSTES'!$C$7
Name Estudiante: 'AJUSTES'!$C$8
Name Tutor: 'AJUSTES'!$C$9
Name FechaIni: 'AJUSTES'!$C$10
Name FechaFin: 'AJUSTES'!$C$11
Name ListaEtapa: 'AJUSTES'!$B$15:$B$23

Sheet PANEL
F1: CRONOGRAMA DE TESIS
B2: Herramientas inteligentes que simplifican tu vida. | F2: Tu tesis, de un vistazo
C4: El panel se arma solo con lo que anotás en CRONOGRAMA y REUNIONES. No hace falta escribir nada acá.
B5: + Cronograma | E5: Reuniones | G5: Ajustes | I5: Ayuda
B6: ="Trabajo: "&TituloTesis&IF(Estudiante="",""," · Estudiante: "&Estudiante)&IF(Tutor="",""," · Tutor: "&Tutor)
B8: AVANCE GENERAL | E8: DÍAS PARA TU ENTREGA | H8: TAREAS COMPLETADAS | K8: TAREAS ATRASADAS
B9: =IFERROR(SUMPRODUCT(((CRONOGRAMA!$D$7:$D$46<>"")*(CRONOGRAMA!$F$7:$F$46-CRONOGRAMA!$E$7:$E$46+1))*CRONOGRAMA!$G$7:$G$46)/SUMPRODUCT(((CRONOGRAMA!$D$7:$D$46<>"")*(CRONOGRAMA!$F$7:$F$46-CRONOGRAMA!$E$7:$E$46+1))),0) | E9: =IF(N(FechaFin)=0,"-",FechaFin-TODAY()) | H9: =COUNTIF(CRONOGRAMA!$H$7:$H$46,"Completada")&" de "&COUNTA(CRONOGRAMA!$D$7:$D$46) | K9: =COUNTIF(CRONOGRAMA!$H$7:$H$46,"Atrasada")
B10: ponderado por duración de cada tarea | E10: negativo = fecha vencida | H10: tareas | K10: pasó su fecha sin completarse
B12: =IF(COUNTA(CRONOGRAMA!$D$7:$D$46)=0,"Cargá tus tareas en la hoja CRONOGRAMA para ver tu panel.",IF(K9>0,"⚠ Tenés "&K9&" tarea(s) atrasada(s). Revisalas en CRONOGRAMA.",IF(D14+0.1<D13,"⚠ Tu avance está por detrás del tiempo transcurrido. Conviene ajustar el plan.","✔ Vas bien: tu avance acompaña el tiempo transcurrido.")))
B13: Tiempo transcurrido | D13: =IF(OR(N(FechaIni)=0,N(FechaFin)<=N(FechaIni)),0,MAX(0,MIN(1,(TODAY()-FechaIni)/(FechaFin-FechaIni))))
B14: Avance real | D14: =B9
B16: AVANCE POR ETAPA
B17: Etapa | D17: Tareas | E17: Avance | F17: Atrasadas
B18: =IF('AJUSTES'!$B$15="","",'AJUSTES'!$B$15) | D18: =IF(B18="",0,COUNTIFS(CRONOGRAMA!$C$7:$C$46,B18,CRONOGRAMA!$D$7:$D$46,"<>")) | E18: =IF(B18="",0,IFERROR(SUMPRODUCT(((CRONOGRAMA!$C$7:$C$46=B18)*(CRONOGRAMA!$D$7:$D$46<>"")*(CRONOGRAMA!$F$7:$F$46-CRONOGRAMA!$E$7:$E$46+1))*CRONOGRAMA!$G$7:$G$46)/SUMPRODUCT(((CRONOGRAMA!$C$7:$C$46=B18)*(CRONOGRAMA!$D$7:$D$46<>"")*(CRONOGRAMA!$F$7:$F$46-CRONOGRAMA!$E$7:$E$46+1))),0)) | F18: =IF(B18="",0,COUNTIFS(CRONOGRAMA!$C$7:$C$46,B18,CRONOGRAMA!$H$7:$H$46,"Atrasada"))
B19: =IF('AJUSTES'!$B$16="","",'AJUSTES'!$B$16) | D19: =IF(B19="",0,COUNTIFS(CRONOGRAMA!$C$7:$C$46,B19,CRONOGRAMA!$D$7:$D$46,"<>")) | E19: =IF(B19="",0,IFERROR(SUMPRODUCT(((CRONOGRAMA!$C$7:$C$46=B19)*(CRONOGRAMA!$D$7:$D$46<>"")*(CRONOGRAMA!$F$7:$F$46-CRONOGRAMA!$E$7:$E$46+1))*CRONOGRAMA!$G$7:$G$46)/SUMPRODUCT(((CRONOGRAMA!$C$7:$C$46=B19)*(CRONOGRAMA!$D$7:$D$46<>"")*(CRONOGRAMA!$F$7:$F$46-CRONOGRAMA!$E$7:$E$46+1))),0)) | F19: =IF(B19="",0,COUNTIFS(CRONOGRAMA!$C$7:$C$46,B19,CRONOGRAMA!$H$7:$H$46,"Atrasada"))
B20: =IF('AJUSTES'!$B$17="","",'AJUSTES'!$B$17) | D20: =IF(B20="",0,COUNTIFS(CRONOGRAMA!$C$7:$C$46,B20,CRONOGRAMA!$D$7:$D$46,"<>")) | E20: =IF(B20="",0,IFERROR(SUMPRODUCT(((CRONOGRAMA!$C$7:$C$46=B20)*(CRONOGRAMA!$D$7:$D$46<>"")*(CRONOGRAMA!$F$7:$F$46-CRONOGRAMA!$E$7:$E$46+1))*CRONOGRAMA!$G$7:$G$46)/SUMPRODUCT(((CRONOGRAMA!$C$7:$C$46=B20)*(CRONOGRAMA!$D$7:$D$46<>"")*(CRONOGRAMA!$F$7:$F$46-CRONOGRAMA!$E$7:$E$46+1))),0)) | F20: =IF(B20="",0,COUNTIFS(CRONOGRAMA!$C$7:$C$46,B20,CRONOGRAMA!$H$7:$H$46,"Atrasada"))
B21: =IF('AJUSTES'!$B$18="","",'AJUSTES'!$B$18) | D21: =IF(B21="",0,COUNTIFS(CRONOGRAMA!$C$7:$C$46,B21,CRONOGRAMA!$D$7:$D$46,"<>")) | E21: =IF(B21="",0,IFERROR(SUMPRODUCT(((CRONOGRAMA!$C$7:$C$46=B21)*(CRONOGRAMA!$D$7:$D$46<>"")*(CRONOGRAMA!$F$7:$F$46-CRONOGRAMA!$E$7:$E$46+1))*CRONOGRAMA!$G$7:$G$46)/SUMPRODUCT(((CRONOGRAMA!$C$7:$C$46=B21)*(CRONOGRAMA!$D$7:$D$46<>"")*(CRONOGRAMA!$F$7:$F$46-CRONOGRAMA!$E$7:$E$46+1))),0)) | F21: =IF(B21="",0,COUNTIFS(CRONOGRAMA!$C$7:$C$46,B21,CRONOGRAMA!$H$7:$H$46,"Atrasada"))
B22: =IF('AJUSTES'!$B$19="","",'AJUSTES'!$B$19) | D22: =IF(B22="",0,COUNTIFS(CRONOGRAMA!$C$7:$C$46,B22,CRONOGRAMA!$D$7:$D$46,"<>")) | E22: =IF(B22="",0,IFERROR(SUMPRODUCT(((CRONOGRAMA!$C$7:$C$46=B22)*(CRONOGRAMA!$D$7:$D$46<>"")*(CRONOGRAMA!$F$7:$F$46-CRONOGRAMA!$E$7:$E$46+1))*CRONOGRAMA!$G$7:$G$46)/SUMPRODUCT(((CRONOGRAMA!$C$7:$C$46=B22)*(CRONOGRAMA!$D$7:$D$46<>"")*(CRONOGRAMA!$F$7:$F$46-CRONOGRAMA!$E$7:$E$46+1))),0)) | F22: =IF(B22="",0,COUNTIFS(CRONOGRAMA!$C$7:$C$46,B22,CRONOGRAMA!$H$7:$H$46,"Atrasada"))
B23: =IF('AJUSTES'!$B$20="","",'AJUSTES'!$B$20) | D23: =IF(B23="",0,COUNTIFS(CRONOGRAMA!$C$7:$C$46,B23,CRONOGRAMA!$D$7:$D$46,"<>")) | E23: =IF(B23="",0,IFERROR(SUMPRODUCT(((CRONOGRAMA!$C$7:$C$46=B23)*(CRONOGRAMA!$D$7:$D$46<>"")*(CRONOGRAMA!$F$7:$F$46-CRONOGRAMA!$E$7:$E$46+1))*CRONOGRAMA!$G$7:$G$46)/SUMPRODUCT(((CRONOGRAMA!$C$7:$C$46=B23)*(CRONOGRAMA!$D$7:$D$46<>"")*(CRONOGRAMA!$F$7:$F$46-CRONOGRAMA!$E$7:$E$46+1))),0)) | F23: =IF(B23="",0,COUNTIFS(CRONOGRAMA!$C$7:$C$46,B23,CRONOGRAMA!$H$7:$H$46,"Atrasada"))
B24: =IF('AJUSTES'!$B$21="","",'AJUSTES'!$B$21) | D24: =IF(B24="",0,COUNTIFS(CRONOGRAMA!$C$7:$C$46,B24,CRONOGRAMA!$D$7:$D$46,"<>")) | E24: =IF(B24="",0,IFERROR(SUMPRODUCT(((CRONOGRAMA!$C$7:$C$46=B24)*(CRONOGRAMA!$D$7:$D$46<>"")*(CRONOGRAMA!$F$7:$F$46-CRONOGRAMA!$E$7:$E$46+1))*CRONOGRAMA!$G$7:$G$46)/SUMPRODUCT(((CRONOGRAMA!$C$7:$C$46=B24)*(CRONOGRAMA!$D$7:$D$46<>"")*(CRONOGRAMA!$F$7:$F$46-CRONOGRAMA!$E$7:$E$46+1))),0)) | F24: =IF(B24="",0,COUNTIFS(CRONOGRAMA!$C$7:$C$46,B24,CRONOGRAMA!$H$7:$H$46,"Atrasada"))
B25: =IF('AJUSTES'!$B$22="","",'AJUSTES'!$B$22) | D25: =IF(B25="",0,COUNTIFS(CRONOGRAMA!$C$7:$C$46,B25,CRONOGRAMA!$D$7:$D$46,"<>")) | E25: =IF(B25="",0,IFERROR(SUMPRODUCT(((CRONOGRAMA!$C$7:$C$46=B25)*(CRONOGRAMA!$D$7:$D$46<>"")*(CRONOGRAMA!$F$7:$F$46-CRONOGRAMA!$E$7:$E$46+1))*CRONOGRAMA!$G$7:$G$46)/SUMPRODUCT(((CRONOGRAMA!$C$7:$C$46=B25)*(CRONOGRAMA!$D$7:$D$46<>"")*(CRONOGRAMA!$F$7:$F$46-CRONOGRAMA!$E$7:$E$46+1))),0)) | F25: =IF(B25="",0,COUNTIFS(CRONOGRAMA!$C$7:$C$46,B25,CRONOGRAMA!$H$7:$H$46,"Atrasada"))
B26: =IF('AJUSTES'!$B$23="","",'AJUSTES'!$B$23) | D26: =IF(B26="",0,COUNTIFS(CRONOGRAMA!$C$7:$C$46,B26,CRONOGRAMA!$D$7:$D$46,"<>")) | E26: =IF(B26="",0,IFERROR(SUMPRODUCT(((CRONOGRAMA!$C$7:$C$46=B26)*(CRONOGRAMA!$D$7:$D$46<>"")*(CRONOGRAMA!$F$7:$F$46-CRONOGRAMA!$E$7:$E$46+1))*CRONOGRAMA!$G$7:$G$46)/SUMPRODUCT(((CRONOGRAMA!$C$7:$C$46=B26)*(CRONOGRAMA!$D$7:$D$46<>"")*(CRONOGRAMA!$F$7:$F$46-CRONOGRAMA!$E$7:$E$46+1))),0)) | F26: =IF(B26="",0,COUNTIFS(CRONOGRAMA!$C$7:$C$46,B26,CRONOGRAMA!$H$7:$H$46,"Atrasada"))
B27: TOTAL | D27: =SUM(D18:D26) | E27: =B9 | F27: =SUM(F18:F26)
B29: ESTADO DE LAS TAREAS
B30: Estado | D30: Tareas | E30: %
B31: Completada | D31: =COUNTIF(CRONOGRAMA!$H$7:$H$46,B31) | E31: =IF($D$35=0,0,D31/$D$35)
B32: En curso | D32: =COUNTIF(CRONOGRAMA!$H$7:$H$46,B32) | E32: =IF($D$35=0,0,D32/$D$35)
B33: Por empezar | D33: =COUNTIF(CRONOGRAMA!$H$7:$H$46,B33) | E33: =IF($D$35=0,0,D33/$D$35)
B34: Atrasada | D34: =COUNTIF(CRONOGRAMA!$H$7:$H$46,B34) | E34: =IF($D$35=0,0,D34/$D$35)
B35: TOTAL | D35: =SUM(D31:D34) | E35: =SUM(E31:E34)
B37: ÚLTIMA REUNIÓN CON TU TUTOR | E37: PRÓXIMA REUNIÓN
B38: =IF(COUNTIFS(REUNIONES!$B$7:$B$66,">0",REUNIONES!$B$7:$B$66,"<="&TODAY())=0,"-",SUMPRODUCT(MAX((REUNIONES!$B$7:$B$66<=TODAY())*REUNIONES!$B$7:$B$66))) | E38: =IFERROR(SMALL(REUNIONES!$B$7:$B$66,COUNTIF(REUNIONES!$B$7:$B$66,"<"&TODAY())+1),"-")
B39: según REUNIONES | E39: agendada en REUNIONES
B47: MIX SHOP DIGITAL · Herramientas inteligentes que simplifican tu vida.
B48: Versión gratuita · Si sos tutor de tesis y acompañás a varios estudiantes, conocé TESIS PRO PY → mixshopdigital.com.py

Sheet CRONOGRAMA
F1: CRONOGRAMA
B2: Herramientas inteligentes que simplifican tu vida. | F2: Tu plan, semana a semana
C4: Una fila por tarea. Completá las celdas amarillas: el estado y el diagrama de barras se arman solos. Deslizá hacia la derecha para ver las semanas.
C5: ← Volver al PANEL
B6: N° | C6: Etapa | D6: Tarea | E6: Inicio | F6: Fin | G6: Avance | H6: Estado | I6: Días que faltan | J6: =IF(N(FechaIni)=0,"",FechaIni-WEEKDAY(FechaIni,2)+1) | K6: =IF(J6="","",J6+7) | L6: =IF(K6="","",K6+7) | M6: =IF(L6="","",L6+7) | N6: =IF(M6="","",M6+7) | O6: =IF(N6="","",N6+7) | P6: =IF(O6="","",O6+7) | Q6: =IF(P6="","",P6+7) | R6: =IF(Q6="","",Q6+7) | ... BI6: =IF(BH6="","",BH6+7)
B7: =IF(D7="","",1) | C7: Tema y proyecto | D7: Elegir el tema y definir el problema | E7: 46174 | F7: 46193 | G7: 1 | H7: =IF(D7="","",IF(N(G7)>=1,"Completada",IF(AND(N(F7)>0,F7<TODAY()),"Atrasada",IF(AND(N(E7)>0,E7<=TODAY()),"En curso","Por empezar")))) | I7: =IF(OR(D7="",N(F7)=0,N(G7)>=1),"",F7-TODAY())
B8: =IF(D8="","",2) | C8: Tema y proyecto | D8: Redactar el anteproyecto | E8: 46194 | F8: 46234 | G8: 1 | H8: =IF(D8="","",IF(N(G8)>=1,"Completada",IF(AND(N(F8)>0,F8<TODAY()),"Atrasada",IF(AND(N(E8)>0,E8<=TODAY()),"En curso","Por empezar")))) | I8: =IF(OR(D8="",N(F8)=0,N(G8)>=1),"",F8-TODAY())
B9: =IF(D9="","",3) | C9: Marco teórico | D9: Buscar y leer antecedentes | E9: 46218 | F9: 46265 | G9: 1 | H9: =IF(D9="","",IF(N(G9)>=1,"Completada",IF(AND(N(F9)>0,F9<TODAY()),"Atrasada",IF(AND(N(E9)>0,E9<=TODAY()),"En curso","Por empezar")))) | I9: =IF(OR(D9="",N(F9)=0,N(G9)>=1),"",F9-TODAY())
B10: =IF(D10="","",4) | C10: Marco teórico | D10: Redactar el marco teórico | E10: 46266 | F10: 46310 | G10: 1 | H10: =IF(D10="","",IF(N(G10)>=1,"Completada",IF(AND(N(F10)>0,F10<TODAY()),"Atrasada",IF(AND(N(E10)>0,E10<=TODAY()),"En curso","Por empezar")))) | I10: =IF(OR(D10="",N(F10)=0,N(G10)>=1),"",F10-TODAY())
B11: =IF(D11="","",5) | C11: Metodología | D11: Diseñar la encuesta | E11: 46280 | F11: 46305 | G11: 1 | H11: =IF(D11="","",IF(N(G11)>=1,"Completada",IF(AND(N(F11)>0,F11<TODAY()),"Atrasada",IF(AND(N(E11)>0,E11<=TODAY()),"En curso","Por empezar")))) | I11: =IF(OR(D11="",N(F11)=0,N(G11)>=1),"",F11-TODAY())
B12: =IF(D12="","",6) | C12: Metodología | D12: Validar la encuesta con el tutor | E12: 46306 | F12: 46320 | G12: 0.8 | H12: =IF(D12="","",IF(N(G12)>=1,"Completada",IF(AND(N(F12)>0,F12<TODAY()),"Atrasada",IF(AND(N(E12)>0,E12<=TODAY()),"En curso","Por empezar")))) | I12: =IF(OR(D12="",N(F12)=0,N(G12)>=1),"",F12-TODAY())
B13: =IF(D13="","",7) | C13: Trabajo de campo | D13: Aplicar las encuestas | E13: 46315 | F13: 46356 | G13: 0.4 | H13: =IF(D13="","",IF(N(G13)>=1,"Completada",IF(AND(N(F13)>0,F13<TODAY()),"Atrasada",IF(AND(N(E13)>0,E13<=TODAY()),"En curso","Por empezar")))) | I13: =IF(OR(D13="",N(F13)=0,N(G13)>=1),"",F13-TODAY())
B14: =IF(D14="","",8) | C14: Trabajo de campo | D14: Cargar los datos | E14: 46341 | F14: 46366 | G14: 0 | H14: =IF(D14="","",IF(N(G14)>=1,"Completada",IF(AND(N(F14)>0,F14<TODAY()),"Atrasada",IF(AND(N(E14)>0,E14<=TODAY()),"En curso","Por empezar")))) | I14: =IF(OR(D14="",N(F14)=0,N(G14)>=1),"",F14-TODAY())
B15: =IF(D15="","",9) | C15: Análisis de datos | D15: Procesar y analizar resultados | E15: 46357 | F15: 46402 | G15: 0 | H15: =IF(D15="","",IF(N(G15)>=1,"Completada",IF(AND(N(F15)>0,F15<TODAY()),"Atrasada",IF(AND(N(E15)>0,E15<=TODAY()),"En curso","Por empezar")))) | I15: =IF(OR(D15="",N(F15)=0,N(G15)>=1),"",F15-TODAY())
B16: =IF(D16="","",10) | C16: Análisis de datos | D16: Elaborar tablas y gráficos | E16: 46392 | F16: 46418 | G16: 0 | H16: =IF(D16="","",IF(N(G16)>=1,"Completada",IF(AND(N(F16)>0,F16<TODAY()),"Atrasada",IF(AND(N(E16)>0,E16<=TODAY()),"En curso","Por empezar")))) | I16: =IF(OR(D16="",N(F16)=0,N(G16)>=1),"",F16-TODAY())
B17: =IF(D17="","",11) | C17: Redacción | D17: Redactar resultados y discusión | E17: 46402 | F17: 46446 | G17: 0 | H17: =IF(D17="","",IF(N(G17)>=1,"Completada",IF(AND(N(F17)>0,F17<TODAY()),"Atrasada",IF(AND(N(E17)>0,E17<=TODAY()),"En curso","Por empezar")))) | I17: =IF(OR(D17="",N(F17)=0,N(G17)>=1),"",F17-TODAY())
B18: =IF(D18="","",12) | C18: Redacción | D18: Redactar conclusiones | E18: 46447 | F18: 46461 | G18: 0 | H18: =IF(D18="","",IF(N(G18)>=1,"Completada",IF(AND(N(F18)>0,F18<TODAY()),"Atrasada",IF(AND(N(E18)>0,E18<=TODAY()),"En curso","Por empezar")))) | I18: =IF(OR(D18="",N(F18)=0,N(G18)>=1),"",F18-TODAY())
B19: =IF(D19="","",13) | C19: Redacción | D19: Introducción y resumen | E19: 46456 | F19: 46471 | G19: 0 | H19: =IF(D19="","",IF(N(G19)>=1,"Completada",IF(AND(N(F19)>0,F19<TODAY()),"Atrasada",IF(AND(N(E19)>0,E19<=TODAY()),"En curso","Por empezar")))) | I19: =IF(OR(D19="",N(F19)=0,N(G19)>=1),"",F19-TODAY())
B20: =IF(D20="","",14) | C20: Revisión del tutor | D20: Revisión del borrador completo | E20: 46462 | F20: 46477 | G20: 0 | H20: =IF(D20="","",IF(N(G20)>=1,"Completada",IF(AND(N(F20)>0,F20<TODAY()),"Atrasada",IF(AND(N(E20)>0,E20<=TODAY()),"En curso","Por empezar")))) | I20: =IF(OR(D20="",N(F20)=0,N(G20)>=1),"",F20-TODAY())
B21: =IF(D21="","",15) | C21: Revisión del tutor | D21: Hacer las correcciones | E21: 46478 | F21: 46487 | G21: 0 | H21: =IF(D21="","",IF(N(G21)>=1,"Completada",IF(AND(N(F21)>0,F21<TODAY()),"Atrasada",IF(AND(N(E21)>0,E21<=TODAY()),"En curso","Por empezar")))) | I21: =IF(OR(D21="",N(F21)=0,N(G21)>=1),"",F21-TODAY())
B22: =IF(D22="","",16) | C22: Formato y entrega | D22: Formato, citas y referencias | E22: 46478 | F22: 46492 | G22: 0 | H22: =IF(D22="","",IF(N(G22)>=1,"Completada",IF(AND(N(F22)>0,F22<TODAY()),"Atrasada",IF(AND(N(E22)>0,E22<=TODAY()),"En curso","Por empezar")))) | I22: =IF(OR(D22="",N(F22)=0,N(G22)>=1),"",F22-TODAY())
B23: =IF(D23="","",17) | C23: Formato y entrega | D23: Entregar las copias | E23: 46493 | F23: 46497 | G23: 0 | H23: =IF(D23="","",IF(N(G23)>=1,"Completada",IF(AND(N(F23)>0,F23<TODAY()),"Atrasada",IF(AND(N(E23)>0,E23<=TODAY()),"En curso","Por empezar")))) | I23: =IF(OR(D23="",N(F23)=0,N(G23)>=1),"",F23-TODAY())
B24: =IF(D24="","",18) | C24: Defensa | D24: Preparar la presentación | E24: 46487 | F24: 46502 | G24: 0 | H24: =IF(D24="","",IF(N(G24)>=1,"Completada",IF(AND(N(F24)>0,F24<TODAY()),"Atrasada",IF(AND(N(E24)>0,E24<=TODAY()),"En curso","Por empezar")))) | I24: =IF(OR(D24="",N(F24)=0,N(G24)>=1),"",F24-TODAY())
B25: =IF(D25="","",19) | C25: Defensa | D25: Defensa oral | E25: 46507 | F25: 46507 | G25: 0 | H25: =IF(D25="","",IF(N(G25)>=1,"Completada",IF(AND(N(F25)>0,F25<TODAY()),"Atrasada",IF(AND(N(E25)>0,E25<=TODAY()),"En curso","Por empezar")))) | I25: =IF(OR(D25="",N(F25)=0,N(G25)>=1),"",F25-TODAY())
B26: =IF(D26="","",20) | H26: =IF(D26="","",IF(N(G26)>=1,"Completada",IF(AND(N(F26)>0,F26<TODAY()),"Atrasada",IF(AND(N(E26)>0,E26<=TODAY()),"En curso","Por empezar")))) | I26: =IF(OR(D26="",N(F26)=0,N(G26)>=1),"",F26-TODAY())
B27: =IF(D27="","",21) | H27: =IF(D27="","",IF(N(G27)>=1,"Completada",IF(AND(N(F27)>0,F27<TODAY()),"Atrasada",IF(AND(N(E27)>0,E27<=TODAY()),"En curso","Por empezar")))) | I27: =IF(OR(D27="",N(F27)=0,N(G27)>=1),"",F27-TODAY())
B28: =IF(D28="","",22) | H28: =IF(D28="","",IF(N(G28)>=1,"Completada",IF(AND(N(F28)>0,F28<TODAY()),"Atrasada",IF(AND(N(E28)>0,E28<=TODAY()),"En curso","Por empezar")))) | I28: =IF(OR(D28="",N(F28)=0,N(G28)>=1),"",F28-TODAY())
B29: =IF(D29="","",23) | H29: =IF(D29="","",IF(N(G29)>=1,"Completada",IF(AND(N(F29)>0,F29<TODAY()),"Atrasada",IF(AND(N(E29)>0,E29<=TODAY()),"En curso","Por empezar")))) | I29: =IF(OR(D29="",N(F29)=0,N(G29)>=1),"",F29-TODAY())
B30: =IF(D30="","",24) | H30: =IF(D30="","",IF(N(G30)>=1,"Completada",IF(AND(N(F30)>0,F30<TODAY()),"Atrasada",IF(AND(N(E30)>0,E30<=TODAY()),"En curso","Por empezar")))) | I30: =IF(OR(D30="",N(F30)=0,N(G30)>=1),"",F30-TODAY())
B31: =IF(D31="","",25) | H31: =IF(D31="","",IF(N(G31)>=1,"Completada",IF(AND(N(F31)>0,F31<TODAY()),"Atrasada",IF(AND(N(E31)>0,E31<=TODAY()),"En curso","Por empezar")))) | I31: =IF(OR(D31="",N(F31)=0,N(G31)>=1),"",F31-TODAY())
B32: =IF(D32="","",26) | H32: =IF(D32="","",IF(N(G32)>=1,"Completada",IF(AND(N(F32)>0,F32<TODAY()),"Atrasada",IF(AND(N(E32)>0,E32<=TODAY()),"En curso","Por empezar")))) | I32: =IF(OR(D32="",N(F32)=0,N(G32)>=1),"",F32-TODAY())
B33: =IF(D33="","",27) | H33: =IF(D33="","",IF(N(G33)>=1,"Completada",IF(AND(N(F33)>0,F33<TODAY()),"Atrasada",IF(AND(N(E33)>0,E33<=TODAY()),"En curso","Por empezar")))) | I33: =IF(OR(D33="",N(F33)=0,N(G33)>=1),"",F33-TODAY())
B34: =IF(D34="","",28) | H34: =IF(D34="","",IF(N(G34)>=1,"Completada",IF(AND(N(F34)>0,F34<TODAY()),"Atrasada",IF(AND(N(E34)>0,E34<=TODAY()),"En curso","Por empezar")))) | I34: =IF(OR(D34="",N(F34)=0,N(G34)>=1),"",F34-TODAY())
B35: =IF(D35="","",29) | H35: =IF(D35="","",IF(N(G35)>=1,"Completada",IF(AND(N(F35)>0,F35<TODAY()),"Atrasada",IF(AND(N(E35)>0,E35<=TODAY()),"En curso","Por empezar")))) | I35: =IF(OR(D35="",N(F35)=0,N(G35)>=1),"",F35-TODAY())
B36: =IF(D36="","",30) | H36: =IF(D36="","",IF(N(G36)>=1,"Completada",IF(AND(N(F36)>0,F36<TODAY()),"Atrasada",IF(AND(N(E36)>0,E36<=TODAY()),"En curso","Por empezar")))) | I36: =IF(OR(D36="",N(F36)=0,N(G36)>=1),"",F36-TODAY())
B37: =IF(D37="","",31) | H37: =IF(D37="","",IF(N(G37)>=1,"Completada",IF(AND(N(F37)>0,F37<TODAY()),"Atrasada",IF(AND(N(E37)>0,E37<=TODAY()),"En curso","Por empezar")))) | I37: =IF(OR(D37="",N(F37)=0,N(G37)>=1),"",F37-TODAY())
B38: =IF(D38="","",32) | H38: =IF(D38="","",IF(N(G38)>=1,"Completada",IF(AND(N(F38)>0,F38<TODAY()),"Atrasada",IF(AND(N(E38)>0,E38<=TODAY()),"En curso","Por empezar")))) | I38: =IF(OR(D38="",N(F38)=0,N(G38)>=1),"",F38-TODAY())
B39: =IF(D39="","",33) | H39: =IF(D39="","",IF(N(G39)>=1,"Completada",IF(AND(N(F39)>0,F39<TODAY()),"Atrasada",IF(AND(N(E39)>0,E39<=TODAY()),"En curso","Por empezar")))) | I39: =IF(OR(D39="",N(F39)=0,N(G39)>=1),"",F39-TODAY())
B40: =IF(D40="","",34) | H40: =IF(D40="","",IF(N(G40)>=1,"Completada",IF(AND(N(F40)>0,F40<TODAY()),"Atrasada",IF(AND(N(E40)>0,E40<=TODAY()),"En curso","Por empezar")))) | I40: =IF(OR(D40="",N(F40)=0,N(G40)>=1),"",F40-TODAY())
B41: =IF(D41="","",35) | H41: =IF(D41="","",IF(N(G41)>=1,"Completada",IF(AND(N(F41)>0,F41<TODAY()),"Atrasada",IF(AND(N(E41)>0,E41<=TODAY()),"En curso","Por empezar")))) | I41: =IF(OR(D41="",N(F41)=0,N(G41)>=1),"",F41-TODAY())
...

Sheet REUNIONES
C1: REUNIONES
B2: Herramientas inteligentes que simplifican tu vida. | C2: Lo que hablás con tu tutor
B4: ← VOLVER | C4: Anotá cada reunión, también las que ya agendaste para más adelante. El PANEL te muestra la última y la próxima.
B6: Fecha | C6: Tema tratado | D6: Acuerdos y tareas pendientes
B7: 46183 | C7: Elección del tema | D7: Delimitar el problema y entregar el anteproyecto.
B8: 46211 | C8: Anteproyecto | D8: Ajustar los objetivos. Buscar 15 antecedentes.
B9: 46246 | C9: Antecedentes | D9: Ordenar las fuentes por tema.
B10: 46281 | C10: Marco teórico | D10: Corregir citas y completar el capítulo 2.
B11: 46309 | C11: Encuesta | D11: Validar la encuesta antes de aplicarla.
B12: 46337 | C12: Avance del trabajo de campo
B13: 46365 | C13: Primeros resultados
B69: MIX SHOP DIGITAL · Herramientas inteligentes que simplifican tu vida.
B70: Versión gratuita · Si sos tutor de tesis y acompañás a varios estudiantes, conocé TESIS PRO PY → mixshopdigital.com.py

Sheet AJUSTES
C1: AJUSTES
B2: Herramientas inteligentes que simplifican tu vida. | C2: Cargalos una sola vez
B4: ← VOLVER | C4: Completá solamente las celdas amarillas. Estos datos alimentan las demás hojas automáticamente.
B6: 1. TU TESIS
B7: Título del trabajo | C7: Lectura y rendimiento escolar (EJEMPLO) | D7: Aparece en el PANEL.
B8: Estudiante | C8: María | D8: Opcional.
B9: Tutor | C9: Prof. Ramírez | D9: Opcional.
B10: Fecha de inicio | C10: 46174 | D10: El día en que empezaste (o vas a empezar). El diagrama arranca esa semana.
B11: Fecha de entrega o defensa | C11: 46507 | D11: Tu fecha límite. El PANEL cuenta los días que faltan.
B13: 2. ETAPAS DE TU TESIS (podés renombrarlas)
B14: Se usan en la lista desplegable de CRONOGRAMA. Cambiá el nombre, pero no dejes huecos entre medio.
B15: Tema y proyecto | C15: Hasta 9 etapas.
B16: Marco teórico
B17: Metodología
B18: Trabajo de campo
B19: Análisis de datos
B20: Redacción
B21: Revisión del tutor
B22: Formato y entrega
B23: Defensa
B27: MIX SHOP DIGITAL · Herramientas inteligentes que simplifican tu vida.
B28: Versión gratuita · Si sos tutor de tesis y acompañás a varios estudiantes, conocé TESIS PRO PY → mixshopdigital.com.py

Sheet AYUDA
D1: AYUDA
B2: Herramientas inteligentes que simplifican tu vida. | D2: Se aprende en 2 minutos
B4: ← VOLVER | C4: Leé esta hoja una vez. Después ya no la vas a necesitar.
B6: ¿PARA QUÉ SIRVE?
B7: Para planificar tu tesis de principio a fin, ver semana a semana qué te toca hacer y saber si vas a llegar a tu fecha de entrega. Sin fórmulas y sin Internet.
B9: EMPEZÁ EN 3 PASOS
B10: 1) En AJUSTES poné el título de tu tesis, tu fecha de inicio y tu fecha de entrega o defensa. Si querés, renombrá las etapas.
B11: 2) En CRONOGRAMA anotá cada tarea: etapa, descripción, fecha de inicio, fecha de fin y cuánto avanzaste. El diagrama de barras se dibuja solo.
B12: 3) Mirá el PANEL: avance general, días que faltan, tareas atrasadas y un aviso que te dice cómo vas. Anotá tus reuniones con el tutor en REUNIONES.
B14: COLORES DEL DIAGRAMA
B15: Azul: tarea en marcha o por empezar. Verde: tarea completada. Coral: tarea atrasada. Columna dorada: la semana de hoy.
B17: PREGUNTAS FRECUENTES
B18: • Veo todo en cero: hacé clic en «Habilitar edición» en la barra amarilla de Excel.
B19: • ¿Cómo completo una tarea? Poné 100 % en la columna Avance.
B20: • ¿Por qué una tarea figura como atrasada? Porque pasó su fecha de fin y todavía no está al 100 %. Corregí el avance o movela de fecha.
... B34: Versión gratuita · Si sos tutor de tesis y acompañás a varios estudiantes, conocé TESIS PRO PY → mixshopdigital.com.py
