Workbook
Name NombreNeg: 'AJUSTES'!$C$7
Name AnioCtl: 'AJUSTES'!$C$8
Name Moneda: 'AJUSTES'!$C$9
Name PaisCod: 'AJUSTES'!$C$10
Name ListaPago: 'AJUSTES'!$B$14:$B$19
Name ListaEntrega: 'AJUSTES'!$C$14:$C$18
Name PedFecha: PEDIDOS!$C$8:$C$207
Name PedCli: PEDIDOS!$D$8:$D$207
Name PedTel: PEDIDOS!$E$8:$E$207
Name PedProd: PEDIDOS!$G$8:$G$207
Name PedTot: PEDIDOS!$L$8:$L$207
Name PedGan: PEDIDOS!$O$8:$O$207
Name PedPag: PEDIDOS!$Q$8:$Q$207
Name PedSal: PEDIDOS!$R$8:$R$207
Name PedEP: PEDIDOS!$S$8:$S$207
Name PedForma: PEDIDOS!$T$8:$T$207
Name PedEst: PEDIDOS!$V$8:$V$207
Name PedAviso: PEDIDOS!$W$8:$W$207
Name MesN: 'PANEL'!$P$6
Name Desde: 'PANEL'!$P$7
Name Hasta: 'PANEL'!$P$8

Sheet PANEL
F1: CONTROL DE PEDIDOS Y ENTREGAS
B2: Herramientas inteligentes que simplifican tu vida. | F2: Tu negocio, de un vistazo
C4: El panel se arma solo con lo que anotás en PEDIDOS. No hace falta escribir nada acá, salvo elegir el período.
B5: + Anotar pedidos | E5: Ajustes | G5: Ayuda
B6: Período a mirar: | C6: Todo el año | E6: ="Año: "&AnioCtl&" · "&NombreNeg | P6: =IFERROR(MATCH(C6,{"Todo el año","Enero","Febrero","Marzo","Abril","Mayo","Junio","Julio","Agosto","Septiembre","Octubre","Noviembre","Diciembre"},0)-1,0)
P7: =IF(MesN=0,DATE(AnioCtl,1,1),DATE(AnioCtl,MesN,1))
B8: VENTAS DEL PERÍODO | E8: COBRADO | H8: POR COBRAR | K8: GANANCIA ESTIMADA | P8: =IF(MesN=0,DATE(AnioCtl+1,1,1),DATE(AnioCtl,MesN+1,1))
B9: =SUMIFS(PedTot,PedFecha,">="&Desde,PedFecha,"<"&Hasta,PedEst,"<>Cancelado") | E9: =SUMIFS(PedPag,PedFecha,">="&Desde,PedFecha,"<"&Hasta,PedEst,"<>Cancelado") | H9: =SUMIFS(PedSal,PedFecha,">="&Desde,PedFecha,"<"&Hasta,PedEst,"<>Cancelado") | K9: =SUMIFS(PedGan,PedFecha,">="&Desde,PedFecha,"<"&Hasta,PedEst,"<>Cancelado") | P9: =SUMIFS(PedSal,PedEst,"<>Cancelado")
B10: =Moneda | E10: lo que ya te pagaron | H10: saldo de los pedidos del período | K10: solo pedidos con costos cargados
B12: PEDIDOS | E12: TICKET PROMEDIO | H12: ENTREGAS EN CURSO | K12: ENTREGAS ATRASADAS
B13: =COUNTIFS(PedFecha,">="&Desde,PedFecha,"<"&Hasta,PedEst,"<>Cancelado",PedCli,"<>") | E13: =IFERROR(B9/B13,0) | H13: =COUNTIF(PedEst,"Pendiente")+COUNTIF(PedEst,"Preparando")+COUNTIF(PedEst,"Enviado") | K13: =COUNTIF(PedAviso,"✖*")
B14: sin contar los cancelados | E14: venta promedio por pedido | H14: de todos los períodos | K14: pasaron la fecha prometida
B16: =IF(COUNTIF(PedCli,"?*")=0,"Cargá tus pedidos en la hoja PEDIDOS para ver tu panel.",IF(K13>0,"✖ Tenés "&K13&" entrega(s) atrasada(s): revisá «Próximas entregas» más abajo.",IF(P9>0,"⚠ Te deben "&FIXED(P9,0)&" "&Moneda&" en total: revisá «A cobrar» más abajo.","✔ Todo al día: sin entregas atrasadas ni saldos pendientes.")))
B18: ="MES A MES · "&AnioCtl
B19: Mes | C19: Pedidos | D19: Ventas | E19: Cobrado | F19: Ganancia
B20: Enero | C20: =COUNTIFS(PedFecha,">="&DATE(AnioCtl,1,1),PedFecha,"<"&DATE(AnioCtl,2,1),PedEst,"<>Cancelado",PedCli,"<>") | D20: =SUMIFS(PedTot,PedFecha,">="&DATE(AnioCtl,1,1),PedFecha,"<"&DATE(AnioCtl,2,1),PedEst,"<>Cancelado") | E20: =SUMIFS(PedPag,PedFecha,">="&DATE(AnioCtl,1,1),PedFecha,"<"&DATE(AnioCtl,2,1),PedEst,"<>Cancelado") | F20: =SUMIFS(PedGan,PedFecha,">="&DATE(AnioCtl,1,1),PedFecha,"<"&DATE(AnioCtl,2,1),PedEst,"<>Cancelado")
B21: Febrero | C21: =COUNTIFS(PedFecha,">="&DATE(AnioCtl,2,1),PedFecha,"<"&DATE(AnioCtl,3,1),PedEst,"<>Cancelado",PedCli,"<>") | D21: =SUMIFS(PedTot,PedFecha,">="&DATE(AnioCtl,2,1),PedFecha,"<"&DATE(AnioCtl,3,1),PedEst,"<>Cancelado") | E21: =SUMIFS(PedPag,PedFecha,">="&DATE(AnioCtl,2,1),PedFecha,"<"&DATE(AnioCtl,3,1),PedEst,"<>Cancelado") | F21: =SUMIFS(PedGan,PedFecha,">="&DATE(AnioCtl,2,1),PedFecha,"<"&DATE(AnioCtl,3,1),PedEst,"<>Cancelado")
B22: Marzo | C22: =COUNTIFS(PedFecha,">="&DATE(AnioCtl,3,1),PedFecha,"<"&DATE(AnioCtl,4,1),PedEst,"<>Cancelado",PedCli,"<>") | D22: =SUMIFS(PedTot,PedFecha,">="&DATE(AnioCtl,3,1),PedFecha,"<"&DATE(AnioCtl,4,1),PedEst,"<>Cancelado") | E22: =SUMIFS(PedPag,PedFecha,">="&DATE(AnioCtl,3,1),PedFecha,"<"&DATE(AnioCtl,4,1),PedEst,"<>Cancelado") | F22: =SUMIFS(PedGan,PedFecha,">="&DATE(AnioCtl,3,1),PedFecha,"<"&DATE(AnioCtl,4,1),PedEst,"<>Cancelado")
B23: Abril | C23: =COUNTIFS(PedFecha,">="&DATE(AnioCtl,4,1),PedFecha,"<"&DATE(AnioCtl,5,1),PedEst,"<>Cancelado",PedCli,"<>") | D23: =SUMIFS(PedTot,PedFecha,">="&DATE(AnioCtl,4,1),PedFecha,"<"&DATE(AnioCtl,5,1),PedEst,"<>Cancelado") | E23: =SUMIFS(PedPag,PedFecha,">="&DATE(AnioCtl,4,1),PedFecha,"<"&DATE(AnioCtl,5,1),PedEst,"<>Cancelado") | F23: =SUMIFS(PedGan,PedFecha,">="&DATE(AnioCtl,4,1),PedFecha,"<"&DATE(AnioCtl,5,1),PedEst,"<>Cancelado")
B24: Mayo | C24: =COUNTIFS(PedFecha,">="&DATE(AnioCtl,5,1),PedFecha,"<"&DATE(AnioCtl,6,1),PedEst,"<>Cancelado",PedCli,"<>") | D24: =SUMIFS(PedTot,PedFecha,">="&DATE(AnioCtl,5,1),PedFecha,"<"&DATE(AnioCtl,6,1),PedEst,"<>Cancelado") | E24: =SUMIFS(PedPag,PedFecha,">="&DATE(AnioCtl,5,1),PedFecha,"<"&DATE(AnioCtl,6,1),PedEst,"<>Cancelado") | F24: =SUMIFS(PedGan,PedFecha,">="&DATE(AnioCtl,5,1),PedFecha,"<"&DATE(AnioCtl,6,1),PedEst,"<>Cancelado")
B25: Junio | C25: =COUNTIFS(PedFecha,">="&DATE(AnioCtl,6,1),PedFecha,"<"&DATE(AnioCtl,7,1),PedEst,"<>Cancelado",PedCli,"<>") | D25: =SUMIFS(PedTot,PedFecha,">="&DATE(AnioCtl,6,1),PedFecha,"<"&DATE(AnioCtl,7,1),PedEst,"<>Cancelado") | E25: =SUMIFS(PedPag,PedFecha,">="&DATE(AnioCtl,6,1),PedFecha,"<"&DATE(AnioCtl,7,1),PedEst,"<>Cancelado") | F25: =SUMIFS(PedGan,PedFecha,">="&DATE(AnioCtl,6,1),PedFecha,"<"&DATE(AnioCtl,7,1),PedEst,"<>Cancelado")
B26: Julio | C26: =COUNTIFS(PedFecha,">="&DATE(AnioCtl,7,1),PedFecha,"<"&DATE(AnioCtl,8,1),PedEst,"<>Cancelado",PedCli,"<>") | D26: =SUMIFS(PedTot,PedFecha,">="&DATE(AnioCtl,7,1),PedFecha,"<"&DATE(AnioCtl,8,1),PedEst,"<>Cancelado") | E26: =SUMIFS(PedPag,PedFecha,">="&DATE(AnioCtl,7,1),PedFecha,"<"&DATE(AnioCtl,8,1),PedEst,"<>Cancelado") | F26: =SUMIFS(PedGan,PedFecha,">="&DATE(AnioCtl,7,1),PedFecha,"<"&DATE(AnioCtl,8,1),PedEst,"<>Cancelado")
B27: Agosto | C27: =COUNTIFS(PedFecha,">="&DATE(AnioCtl,8,1),PedFecha,"<"&DATE(AnioCtl,9,1),PedEst,"<>Cancelado",PedCli,"<>") | D27: =SUMIFS(PedTot,PedFecha,">="&DATE(AnioCtl,8,1),PedFecha,"<"&DATE(AnioCtl,9,1),PedEst,"<>Cancelado") | E27: =SUMIFS(PedPag,PedFecha,">="&DATE(AnioCtl,8,1),PedFecha,"<"&DATE(AnioCtl,9,1),PedEst,"<>Cancelado") | F27: =SUMIFS(PedGan,PedFecha,">="&DATE(AnioCtl,8,1),PedFecha,"<"&DATE(AnioCtl,9,1),PedEst,"<>Cancelado")
B28: Septiembre | C28: =COUNTIFS(PedFecha,">="&DATE(AnioCtl,9,1),PedFecha,"<"&DATE(AnioCtl,10,1),PedEst,"<>Cancelado",PedCli,"<>") | D28: =SUMIFS(PedTot,PedFecha,">="&DATE(AnioCtl,9,1),PedFecha,"<"&DATE(AnioCtl,10,1),PedEst,"<>Cancelado") | E28: =SUMIFS(PedPag,PedFecha,">="&DATE(AnioCtl,9,1),PedFecha,"<"&DATE(AnioCtl,10,1),PedEst,"<>Cancelado") | F28: =SUMIFS(PedGan,PedFecha,">="&DATE(AnioCtl,9,1),PedFecha,"<"&DATE(AnioCtl,10,1),PedEst,"<>Cancelado")
B29: Octubre | C29: =COUNTIFS(PedFecha,">="&DATE(AnioCtl,10,1),PedFecha,"<"&DATE(AnioCtl,11,1),PedEst,"<>Cancelado",PedCli,"<>") | D29: =SUMIFS(PedTot,PedFecha,">="&DATE(AnioCtl,10,1),PedFecha,"<"&DATE(AnioCtl,11,1),PedEst,"<>Cancelado") | E29: =SUMIFS(PedPag,PedFecha,">="&DATE(AnioCtl,10,1),PedFecha,"<"&DATE(AnioCtl,11,1),PedEst,"<>Cancelado") | F29: =SUMIFS(PedGan,PedFecha,">="&DATE(AnioCtl,10,1),PedFecha,"<"&DATE(AnioCtl,11,1),PedEst,"<>Cancelado")
B30: Noviembre | C30: =COUNTIFS(PedFecha,">="&DATE(AnioCtl,11,1),PedFecha,"<"&DATE(AnioCtl,12,1),PedEst,"<>Cancelado",PedCli,"<>") | D30: =SUMIFS(PedTot,PedFecha,">="&DATE(AnioCtl,11,1),PedFecha,"<"&DATE(AnioCtl,12,1),PedEst,"<>Cancelado") | E30: =SUMIFS(PedPag,PedFecha,">="&DATE(AnioCtl,11,1),PedFecha,"<"&DATE(AnioCtl,12,1),PedEst,"<>Cancelado") | F30: =SUMIFS(PedGan,PedFecha,">="&DATE(AnioCtl,11,1),PedFecha,"<"&DATE(AnioCtl,12,1),PedEst,"<>Cancelado")
B31: Diciembre | C31: =COUNTIFS(PedFecha,">="&DATE(AnioCtl,12,1),PedFecha,"<"&DATE(AnioCtl,13,1),PedEst,"<>Cancelado",PedCli,"<>") | D31: =SUMIFS(PedTot,PedFecha,">="&DATE(AnioCtl,12,1),PedFecha,"<"&DATE(AnioCtl,13,1),PedEst,"<>Cancelado") | E31: =SUMIFS(PedPag,PedFecha,">="&DATE(AnioCtl,12,1),PedFecha,"<"&DATE(AnioCtl,13,1),PedEst,"<>Cancelado") | F31: =SUMIFS(PedGan,PedFecha,">="&DATE(AnioCtl,12,1),PedFecha,"<"&DATE(AnioCtl,13,1),PedEst,"<>Cancelado")
B32: TOTAL | C32: =SUM(C20:C31) | D32: =SUM(D20:D31) | E32: =SUM(E20:E31) | F32: =SUM(F20:F31)
B34: ESTADO DE LAS ENTREGAS (período elegido) | H34: ESTADO DE PAGO (período elegido, sin cancelados)
B35: Estado | D35: Pedidos | E35: Monto | H35: Estado | J35: Pedidos | K35: Saldo por cobrar
B36: Pendiente | D36: =COUNTIFS(PedEst,$B36,PedFecha,">="&Desde,PedFecha,"<"&Hasta,PedCli,"<>") | E36: =SUMIFS(PedTot,PedEst,$B36,PedFecha,">="&Desde,PedFecha,"<"&Hasta) | H36: Pagado | J36: =COUNTIFS(PedEP,"✔ Pagado",PedFecha,">="&Desde,PedFecha,"<"&Hasta,PedCli,"<>") | K36: =SUMIFS(PedSal,PedEP,"✔ Pagado",PedFecha,">="&Desde,PedFecha,"<"&Hasta)
B37: Preparando | D37: =COUNTIFS(PedEst,$B37,PedFecha,">="&Desde,PedFecha,"<"&Hasta,PedCli,"<>") | E37: =SUMIFS(PedTot,PedEst,$B37,PedFecha,">="&Desde,PedFecha,"<"&Hasta) | H37: Pago parcial | J37: =COUNTIFS(PedEP,"⚠ Pago parcial",PedFecha,">="&Desde,PedFecha,"<"&Hasta,PedCli,"<>") | K37: =SUMIFS(PedSal,PedEP,"⚠ Pago parcial",PedFecha,">="&Desde,PedFecha,"<"&Hasta)
B38: Enviado | D38: =COUNTIFS(PedEst,$B38,PedFecha,">="&Desde,PedFecha,"<"&Hasta,PedCli,"<>") | E38: =SUMIFS(PedTot,PedEst,$B38,PedFecha,">="&Desde,PedFecha,"<"&Hasta) | H38: Sin pagar | J38: =COUNTIFS(PedEP,"✖ Sin pagar",PedFecha,">="&Desde,PedFecha,"<"&Hasta,PedCli,"<>") | K38: =SUMIFS(PedSal,PedEP,"✖ Sin pagar",PedFecha,">="&Desde,PedFecha,"<"&Hasta)
B39: Entregado | D39: =COUNTIFS(PedEst,$B39,PedFecha,">="&Desde,PedFecha,"<"&Hasta,PedCli,"<>") | E39: =SUMIFS(PedTot,PedEst,$B39,PedFecha,">="&Desde,PedFecha,"<"&Hasta) | H39: TOTAL | J39: =SUM(J36:J38) | K39: =SUM(K36:K38)
B40: Cancelado | D40: =COUNTIFS(PedEst,$B40,PedFecha,">="&Desde,PedFecha,"<"&Hasta,PedCli,"<>") | E40: =SUMIFS(PedTot,PedEst,$B40,PedFecha,">="&Desde,PedFecha,"<"&Hasta)
B41: TOTAL | D41: =SUM(D36:D40) | E41: =SUM(E36:E40)
B58: POR FORMA DE ENTREGA (período elegido)
B59: Forma de entrega | D59: Pedidos | E59: Ventas
B60: =IF('AJUSTES'!$C$14="","",'AJUSTES'!$C$14) | D60: =IF($B60="",0,COUNTIFS(PedForma,$B60,PedFecha,">="&Desde,PedFecha,"<"&Hasta,PedEst,"<>Cancelado",PedCli,"<>")) | E60: =IF($B60="",0,SUMIFS(PedTot,PedForma,$B60,PedFecha,">="&Desde,PedFecha,"<"&Hasta,PedEst,"<>Cancelado"))
B61: =IF('AJUSTES'!$C$15="","",'AJUSTES'!$C$15) | D61: =IF($B61="",0,COUNTIFS(PedForma,$B61,PedFecha,">="&Desde,PedFecha,"<"&Hasta,PedEst,"<>Cancelado",PedCli,"<>")) | E61: =IF($B61="",0,SUMIFS(PedTot,PedForma,$B61,PedFecha,">="&Desde,PedFecha,"<"&Hasta,PedEst,"<>Cancelado"))
...

Sheet PEDIDOS
G1: PEDIDOS
B2: Herramientas inteligentes que simplifican tu vida. | G2: Una fila por pedido
C4: Completá las celdas amarillas. El total, el saldo, la ganancia y los avisos se calculan solos. Si dejás «Cant.» vacía se cuenta 1.
B5: ← Volver al PANEL | E5: Ajustes
B6: TOTAL de las filas visibles (usá el filtro de las flechas del encabezado) → | L6: =SUBTOTAL(109,AB8:AB207) | O6: =SUBTOTAL(109,O8:O207) | Q6: =SUBTOTAL(109,Q8:Q207) | R6: =SUBTOTAL(109,R8:R207)
B7: N° | C7: Fecha del pedido | D7: Cliente | E7: WhatsApp / teléfono | F7: Chat | G7: Producto o detalle | H7: Cant. | I7: Precio unitario | J7: Descuento | K7: Envío cobrado al cliente | L7: TOTAL del pedido | M7: Costo del producto (total) | N7: Costo del envío (lo que pagás) | O7: GANANCIA | P7: Forma de pago | Q7: Pagado hasta ahora | R7: SALDO | S7: Estado de pago | T7: Forma de entrega | U7: Entrega prometida | V7: Estado de entrega | W7: AVISO | X7: Nota
B8: =IF(AND($D8="",$G8=""),"",ROW()-7) | F8: =IF($Y8="","",HYPERLINK("https://wa.me/"&$Y8&"?text="&SUBSTITUTE("Hola "&$D8&", te escribo por tu pedido de "&$G8&"."," ","%20"),"Abrir chat")) | L8: =IF(AND($D8="",$G8=""),"",IF(N($H8)=0,1,$H8)*N($I8)-N($J8)+N($K8)) | O8: =IF(OR(AND($D8="",$G8=""),$M8="",$V8="Cancelado"),"",$L8-N($M8)-N($N8)) | R8: =IF(AND($D8="",$G8=""),"",IF($V8="Cancelado",0,MAX(0,$L8-N($Q8)))) | S8: =IF(AND($D8="",$G8=""),"",IF($V8="Cancelado","Cancelado",IF($L8<=0,"",IF(N($Q8)>=$L8,"✔ Pagado",IF(N($Q8)>0,"⚠ Pago parcial","✖ Sin pagar"))))) | W8: =IF(AND($D8="",$G8=""),"",IF($C8="","⚠ Falta la fecha del pedido",IF($V8="","⚠ Elegí el estado de entrega",IF($V8="Cancelado","Cancelado",IF($V8="Entregado",IF($R8>0,"⚠ Entregado: falta cobrar","✔ Cerrado"),IF(AND(N($U8)>0,$U8<TODAY()),"✖ Entrega atrasada ("&(TODAY()-$U8)&" d)","En curso")))))) | Y8: =IF($E8&""="","",IF(LEFT(SUBSTITUTE(SUBSTITUTE(SUBSTITUTE(SUBSTITUTE(SUBSTITUTE($E8&""," ",""),"-",""),"+",""),"(",""),")",""),1)="0",PaisCod&MID(SUBSTITUTE(SUBSTITUTE(SUBSTITUTE(SUBSTITUTE(SUBSTITUTE($E8&""," ",""),"-",""),"+",""),"(",""),")",""),2,20),SUBSTITUTE(SUBSTITUTE(SUBSTITUTE(SUBSTITUTE(SUBSTITUTE($E8&""," ",""),"-",""),"+",""),"(",""),")",""))) | Z8: =IF(AND(N($R8)>0,$V8<>"Cancelado"),$R8+ROW()/1000000,"") | AA8: =IF(AND(OR($V8="Pendiente",$V8="Preparando",$V8="Enviado"),N($U8)>0),$U8+ROW()/1000000,"") | AB8: =IF(AND($D8="",$G8=""),"",IF($V8="Cancelado",0,$L8))
B9: =IF(AND($D9="",$G9=""),"",ROW()-7) | F9: =IF($Y9="","",HYPERLINK("https://wa.me/"&$Y9&"?text="&SUBSTITUTE("Hola "&$D9&", te escribo por tu pedido de "&$G9&"."," ","%20"),"Abrir chat")) | L9: =IF(AND($D9="",$G9=""),"",IF(N($H9)=0,1,$H9)*N($I9)-N($J9)+N($K9)) | O9: =IF(OR(AND($D9="",$G9=""),$M9="",$V9="Cancelado"),"",$L9-N($M9)-N($N9)) | R9: =IF(AND($D9="",$G9=""),"",IF($V9="Cancelado",0,MAX(0,$L9-N($Q9)))) | S9: =IF(AND($D9="",$G9=""),"",IF($V9="Cancelado","Cancelado",IF($L9<=0,"",IF(N($Q9)>=$L9,"✔ Pagado",IF(N($Q9)>0,"⚠ Pago parcial","✖ Sin pagar"))))) | W9: =IF(AND($D9="",$G9=""),"",IF($C9="","⚠ Falta la fecha del pedido",IF($V9="","⚠ Elegí el estado de entrega",IF($V9="Cancelado","Cancelado",IF($V9="Entregado",IF($R9>0,"⚠ Entregado: falta cobrar","✔ Cerrado"),IF(AND(N($U9)>0,$U9<TODAY()),"✖ Entrega atrasada ("&(TODAY()-$U9)&" d)","En curso")))))) | Y9: =IF($E9&""="","",IF(LEFT(SUBSTITUTE(SUBSTITUTE(SUBSTITUTE(SUBSTITUTE(SUBSTITUTE($E9&""," ",""),"-",""),"+",""),"(",""),")",""),1)="0",PaisCod&MID(SUBSTITUTE(SUBSTITUTE(SUBSTITUTE(SUBSTITUTE(SUBSTITUTE($E9&""," ",""),"-",""),"+",""),"(",""),")",""),2,20),SUBSTITUTE(SUBSTITUTE(SUBSTITUTE(SUBSTITUTE(SUBSTITUTE($E9&""," ",""),"-",""),"+",""),"(",""),")",""))) | Z9: =IF(AND(N($R9)>0,$V9<>"Cancelado"),$R9+ROW()/1000000,"") | AA9: =IF(AND(OR($V9="Pendiente",$V9="Preparando",$V9="Enviado"),N($U9)>0),$U9+ROW()/1000000,"") | AB9: =IF(AND($D9="",$G9=""),"",IF($V9="Cancelado",0,$L9))
B10: =IF(AND($D10="",$G10=""),"",ROW()-7) | F10: =IF($Y10="","",HYPERLINK("https://wa.me/"&$Y10&"?text="&SUBSTITUTE("Hola "&$D10&", te escribo por tu pedido de "&$G10&"."," ","%20"),"Abrir chat")) | L10: =IF(AND($D10="",$G10=""),"",IF(N($H10)=0,1,$H10)*N($I10)-N($J10)+N($K10)) | O10: =IF(OR(AND($D10="",$G10=""),$M10="",$V10="Cancelado"),"",$L10-N($M10)-N($N10)) | R10: =IF(AND($D10="",$G10=""),"",IF($V10="Cancelado",0,MAX(0,$L10-N($Q10)))) | S10: =IF(AND($D10="",$G10=""),"",IF($V10="Cancelado","Cancelado",IF($L10<=0,"",IF(N($Q10)>=$L10,"✔ Pagado",IF(N($Q10)>0,"⚠ Pago parcial","✖ Sin pagar"))))) | W10: =IF(AND($D10="",$G10=""),"",IF($C10="","⚠ Falta la fecha del pedido",IF($V10="","⚠ Elegí el estado de entrega",IF($V10="Cancelado","Cancelado",IF($V10="Entregado",IF($R10>0,"⚠ Entregado: falta cobrar","✔ Cerrado"),IF(AND(N($U10)>0,$U10<TODAY()),"✖ Entrega atrasada ("&(TODAY()-$U10)&" d)","En curso")))))) | Y10: =IF($E10&""="","",IF(LEFT(SUBSTITUTE(SUBSTITUTE(SUBSTITUTE(SUBSTITUTE(SUBSTITUTE($E10&""," ",""),"-",""),"+",""),"(",""),")",""),1)="0",PaisCod&MID(SUBSTITUTE(SUBSTITUTE(SUBSTITUTE(SUBSTITUTE(SUBSTITUTE($E10&""," ",""),"-",""),"+",""),"(",""),")",""),2,20),SUBSTITUTE(SUBSTITUTE(SUBSTITUTE(SUBSTITUTE(SUBSTITUTE($E10&""," ",""),"-",""),"+",""),"(",""),")",""))) | Z10: =IF(AND(N($R10)>0,$V10<>"Cancelado"),$R10+ROW()/1000000,"") | AA10: =IF(AND(OR($V10="Pendiente",$V10="Preparando",$V10="Enviado"),N($U10)>0),$U10+ROW()/1000000,"") | AB10: =IF(AND($D10="",$G10=""),"",IF($V10="Cancelado",0,$L10))
B11: =IF(AND($D11="",$G11=""),"",ROW()-7) | F11: =IF($Y11="","",HYPERLINK("https://wa.me/"&$Y11&"?text="&SUBSTITUTE("Hola "&$D11&", te escribo por tu pedido de "&$G11&"."," ","%20"),"Abrir chat")) | L11: =IF(AND($D11="",$G11=""),"",IF(N($H11)=0,1,$H11)*N($I11)-N($J11)+N($K11)) | O11: =IF(OR(AND($D11="",$G11=""),$M11="",$V11="Cancelado"),"",$L11-N($M11)-N($N11)) | R11: =IF(AND($D11="",$G11=""),"",IF($V11="Cancelado",0,MAX(0,$L11-N($Q11)))) | S11: =IF(AND($D11="",$G11=""),"",IF($V11="Cancelado","Cancelado",IF($L11<=0,"",IF(N($Q11)>=$L11,"✔ Pagado",IF(N($Q11)>0,"⚠ Pago parcial","✖ Sin pagar"))))) | W11: =IF(AND($D11="",$G11=""),"",IF($C11="","⚠ Falta la fecha del pedido",IF($V11="","⚠ Elegí el estado de entrega",IF($V11="Cancelado","Cancelado",IF($V11="Entregado",IF($R11>0,"⚠ Entregado: falta cobrar","✔ Cerrado"),IF(AND(N($U11)>0,$U11<TODAY()),"✖ Entrega atrasada ("&(TODAY()-$U11)&" d)","En curso")))))) | Y11: =IF($E11&""="","",IF(LEFT(SUBSTITUTE(SUBSTITUTE(SUBSTITUTE(SUBSTITUTE(SUBSTITUTE($E11&""," ",""),"-",""),"+",""),"(",""),")",""),1)="0",PaisCod&MID(SUBSTITUTE(SUBSTITUTE(SUBSTITUTE(SUBSTITUTE(SUBSTITUTE($E11&""," ",""),"-",""),"+",""),"(",""),")",""),2,20),SUBSTITUTE(SUBSTITUTE(SUBSTITUTE(SUBSTITUTE(SUBSTITUTE($E11&""," ",""),"-",""),"+",""),"(",""),")",""))) | Z11: =IF(AND(N($R11)>0,$V11<>"Cancelado"),$R11+ROW()/1000000,"") | AA11: =IF(AND(OR($V11="Pendiente",$V11="Preparando",$V11="Enviado"),N($U11)>0),$U11+ROW()/1000000,"") | AB11: =IF(AND($D11="",$G11=""),"",IF($V11="Cancelado",0,$L11))
B12: =IF(AND($D12="",$G12=""),"",ROW()-7) | F12: =IF($Y12="","",HYPERLINK("https://wa.me/"&$Y12&"?text="&SUBSTITUTE("Hola "&$D12&", te escribo por tu pedido de "&$G12&"."," ","%20"),"Abrir chat")) | L12: =IF(AND($D12="",$G12=""),"",IF(N($H12)=0,1,$H12)*N($I12)-N($J12)+N($K12)) | O12: =IF(OR(AND($D12="",$G12=""),$M12="",$V12="Cancelado"),"",$L12-N($M12)-N($N12)) | R12: =IF(AND($D12="",$G12=""),"",IF($V12="Cancelado",0,MAX(0,$L12-N($Q12)))) | S12: =IF(AND($D12="",$G12=""),"",IF($V12="Cancelado","Cancelado",IF($L12<=0,"",IF(N($Q12)>=$L12,"✔ Pagado",IF(N($Q12)>0,"⚠ Pago parcial","✖ Sin pagar"))))) | W12: =IF(AND($D12="",$G12=""),"",IF($C12="","⚠ Falta la fecha del pedido",IF($V12="","⚠ Elegí el estado de entrega",IF($V12="Cancelado","Cancelado",IF($V12="Entregado",IF($R12>0,"⚠ Entregado: falta cobrar","✔ Cerrado"),IF(AND(N($U12)>0,$U12<TODAY()),"✖ Entrega atrasada ("&(TODAY()-$U12)&" d)","En curso")))))) | Y12: =IF($E12&""="","",IF(LEFT(SUBSTITUTE(SUBSTITUTE(SUBSTITUTE(SUBSTITUTE(SUBSTITUTE($E12&""," ",""),"-",""),"+",""),"(",""),")",""),1)="0",PaisCod&MID(SUBSTITUTE(SUBSTITUTE(SUBSTITUTE(SUBSTITUTE(SUBSTITUTE($E12&""," ",""),"-",""),"+",""),"(",""),")",""),2,20),SUBSTITUTE(SUBSTITUTE(SUBSTITUTE(SUBSTITUTE(SUBSTITUTE($E12&""," ",""),"-",""),"+",""),"(",""),")",""))) | Z12: =IF(AND(N($R12)>0,$V12<>"Cancelado"),$R12+ROW()/1000000,"") | AA12: =IF(AND(OR($V12="Pendiente",$V12="Preparando",$V12="Enviado"),N($U12)>0),$U12+ROW()/1000000,"") | AB12: =IF(AND($D12="",$G12=""),"",IF($V12="Cancelado",0,$L12))
B13: =IF(AND($D13="",$G13=""),"",ROW()-7) | F13: =IF($Y13="","",HYPERLINK("https://wa.me/"&$Y13&"?text="&SUBSTITUTE("Hola "&$D13&", te escribo por tu pedido de "&$G13&"."," ","%20"),"Abrir chat")) | L13: =IF(AND($D13="",$G13=""),"",IF(N($H13)=0,1,$H13)*N($I13)-N($J13)+N($K13)) | O13: =IF(OR(AND($D13="",$G13=""),$M13="",$V13="Cancelado"),"",$L13-N($M13)-N($N13)) | R13: =IF(AND($D13="",$G13=""),"",IF($V13="Cancelado",0,MAX(0,$L13-N($Q13)))) | S13: =IF(AND($D13="",$G13=""),"",IF($V13="Cancelado","Cancelado",IF($L13<=0,"",IF(N($Q13)>=$L13,"✔ Pagado",IF(N($Q13)>0,"⚠ Pago parcial","✖ Sin pagar"))))) | W13: =IF(AND($D13="",$G13=""),"",IF($C13="","⚠ Falta la fecha del pedido",IF($V13="","⚠ Elegí el estado de entrega",IF($V13="Cancelado","Cancelado",IF($V13="Entregado",IF($R13>0,"⚠ Entregado: falta cobrar","✔ Cerrado"),IF(AND(N($U13)>0,$U13<TODAY()),"✖ Entrega atrasada ("&(TODAY()-$U13)&" d)","En curso")))))) | Y13: =IF($E13&""="","",IF(LEFT(SUBSTITUTE(SUBSTITUTE(SUBSTITUTE(SUBSTITUTE(SUBSTITUTE($E13&""," ",""),"-",""),"+",""),"(",""),")",""),1)="0",PaisCod&MID(SUBSTITUTE(SUBSTITUTE(SUBSTITUTE(SUBSTITUTE(SUBSTITUTE($E13&""," ",""),"-",""),"+",""),"(",""),")",""),2,20),SUBSTITUTE(SUBSTITUTE(SUBSTITUTE(SUBSTITUTE(SUBSTITUTE($E13&""," ",""),"-",""),"+",""),"(",""),")",""))) | Z13: =IF(AND(N($R13)>0,$V13<>"Cancelado"),$R13+ROW()/1000000,"") | AA13: =IF(AND(OR($V13="Pendiente",$V13="Preparando",$V13="Enviado"),N($U13)>0),$U13+ROW()/1000000,"") | AB13: =IF(AND($D13="",$G13=""),"",IF($V13="Cancelado",0,$L13))
B14: =IF(AND($D14="",$G14=""),"",ROW()-7) | F14: =IF($Y14="","",HYPERLINK("https://wa.me/"&$Y14&"?text="&SUBSTITUTE("Hola "&$D14&", te escribo por tu pedido de "&$G14&"."," ","%20"),"Abrir chat")) | L14: =IF(AND($D14="",$G14=""),"",IF(N($H14)=0,1,$H14)*N($I14)-N($J14)+N($K14)) | O14: =IF(OR(AND($D14="",$G14=""),$M14="",$V14="Cancelado"),"",$L14-N($M14)-N($N14)) | R14: =IF(AND($D14="",$G14=""),"",IF($V14="Cancelado",0,MAX(0,$L14-N($Q14)))) | S14: =IF(AND($D14="",$G14=""),"",IF($V14="Cancelado","Cancelado",IF($L14<=0,"",IF(N($Q14)>=$L14,"✔ Pagado",IF(N($Q14)>0,"⚠ Pago parcial","✖ Sin pagar"))))) | W14: =IF(AND($D14="",$G14=""),"",IF($C14="","⚠ Falta la fecha del pedido",IF($V14="","⚠ Elegí el estado de entrega",IF($V14="Cancelado","Cancelado",IF($V14="Entregado",IF($R14>0,"⚠ Entregado: falta cobrar","✔ Cerrado"),IF(AND(N($U14)>0,$U14<TODAY()),"✖ Entrega atrasada ("&(TODAY()-$U14)&" d)","En curso")))))) | Y14: =IF($E14&""="","",IF(LEFT(SUBSTITUTE(SUBSTITUTE(SUBSTITUTE(SUBSTITUTE(SUBSTITUTE($E14&""," ",""),"-",""),"+",""),"(",""),")",""),1)="0",PaisCod&MID(SUBSTITUTE(SUBSTITUTE(SUBSTITUTE(SUBSTITUTE(SUBSTITUTE($E14&""," ",""),"-",""),"+",""),"(",""),")",""),2,20),SUBSTITUTE(SUBSTITUTE(SUBSTITUTE(SUBSTITUTE(SUBSTITUTE($E14&""," ",""),"-",""),"+",""),"(",""),")",""))) | Z14: =IF(AND(N($R14)>0,$V14<>"Cancelado"),$R14+ROW()/1000000,"") | AA14: =IF(AND(OR($V14="Pendiente",$V14="Preparando",$V14="Enviado"),N($U14)>0),$U14+ROW()/1000000,"") | AB14: =IF(AND($D14="",$G14=""),"",IF($V14="Cancelado",0,$L14))
B15: =IF(AND($D15="",$G15=""),"",ROW()-7) | F15: =IF($Y15="","",HYPERLINK("https://wa.me/"&$Y15&"?text="&SUBSTITUTE("Hola "&$D15&", te escribo por tu pedido de "&$G15&"."," ","%20"),"Abrir chat")) | L15: =IF(AND($D15="",$G15=""),"",IF(N($H15)=0,1,$H15)*N($I15)-N($J15)+N($K15)) | O15: =IF(OR(AND($D15="",$G15=""),$M15="",$V15="Cancelado"),"",$L15-N($M15)-N($N15)) | R15: =IF(AND($D15="",$G15=""),"",IF($V15="Cancelado",0,MAX(0,$L15-N($Q15)))) | S15: =IF(AND($D15="",$G15=""),"",IF($V15="Cancelado","Cancelado",IF($L15<=0,"",IF(N($Q15)>=$L15,"✔ Pagado",IF(N($Q15)>0,"⚠ Pago parcial","✖ Sin pagar"))))) | W15: =IF(AND($D15="",$G15=""),"",IF($C15="","⚠ Falta la fecha del pedido",IF($V15="","⚠ Elegí el estado de entrega",IF($V15="Cancelado","Cancelado",IF($V15="Entregado",IF($R15>0,"⚠ Entregado: falta cobrar","✔ Cerrado"),IF(AND(N($U15)>0,$U15<TODAY()),"✖ Entrega atrasada ("&(TODAY()-$U15)&" d)","En curso")))))) | Y15: =IF($E15&""="","",IF(LEFT(SUBSTITUTE(SUBSTITUTE(SUBSTITUTE(SUBSTITUTE(SUBSTITUTE($E15&""," ",""),"-",""),"+",""),"(",""),")",""),1)="0",PaisCod&MID(SUBSTITUTE(SUBSTITUTE(SUBSTITUTE(SUBSTITUTE(SUBSTITUTE($E15&""," ",""),"-",""),"+",""),"(",""),")",""),2,20),SUBSTITUTE(SUBSTITUTE(SUBSTITUTE(SUBSTITUTE(SUBSTITUTE($E15&""," ",""),"-",""),"+",""),"(",""),")",""))) | Z15: =IF(AND(N($R15)>0,$V15<>"Cancelado"),$R15+ROW()/1000000,"") | AA15: =IF(AND(OR($V15="Pendiente",$V15="Preparando",$V15="Enviado"),N($U15)>0),$U15+ROW()/1000000,"") | AB15: =IF(AND($D15="",$G15=""),"",IF($V15="Cancelado",0,$L15))
B16: =IF(AND($D16="",$G16=""),"",ROW()-7) | F16: =IF($Y16="","",HYPERLINK("https://wa.me/"&$Y16&"?text="&SUBSTITUTE("Hola "&$D16&", te escribo por tu pedido de "&$G16&"."," ","%20"),"Abrir chat")) | L16: =IF(AND($D16="",$G16=""),"",IF(N($H16)=0,1,$H16)*N($I16)-N($J16)+N($K16)) | O16: =IF(OR(AND($D16="",$G16=""),$M16="",$V16="Cancelado"),"",$L16-N($M16)-N($N16)) | R16: =IF(AND($D16="",$G16=""),"",IF($V16="Cancelado",0,MAX(0,$L16-N($Q16)))) | S16: =IF(AND($D16="",$G16=""),"",IF($V16="Cancelado","Cancelado",IF($L16<=0,"",IF(N($Q16)>=$L16,"✔ Pagado",IF(N($Q16)>0,"⚠ Pago parcial","✖ Sin pagar"))))) | W16: =IF(AND($D16="",$G16=""),"",IF($C16="","⚠ Falta la fecha del pedido",IF($V16="","⚠ Elegí el estado de entrega",IF($V16="Cancelado","Cancelado",IF($V16="Entregado",IF($R16>0,"⚠ Entregado: falta cobrar","✔ Cerrado"),IF(AND(N($U16)>0,$U16<TODAY()),"✖ Entrega atrasada ("&(TODAY()-$U16)&" d)","En curso")))))) | Y16: =IF($E16&""="","",IF(LEFT(SUBSTITUTE(SUBSTITUTE(SUBSTITUTE(SUBSTITUTE(SUBSTITUTE($E16&""," ",""),"-",""),"+",""),"(",""),")",""),1)="0",PaisCod&MID(SUBSTITUTE(SUBSTITUTE(SUBSTITUTE(SUBSTITUTE(SUBSTITUTE($E16&""," ",""),"-",""),"+",""),"(",""),")",""),2,20),SUBSTITUTE(SUBSTITUTE(SUBSTITUTE(SUBSTITUTE(SUBSTITUTE($E16&""," ",""),"-",""),"+",""),"(",""),")",""))) | Z16: =IF(AND(N($R16)>0,$V16<>"Cancelado"),$R16+ROW()/1000000,"") | AA16: =IF(AND(OR($V16="Pendiente",$V16="Preparando",$V16="Enviado"),N($U16)>0),$U16+ROW()/1000000,"") | AB16: =IF(AND($D16="",$G16=""),"",IF($V16="Cancelado",0,$L16))
B17: =IF(AND($D17="",$G17=""),"",ROW()-7) | F17: =IF($Y17="","",HYPERLINK("https://wa.me/"&$Y17&"?text="&SUBSTITUTE("Hola "&$D17&", te escribo por tu pedido de "&$G17&"."," ","%20"),"Abrir chat")) | L17: =IF(AND($D17="",$G17=""),"",IF(N($H17)=0,1,$H17)*N($I17)-N($J17)+N($K17)) | O17: =IF(OR(AND($D17="",$G17=""),$M17="",$V17="Cancelado"),"",$L17-N($M17)-N($N17)) | R17: =IF(AND($D17="",$G17=""),"",IF($V17="Cancelado",0,MAX(0,$L17-N($Q17)))) | S17: =IF(AND($D17="",$G17=""),"",IF($V17="Cancelado","Cancelado",IF($L17<=0,"",IF(N($Q17)>=$L17,"✔ Pagado",IF(N($Q17)>0,"⚠ Pago parcial","✖ Sin pagar"))))) | W17: =IF(AND($D17="",$G17=""),"",IF($C17="","⚠ Falta la fecha del pedido",IF($V17="","⚠ Elegí el estado de entrega",IF($V17="Cancelado","Cancelado",IF($V17="Entregado",IF($R17>0,"⚠ Entregado: falta cobrar","✔ Cerrado"),IF(AND(N($U17)>0,$U17<TODAY()),"✖ Entrega atrasada ("&(TODAY()-$U17)&" d)","En curso")))))) | Y17: =IF($E17&""="","",IF(LEFT(SUBSTITUTE(SUBSTITUTE(SUBSTITUTE(SUBSTITUTE(SUBSTITUTE($E17&""," ",""),"-",""),"+",""),"(",""),")",""),1)="0",PaisCod&MID(SUBSTITUTE(SUBSTITUTE(SUBSTITUTE(SUBSTITUTE(SUBSTITUTE($E17&""," ",""),"-",""),"+",""),"(",""),")",""),2,20),SUBSTITUTE(SUBSTITUTE(SUBSTITUTE(SUBSTITUTE(SUBSTITUTE($E17&""," ",""),"-",""),"+",""),"(",""),")",""))) | Z17: =IF(AND(N($R17)>0,$V17<>"Cancelado"),$R17+ROW()/1000000,"") | AA17: =IF(AND(OR($V17="Pendiente",$V17="Preparando",$V17="Enviado"),N($U17)>0),$U17+ROW()/1000000,"") | AB17: =IF(AND($D17="",$G17=""),"",IF($V17="Cancelado",0,$L17))
B18: =IF(AND($D18="",$G18=""),"",ROW()-7) | F18: =IF($Y18="","",HYPERLINK("https://wa.me/"&$Y18&"?text="&SUBSTITUTE("Hola "&$D18&", te escribo por tu pedido de "&$G18&"."," ","%20"),"Abrir chat")) | L18: =IF(AND($D18="",$G18=""),"",IF(N($H18)=0,1,$H18)*N($I18)-N($J18)+N($K18)) | O18: =IF(OR(AND($D18="",$G18=""),$M18="",$V18="Cancelado"),"",$L18-N($M18)-N($N18)) | R18: =IF(AND($D18="",$G18=""),"",IF($V18="Cancelado",0,MAX(0,$L18-N($Q18)))) | S18: =IF(AND($D18="",$G18=""),"",IF($V18="Cancelado","Cancelado",IF($L18<=0,"",IF(N($Q18)>=$L18,"✔ Pagado",IF(N($Q18)>0,"⚠ Pago parcial","✖ Sin pagar"))))) | W18: =IF(AND($D18="",$G18=""),"",IF($C18="","⚠ Falta la fecha del pedido",IF($V18="","⚠ Elegí el estado de entrega",IF($V18="Cancelado","Cancelado",IF($V18="Entregado",IF($R18>0,"⚠ Entregado: falta cobrar","✔ Cerrado"),IF(AND(N($U18)>0,$U18<TODAY()),"✖ Entrega atrasada ("&(TODAY()-$U18)&" d)","En curso")))))) | Y18: =IF($E18&""="","",IF(LEFT(SUBSTITUTE(SUBSTITUTE(SUBSTITUTE(SUBSTITUTE(SUBSTITUTE($E18&""," ",""),"-",""),"+",""),"(",""),")",""),1)="0",PaisCod&MID(SUBSTITUTE(SUBSTITUTE(SUBSTITUTE(SUBSTITUTE(SUBSTITUTE($E18&""," ",""),"-",""),"+",""),"(",""),")",""),2,20),SUBSTITUTE(SUBSTITUTE(SUBSTITUTE(SUBSTITUTE(SUBSTITUTE($E18&""," ",""),"-",""),"+",""),"(",""),")",""))) | Z18: =IF(AND(N($R18)>0,$V18<>"Cancelado"),$R18+ROW()/1000000,"") | AA18: =IF(AND(OR($V18="Pendiente",$V18="Preparando",$V18="Enviado"),N($U18)>0),$U18+ROW()/1000000,"") | AB18: =IF(AND($D18="",$G18=""),"",IF($V18="Cancelado",0,$L18))
B19: =IF(AND($D19="",$G19=""),"",ROW()-7) | F19: =IF($Y19="","",HYPERLINK("https://wa.me/"&$Y19&"?text="&SUBSTITUTE("Hola "&$D19&", te escribo por tu pedido de "&$G19&"."," ","%20"),"Abrir chat")) | L19: =IF(AND($D19="",$G19=""),"",IF(N($H19)=0,1,$H19)*N($I19)-N($J19)+N($K19)) | O19: =IF(OR(AND($D19="",$G19=""),$M19="",$V19="Cancelado"),"",$L19-N($M19)-N($N19)) | R19: =IF(AND($D19="",$G19=""),"",IF($V19="Cancelado",0,MAX(0,$L19-N($Q19)))) | S19: =IF(AND($D19="",$G19=""),"",IF($V19="Cancelado","Cancelado",IF($L19<=0,"",IF(N($Q19)>=$L19,"✔ Pagado",IF(N($Q19)>0,"⚠ Pago parcial","✖ Sin pagar"))))) | W19: =IF(AND($D19="",$G19=""),"",IF($C19="","⚠ Falta la fecha del pedido",IF($V19="","⚠ Elegí el estado de entrega",IF($V19="Cancelado","Cancelado",IF($V19="Entregado",IF($R19>0,"⚠ Entregado: falta cobrar","✔ Cerrado"),IF(AND(N($U19)>0,$U19<TODAY()),"✖ Entrega atrasada ("&(TODAY()-$U19)&" d)","En curso")))))) | Y19: =IF($E19&""="","",IF(LEFT(SUBSTITUTE(SUBSTITUTE(SUBSTITUTE(SUBSTITUTE(SUBSTITUTE($E19&""," ",""),"-",""),"+",""),"(",""),")",""),1)="0",PaisCod&MID(SUBSTITUTE(SUBSTITUTE(SUBSTITUTE(SUBSTITUTE(SUBSTITUTE($E19&""," ",""),"-",""),"+",""),"(",""),")",""),2,20),SUBSTITUTE(SUBSTITUTE(SUBSTITUTE(SUBSTITUTE(SUBSTITUTE($E19&""," ",""),"-",""),"+",""),"(",""),")",""))) | Z19: =IF(AND(N($R19)>0,$V19<>"Cancelado"),$R19+ROW()/1000000,"") | AA19: =IF(AND(OR($V19="Pendiente",$V19="Preparando",$V19="Enviado"),N($U19)>0),$U19+ROW()/1000000,"") | AB19: =IF(AND($D19="",$G19=""),"",IF($V19="Cancelado",0,$L19))
... B207: =IF(AND($D207="",$G207=""),"",ROW()-7) | F207: =IF($Y207="","",HYPERLINK("https://wa.me/"&$Y207&"?text="&SUBSTITUTE("Hola "&$D207&", te escribo por tu pedido de "&$G207&"."," ","%20"),"Abrir chat")) | L207: =IF(AND($D207="",$G207=""),"",IF(N($H207)=0,1,$H207)*N($I207)-N($J207)+N($K207)) | O207: =IF(OR(AND($D207="",$G207=""),$M207="",$V207="Cancelado"),"",$L207-N($M207)-N($N207)) | R207: =IF(AND($D207="",$G207=""),"",IF($V207="Cancelado",0,MAX(0,$L207-N($Q207)))) | S207: =IF(AND($D207="",$G207=""),"",IF($V207="Cancelado","Cancelado",IF($L207<=0,"",IF(N($Q207)>=$L207,"✔ Pagado",IF(N($Q207)>0,"⚠ Pago parcial","✖ Sin pagar"))))) | W207: =IF(AND($D207="",$G207=""),"",IF($C207="","⚠ Falta la fecha del pedido",IF($V207="","⚠ Elegí el estado de entrega",IF($V207="Cancelado","Cancelado",IF($V207="Entregado",IF($R207>0,"⚠ Entregado: falta cobrar","✔ Cerrado"),IF(AND(N($U207)>0,$U207<TODAY()),"✖ Entrega atrasada ("&(TODAY()-$U207)&" d)","En curso")))))) | Y207: =IF($E207&""="","",IF(LEFT(SUBSTITUTE(SUBSTITUTE(SUBSTITUTE(SUBSTITUTE(SUBSTITUTE($E207&""," ",""),"-",""),"+",""),"(",""),")",""),1)="0",PaisCod&MID(SUBSTITUTE(SUBSTITUTE(SUBSTITUTE(SUBSTITUTE(SUBSTITUTE($E207&""," ",""),"-",""),"+",""),"(",""),")",""),2,20),SUBSTITUTE(SUBSTITUTE(SUBSTITUTE(SUBSTITUTE(SUBSTITUTE($E207&""," ",""),"-",""),"+",""),"(",""),")",""))) | Z207: =IF(AND(N($R207)>0,$V207<>"Cancelado"),$R207+ROW()/1000000,"") | AA207: =IF(AND(OR($V207="Pendiente",$V207="Preparando",$V207="Enviado"),N($U207)>0),$U207+ROW()/1000000,"") | AB207: =IF(AND($D207="",$G207=""),"",IF($V207="Cancelado",0,$L207))
B210: MIX SHOP DIGITAL · Herramientas inteligentes que simplifican tu vida.
B211: Versión gratuita · Más herramientas gratuitas para tu vida diaria → mixshopdigital.com.py

Sheet AJUSTES
C1: AJUSTES
B2: Herramientas inteligentes que simplifican tu vida. | C2: Cargalos una sola vez
B4: ← VOLVER | C4: Completá solamente las celdas amarillas. Estos datos alimentan las demás hojas automáticamente.
B6: 1. TU NEGOCIO
B7: Nombre del negocio | C7: Mi negocio | D7: Aparece en el PANEL.
B8: Año a controlar | C8: 2026 | D8: El PANEL muestra los pedidos de este año.
B9: Moneda | C9: Gs. | D9: Símbolo que se muestra en las hojas.
B10: Código de país para WhatsApp | C10: 595 | D10: Se usa para armar el enlace «Abrir chat». Paraguay: 595. Escribí el teléfono del cliente tal cual (ej.: 0981 123 456).
B12: 2. LISTAS DESPLEGABLES (podés renombrarlas)
B13: Formas de pago | C13: Formas de entrega | D13: Cambiá el nombre si querés, pero no dejes huecos entre medio.
B14: Efectivo | C14: Delivery propio | D14: Hasta 6 formas de pago y 5 formas de entrega.
B15: Transferencia | C15: Moto delivery | D15: Los estados de entrega (Pendiente, Preparando, Enviado, Entregado, Cancelado) son fijos.
B16: Tarjeta | C16: Encomienda / flete
B17: Billetera móvil | C17: Retiro en el local
B18: Otro | C18: Otro
B23: MIX SHOP DIGITAL · Herramientas inteligentes que simplifican tu vida.
B24: Versión gratuita · Más herramientas gratuitas para tu vida diaria → mixshopdigital.com.py

Sheet AYUDA
D1: AYUDA
B2: Herramientas inteligentes que simplifican tu vida. | D2: Se aprende en 2 minutos
B4: ← VOLVER | C4: Leé esta hoja una vez. Después ya no la vas a necesitar.
B6: ¿PARA QUÉ SIRVE?
B7: Para anotar cada pedido que te llega (por WhatsApp, redes o en persona), saber cuánto te pagaron, cuánto te deben, qué tenés que entregar y cuándo, y cuánto ganás. Sin fórmulas y sin Internet.
B9: EMPEZÁ EN 3 PASOS
B10: 1) En AJUSTES poné el nombre de tu negocio, el año y, si querés, cambiá las formas de pago y de entrega.
B11: 2) En PEDIDOS escribí una fila por pedido: fecha, cliente, teléfono, producto, cantidad, precio y estado de entrega. Más adelante completá lo que te pagaron y, si querés conocer tu ganancia, los costos.
B12: 3) Mirá el PANEL: tus ventas, lo que te deben, las entregas atrasadas y quién te tiene que pagar.
B14: COLORES Y AVISOS
B15: Amarillo claro: celdas que completás vos. Gris o blanco: se calcula solo (bloqueado).
B16: AVISO: «✔ Cerrado» = entregado y pagado. «En curso» = todavía falta entregar. «⚠ Entregado: falta cobrar» = hay saldo. «✖ Entrega atrasada» = pasó la fecha prometida y no está entregado.
B18: PREGUNTAS FRECUENTES
B19: • Veo todo en cero: hacé clic en «Habilitar edición» en la barra amarilla de Excel.
B20: • ¿Para qué sirve «Chat»? Si escribís el teléfono del cliente (ej.: 0981 123 456), aparece «Abrir chat»: un clic y se abre WhatsApp con un saludo ya escrito.
... B38: Versión gratuita · Más herramientas gratuitas para tu vida diaria → mixshopdigital.com.py
