Workbook
Name NombreNegocio: 'CONFIGURACIÓN'!$C$7
Name Responsable: 'CONFIGURACIÓN'!$C$8
Name Moneda: 'CONFIGURACIÓN'!$C$9
Name Comision: 'CONFIGURACIÓN'!$C$11
Name Impuesto: 'CONFIGURACIÓN'!$C$12
Name EnvioHab: 'CONFIGURACIÓN'!$C$13
Name EmpaqueHab: 'CONFIGURACIÓN'!$C$14
Name OtrosHab: 'CONFIGURACIÓN'!$C$15
Name MargenObj: 'CONFIGURACIÓN'!$C$16
Name MargenMin: 'CONFIGURACIÓN'!$C$17
Name Redondeo: 'CONFIGURACIÓN'!$C$19
Name DescHab: 'CONFIGURACIÓN'!$C$20
Name MetaGan: 'CONFIGURACIÓN'!$C$21
Name Metodo: 'CONFIGURACIÓN'!$C$18
Name DivBase: 'CONFIGURACIÓN'!$C$24
Name DivMargen: 'CONFIGURACIÓN'!$C$25
Name DivPromo: 'CONFIGURACIÓN'!$C$26
Name MargenObjReal: 'CONFIGURACIÓN'!$C$27
Name Categorias: 'CONFIGURACIÓN'!$B$31:$B$42
Name ListaCats: 'CONFIGURACIÓN'!$G$30:$G$42
Name CostoFijoUnit: 'COSTOS Y GASTOS'!$H$6
Name CatSel: 'DASHBOARD'!$D$6

Sheet INICIO
B1: MIX SHOP DIGITAL | F1: INICIO
B2: Herramientas inteligentes que simplifican tu vida. | F2: Calculadora gratuita
C4: Hacé clic en cualquier botón del menú para ir directo a esa hoja.
B6: CALCULADORA INTELIGENTE DE PRECIOS Y GANANCIAS
B7: VERSIÓN GRATUITA · Hecha para emprendedores y pequeños negocios de Paraguay
B8: Descubrí cuánto te cuesta realmente vender y cuánto ganás por cada producto.
B10: Precio justo | E10: Hasta 200 productos | H10: Promociones y escenarios | K10: Panel de control
B11: Calculá el precio mínimo y el recomendado sin perder dinero. | E11: Compará costos, precios y márgenes con alertas automáticas. | H11: Simulá descuentos, 2x1 y combos antes de aplicarlos. | K11: Indicadores y gráficos que te ayudan a decidir.
B13: MENÚ
B14: CONFIGURACIÓN | E14: CALCULADORA | H14: COMPARADOR | K14: COSTOS Y GASTOS
B15: 1. Tus datos y porcentajes | E15: 2. Costo, precio y ganancia | H15: Hasta 200 productos | K15: Los gastos que se olvidan
B17: SIMULADOR | E17: DASHBOARD | H17: GUÍA DE USO | K17: MI NEGOCIO PY
B18: Escenarios y promociones | E18: Indicadores y gráficos | H18: Cómo usar la herramienta | K18: Todo tu negocio, en un solo lugar
B21: EMPEZÁ EN 3 PASOS
B22: 1. Configurá tu negocio | F22: 2. Cargá un producto | J22: 3. Mirá tus resultados
B23: Cargá tu comisión, impuestos y el margen que querés ganar. | F23: En la CALCULADORA, ingresá lo que pagaste y tus costos. | J23: Precio recomendado, ganancia y alertas, al instante.
B25: Completá solamente las celdas resaltadas. Las fórmulas, gráficos y títulos están protegidos para que no se borren por accidente.
B26: Azul claro: completás vos | D26: Gris: automático | F26: Naranja: advertencia | H26: Verde: favorable | J26: Rojo: pérdida
B28: ¿Ves todo en blanco? Hacé clic en «Habilitar edición» en la barra amarilla de Excel para que se calculen las fórmulas.
B30: Esta es una versión gratuita de Mix Shop Digital. Si querés gestionar todo tu negocio en un solo lugar, conocé Mi Negocio PY: el sistema de gestión para pequeños negocios de Paraguay.
B31: → mixshopdigital.com.py
B34: MIX SHOP DIGITAL · Herramientas inteligentes que simplifican tu vida.
B35: Versión gratuita · Para gestionar todo tu negocio en un solo lugar, conocé Mi Negocio PY → mixshopdigital.com.py

Sheet CONFIGURACIÓN
B1: MIX SHOP DIGITAL | C1: CONFIGURACIÓN
B2: Herramientas inteligentes que simplifican tu vida. | C2: Datos de tu negocio y reglas de cálculo
B4: ← INICIO | C4: Completá solamente las celdas resaltadas. Todo lo que cargues acá alimenta automáticamente las demás hojas.
B6: 1. DATOS DE TU NEGOCIO
B7: Nombre del negocio | C7: Tienda de María (EJEMPLO) | D7: Aparece en los reportes impresos.
B8: Nombre del responsable | C8: María | D8: Persona que usa la calculadora (opcional).
B9: Moneda utilizada | C9: Gs. | D9: Símbolo que se muestra en los títulos. Para guaraníes dejá «Gs.».
B10: 2. COSTOS Y PORCENTAJES HABITUALES
B11: Comisión por ventas (%) | C11: 0.03 | D11: Porcentaje del precio de venta que se lleva la plataforma o el medio de pago (tarjeta, pasarela, marketplace). Ajustalo a tu realidad.
B12: Impuestos o retenciones sobre ventas (%) | C12: 0 | D12: Se calcula sobre el precio de venta. Está en 0 % a propósito: cada negocio tiene una situación distinta. Consultá con tu contador y cargá el porcentaje que corresponda.
B13: Costo de envío habitual (por unidad) | C13: 0 | D13: Se usa en la CALCULADORA cuando dejás vacío el campo de envío al cliente.
B14: Costo de empaque habitual (por unidad) | C14: 1000 | D14: Bolsa, caja, cinta, etc. Se usa en la CALCULADORA si dejás vacío el campo de empaque.
B15: Otros gastos habituales (por unidad) | C15: 0 | D15: Cualquier gasto variable que repetís en casi todos tus productos.
B16: Margen de ganancia objetivo (%) | C16: 0.3 | D16: Cuánto querés ganar. Se interpreta según el método de cálculo elegido más abajo.
B17: Margen mínimo aceptable (%) | C17: 0.1 | D17: Por debajo de este margen real la planilla te muestra una advertencia.
B18: Método de cálculo preferido | C18: Margen sobre venta | D18: «Margen sobre venta»: el margen es un % del precio final (lo más usado y lo más seguro). «Recargo sobre costo»: el % se suma al costo (markup).
B19: Redondear precios a múltiplos de | C19: 500 | D19: Ej.: 500 redondea hacia arriba a los 500 Gs. más cercanos (precios más prolijos). Poné 0 para no redondear.
B20: Descuento habitual que podrías ofrecer (%) | C20: 0.1 | D20: Se usa en la CALCULADORA si no indicás un descuento para el producto.
B21: Meta de ganancia a alcanzar | C21: 3000000 | D21: Ganancia neta que querés lograr. La CALCULADORA te dice cuántas unidades tenés que vender.
B23: 3. VALORES CALCULADOS (automáticos, no se modifican)
B24: Divisor base (1 − comisión − impuestos) | C24: =1-Comision-Impuesto | D24: Parte del precio que te queda después de comisiones e impuestos.
B25: Divisor para el precio objetivo | C25: =IF(Metodo="Margen sobre venta",1-Comision-Impuesto-MargenObj,(1-Comision-Impuesto)/(1+MargenObj)) | D25: Precio recomendado = costo ÷ este divisor.
B26: Divisor para el precio promocional (mitad del margen) | C26: =IF(Metodo="Margen sobre venta",1-Comision-Impuesto-MargenObj/2,(1-Comision-Impuesto)/(1+MargenObj/2)) | D26: Precio promocional = costo ÷ este divisor.
B27: Margen real objetivo equivalente | C27: =IF(Metodo="Margen sobre venta",MargenObj,MargenObj/(1+MargenObj)) | D27: Si elegiste recargo sobre costo, es el margen sobre venta que equivale a tu recargo.
B28: Verificación de la configuración | C28: =IF(DivMargen<=0,"⚠ Revisá: comisión + impuestos + margen superan el 100 %","✔ Configuración válida")
B30: 4. TUS CATEGORÍAS DE PRODUCTOS (podés renombrarlas) | G30: Todas
B31: Ropa y accesorios | C31: ← categoría editable | G31: =IF(B31="","",B31)
B32: Alimentos y bebidas | G32: =IF(B32="","",B32)
B33: Electrónica y celulares | G33: =IF(B33="","",B33)
B34: Hogar y decoración | G34: =IF(B34="","",B34)
B35: Belleza y cuidado personal | G35: =IF(B35="","",B35)
B36: Herramientas y ferretería | G36: =IF(B36="","",B36)
B37: Papelería y librería | G37: =IF(B37="","",B37)
B38: Servicios | G38: =IF(B38="","",B38)
B39: Mascotas | G39: =IF(B39="","",B39)
B40: Otros | G40: =IF(B40="","",B40)
G41: =IF(B41="","",B41)
G42: =IF(B42="","",B42)
B44: Importante: los impuestos y retenciones dependen de la situación particular de cada negocio. Esta herramienta no reemplaza el asesoramiento de un contador.
B47: MIX SHOP DIGITAL · Herramientas inteligentes que simplifican tu vida.
...

Sheet CALCULADORA
B1: MIX SHOP DIGITAL | F1: CALCULADORA
B2: Herramientas inteligentes que simplifican tu vida. | F2: Costo real, precio recomendado y ganancia
B4: ← INICIO | C4: Completá solamente las celdas resaltadas. Si dejás un campo en blanco, se usa el valor de CONFIGURACIÓN.
B5: PRECIO RECOMENDADO | D5: GANANCIA NETA POR UNIDAD | G5: MARGEN REAL SOBRE LA VENTA | H5: PRECIO MÍNIMO (SIN PÉRDIDA)
B6: =H14 | D6: =H16 | G6: =H17 | H6: =H12
B7: ="por unidad · "&Moneda | D7: ="por unidad · "&Moneda | G7: ganancia ÷ precio de venta | H7: ="por debajo perdés · "&Moneda
B9: 1. DATOS DEL PRODUCTO Y SUS COSTOS | G9: 3. RESULTADOS AUTOMÁTICOS
B10: Concepto | C10: Monto que ingresás | D10: Se aplica a | E10: Costo por unidad | G10: Resultado | H10: Valor | I10: Estado / cómo leerlo
B11: Nombre del producto | C11: Remera básica de algodón (EJEMPLO) | G11: Costo total unitario | H11: =E24 | I11: Todo lo que te cuesta cada unidad.
B12: Código o SKU | C12: RB-001 | G12: Precio mínimo para no perder dinero | H12: =IF(OR(E24<=0,H29<=0),0,E24/H29) | I12: Por debajo de este precio perdés plata.
B13: Categoría | C13: Ropa y accesorios | G13: Precio con margen objetivo (exacto) | H13: =IF(OR(E24<=0,H30<=0),0,E24/H30) | I13: Resuelto matemáticamente, sin sumar % al costo.
B14: Proveedor | C14: Proveedor Ejemplo S.A. | G14: PRECIO RECOMENDADO | H14: =IF(H13=0,0,IF(Redondeo>0,CEILING(H13,Redondeo),H13)) | I14: Precio sugerido (redondeado hacia arriba).
B15: Cantidad adquirida (unidades) | C15: 50 | D15: unidades | G15: Ganancia bruta por unidad | H15: =H14-E24 | I15: Precio − costo, antes de comisiones e impuestos.
B16: Costo total de compra (lote) | C16: 1250000 | D16: Lote completo | E16: =IF(C16="",0,C16/IF(N(C15)>0,C15,1)) | G16: Ganancia neta estimada por unidad | H16: =H14*H29-E24 | I16: =IF(H14=0,"",IF(H16<0,"✖ Pérdida por unidad","✔ Ganancia por unidad"))
B17: Transporte o importación | C17: 100000 | D17: Lote completo | E17: =IF(C17="",0,IF(D17="Lote completo",C17/IF(N($C$15)>0,$C$15,1),C17)) | G17: Margen real sobre el precio de venta | H17: =IF(H14=0,0,H16/H14) | I17: =IF(H14=0,"",IF(H17<0,"✖ Pérdida",IF(H17<MargenMin,"⚠ Margen insuficiente","✔ Margen saludable")))
B18: Envío al cliente | C18: 15000 | D18: Por unidad | E18: =IF(C18="",EnvioHab,IF(D18="Lote completo",C18/IF(N($C$15)>0,$C$15,1),C18)) | G18: Rentabilidad sobre el costo (recargo) | H18: =IF(E24=0,0,H16/E24) | I18: Ganancia neta ÷ costo. No es lo mismo que el margen.
B19: Empaque | C19: 1500 | D19: Por unidad | E19: =IF(C19="",EmpaqueHab,IF(D19="Lote completo",C19/IF(N($C$15)>0,$C$15,1),C19)) | G19: Ganancia total estimada del lote | H19: =H16*E34 | I19: ="Con "&FIXED(E34,0)&" unidades disponibles"
B20: Etiquetas y presentación | C20: 60000 | D20: Lote completo | E20: =IF(C20="",0,IF(D20="Lote completo",C20/IF(N($C$15)>0,$C$15,1),C20)) | G20: Precio promocional posible | H20: =IF(OR(E24<=0,H31<=0),0,IF(Redondeo>0,CEILING(E24/H31,Redondeo),E24/H31)) | I20: Conserva la mitad de tu margen objetivo.
B21: Otros costos variables | D21: Por unidad | E21: =IF(C21="",OtrosHab,IF(D21="Lote completo",C21/IF(N($C$15)>0,$C$15,1),C21)) | G21: Precio después del descuento | H21: =H14*(1-E32) | I21: ="Descuento aplicado: "&ROUND(E32*100,1)&" %"
B22: Otros costos asignables | D22: Por unidad | E22: =IF(C22="",0,IF(D22="Lote completo",C22/IF(N($C$15)>0,$C$15,1),C22)) | G22: Ganancia neta después del descuento | H22: =H21*H29-E24 | I22: =IF(H21=0,"",IF(H22<0,"✖ Con este descuento perdés",IF(H22/H21<MargenMin,"⚠ Margen bajo con descuento","✔ Sigue siendo rentable")))
B23: Incluir costos fijos (por unidad) | C23: No | D23: ¿incluir? | E23: =IF(C23="Sí",CostoFijoUnit,0) | G23: Unidades para alcanzar tu meta | H23: =IF(OR(H14=0,H16<=0),"N/D",ROUNDUP(E35/H16,0)) | I23: ="Meta: "&FIXED(E35,0)&" "&Moneda
B24: COSTO TOTAL UNITARIO | E24: =IF(N(C16)<=0,0,SUM(E16:E23)) | G24: Ganancia neta con tu precio actual | H24: =IF(E33<=0,0,E33*H29-E24) | I24: =IF(E33<=0,"Cargá tu precio actual",IF(H24<0,"✖ Vendés por debajo del costo","✔ Ganancia con precio actual"))
B25: Chequeo | C25: =IF(AND(N(C16)>0,N(C15)<=0),"⚠ Indicá la cantidad adquirida",IF(E24=0,"Cargá el costo de compra para ver resultados","✔ Datos completos")) | G25: Margen real con tu precio actual | H25: =IF(E33<=0,0,H24/E33) | I25: =IF(E33<=0,"",IF(H25<0,"✖ Pérdida",IF(H25<MargenMin,"⚠ Margen insuficiente","✔ Precio actual rentable")))
B27: 2. PARÁMETROS COMERCIALES | G27: Detalle técnico del cálculo
B28: Concepto | C28: Tu dato (opcional) | D28: Si lo dejás vacío | E28: Valor que se usa | G28: ="Método activo: "&Metodo
B29: Margen de ganancia deseado (%) | D29: usa CONFIGURACIÓN | E29: =IF(C29="",MargenObj,C29) | G29: Divisor base = 1 − comisión − impuestos | H29: =1-E30-E31 | I29: =IF(MIN(H29:H31)<=0,"⚠ Revisá comisión, impuestos y margen: suman 100 % o más","")
B30: Comisión de plataforma / medio de pago (%) | D30: usa CONFIGURACIÓN | E30: =IF(C30="",Comision,C30) | G30: Divisor del precio objetivo | H30: =IF(Metodo="Margen sobre venta",H29-E29,H29/(1+E29))
B31: Impuestos o retenciones sobre ventas (%) | D31: usa CONFIGURACIÓN | E31: =IF(C31="",Impuesto,C31) | G31: Divisor del precio promocional | H31: =IF(Metodo="Margen sobre venta",H29-E29/2,H29/(1+E29/2))
B32: Descuento que podrías ofrecer (%) | D32: usa CONFIGURACIÓN | E32: =IF(C32="",DescHab,C32)
B33: Precio de venta actual | C33: 60000 | D33: sin precio actual | E33: =IF(C33="",0,C33) | G33: Fórmulas: Precio = Costo ÷ Divisor. Ganancia neta = Precio × divisor base − Costo.
B34: Unidades disponibles | C34: 50 | D34: usa la cantidad adquirida | E34: =IF(C34="",N(C15),C34)
B35: Meta de ganancia neta a alcanzar | D35: usa CONFIGURACIÓN | E35: =IF(C35="",MetaGan,C35) | G35: Colores:
G36: Azul claro: completás vos | H36: Gris: automático | I36: Naranja: advertencia · Rojo: pérdida · Verde: favorable
B39: MIX SHOP DIGITAL · Herramientas inteligentes que simplifican tu vida.
B40: Versión gratuita · Para gestionar todo tu negocio en un solo lugar, conocé Mi Negocio PY → mixshopdigital.com.py

Sheet COMPARADOR DE PRODUCTOS
B1: MIX SHOP DIGITAL | E1: COMPARADOR DE PRODUCTOS
B2: Herramientas inteligentes que simplifican tu vida. | E2: Hasta 200 productos · rentabilidad automática
B4: ← INICIO | C4: Completá solamente las celdas resaltadas. En «Costo unitario» poné el costo TOTAL por unidad (compra + envío + empaque + otros).
B5: ="Estado de la tabla: "&SUMPRODUCT((C7:C206<>"")*(E7:E206>0))&" productos cargados · Alertas: "&COUNTIF(L7:L206,"PÉRDIDA")&" con pérdida y "&COUNTIF(L7:L206,"Margen bajo")&" con margen bajo"
B6: Código | C6: Producto | D6: Categoría | E6: Costo unitario | F6: Precio actual | G6: Precio recomendado | H6: Ganancia por unidad | I6: Margen % | J6: Stock disponible | K6: Valor del stock (a costo) | L6: Estado de rentabilidad | M6: Observaciones | N6: Ranking
B7: RB-001 | C7: Remera básica de algodón | D7: Ropa y accesorios | E7: 28500 | F7: 60000 | G7: =IF(OR(C7="",E7<=0,DivMargen<=0),0,IF(Redondeo>0,CEILING(E7/DivMargen,Redondeo),E7/DivMargen)) | H7: =IF(OR(C7="",E7<=0,F7<=0),0,F7*DivBase-E7) | I7: =IF(OR(C7="",E7<=0,F7<=0),0,H7/F7) | J7: 50 | K7: =IF(OR(C7="",E7<=0),0,E7*J7) | L7: =IF(OR(C7="",E7<=0),"",IF(F7<=0,"Sin precio",IF(H7<0,"PÉRDIDA",IF(I7<MargenMin,"Margen bajo",IF(I7<MargenObjReal,"Aceptable","Rentable"))))) | N7: =IF(ISNUMBER(W7),RANK(W7,$W$7:$W$206),"") | W7: =IF(AND(C7<>"",E7>0,F7>0),H7+ROW()/1000000000,"") | X7: =IF(AND(C7<>"",E7>0,F7>0,OR(CatSel="Todas",D7=CatSel)),H7+ROW()/1000000000,"")
B8: RB-002 | C8: Remera estampada | D8: Ropa y accesorios | E8: 32000 | F8: 55000 | G8: =IF(OR(C8="",E8<=0,DivMargen<=0),0,IF(Redondeo>0,CEILING(E8/DivMargen,Redondeo),E8/DivMargen)) | H8: =IF(OR(C8="",E8<=0,F8<=0),0,F8*DivBase-E8) | I8: =IF(OR(C8="",E8<=0,F8<=0),0,H8/F8) | J8: 30 | K8: =IF(OR(C8="",E8<=0),0,E8*J8) | L8: =IF(OR(C8="",E8<=0),"",IF(F8<=0,"Sin precio",IF(H8<0,"PÉRDIDA",IF(I8<MargenMin,"Margen bajo",IF(I8<MargenObjReal,"Aceptable","Rentable"))))) | N8: =IF(ISNUMBER(W8),RANK(W8,$W$7:$W$206),"") | W8: =IF(AND(C8<>"",E8>0,F8>0),H8+ROW()/1000000000,"") | X8: =IF(AND(C8<>"",E8>0,F8>0,OR(CatSel="Todas",D8=CatSel)),H8+ROW()/1000000000,"")
B9: JN-010 | C9: Jean clásico | D9: Ropa y accesorios | E9: 95000 | F9: 160000 | G9: =IF(OR(C9="",E9<=0,DivMargen<=0),0,IF(Redondeo>0,CEILING(E9/DivMargen,Redondeo),E9/DivMargen)) | H9: =IF(OR(C9="",E9<=0,F9<=0),0,F9*DivBase-E9) | I9: =IF(OR(C9="",E9<=0,F9<=0),0,H9/F9) | J9: 20 | K9: =IF(OR(C9="",E9<=0),0,E9*J9) | L9: =IF(OR(C9="",E9<=0),"",IF(F9<=0,"Sin precio",IF(H9<0,"PÉRDIDA",IF(I9<MargenMin,"Margen bajo",IF(I9<MargenObjReal,"Aceptable","Rentable"))))) | N9: =IF(ISNUMBER(W9),RANK(W9,$W$7:$W$206),"") | W9: =IF(AND(C9<>"",E9>0,F9>0),H9+ROW()/1000000000,"") | X9: =IF(AND(C9<>"",E9>0,F9>0,OR(CatSel="Todas",D9=CatSel)),H9+ROW()/1000000000,"")
B10: GR-001 | C10: Gorra deportiva | D10: Ropa y accesorios | E10: 18000 | F10: 25000 | G10: =IF(OR(C10="",E10<=0,DivMargen<=0),0,IF(Redondeo>0,CEILING(E10/DivMargen,Redondeo),E10/DivMargen)) | H10: =IF(OR(C10="",E10<=0,F10<=0),0,F10*DivBase-E10) | I10: =IF(OR(C10="",E10<=0,F10<=0),0,H10/F10) | J10: 40 | K10: =IF(OR(C10="",E10<=0),0,E10*J10) | L10: =IF(OR(C10="",E10<=0),"",IF(F10<=0,"Sin precio",IF(H10<0,"PÉRDIDA",IF(I10<MargenMin,"Margen bajo",IF(I10<MargenObjReal,"Aceptable","Rentable"))))) | N10: =IF(ISNUMBER(W10),RANK(W10,$W$7:$W$206),"") | W10: =IF(AND(C10<>"",E10>0,F10>0),H10+ROW()/1000000000,"") | X10: =IF(AND(C10<>"",E10>0,F10>0,OR(CatSel="Todas",D10=CatSel)),H10+ROW()/1000000000,"")
B11: CE-100 | C11: Funda para celular | D11: Electrónica y celulares | E11: 6500 | F11: 20000 | G11: =IF(OR(C11="",E11<=0,DivMargen<=0),0,IF(Redondeo>0,CEILING(E11/DivMargen,Redondeo),E11/DivMargen)) | H11: =IF(OR(C11="",E11<=0,F11<=0),0,F11*DivBase-E11) | I11: =IF(OR(C11="",E11<=0,F11<=0),0,H11/F11) | J11: 120 | K11: =IF(OR(C11="",E11<=0),0,E11*J11) | L11: =IF(OR(C11="",E11<=0),"",IF(F11<=0,"Sin precio",IF(H11<0,"PÉRDIDA",IF(I11<MargenMin,"Margen bajo",IF(I11<MargenObjReal,"Aceptable","Rentable"))))) | N11: =IF(ISNUMBER(W11),RANK(W11,$W$7:$W$206),"") | W11: =IF(AND(C11<>"",E11>0,F11>0),H11+ROW()/1000000000,"") | X11: =IF(AND(C11<>"",E11>0,F11>0,OR(CatSel="Todas",D11=CatSel)),H11+ROW()/1000000000,"")
B12: CE-101 | C12: Cargador rápido 20W | D12: Electrónica y celulares | E12: 38000 | F12: 65000 | G12: =IF(OR(C12="",E12<=0,DivMargen<=0),0,IF(Redondeo>0,CEILING(E12/DivMargen,Redondeo),E12/DivMargen)) | H12: =IF(OR(C12="",E12<=0,F12<=0),0,F12*DivBase-E12) | I12: =IF(OR(C12="",E12<=0,F12<=0),0,H12/F12) | J12: 45 | K12: =IF(OR(C12="",E12<=0),0,E12*J12) | L12: =IF(OR(C12="",E12<=0),"",IF(F12<=0,"Sin precio",IF(H12<0,"PÉRDIDA",IF(I12<MargenMin,"Margen bajo",IF(I12<MargenObjReal,"Aceptable","Rentable"))))) | N12: =IF(ISNUMBER(W12),RANK(W12,$W$7:$W$206),"") | W12: =IF(AND(C12<>"",E12>0,F12>0),H12+ROW()/1000000000,"") | X12: =IF(AND(C12<>"",E12>0,F12>0,OR(CatSel="Todas",D12=CatSel)),H12+ROW()/1000000000,"")
B13: CE-102 | C13: Auriculares inalámbricos | D13: Electrónica y celulares | E13: 85000 | F13: 110000 | G13: =IF(OR(C13="",E13<=0,DivMargen<=0),0,IF(Redondeo>0,CEILING(E13/DivMargen,Redondeo),E13/DivMargen)) | H13: =IF(OR(C13="",E13<=0,F13<=0),0,F13*DivBase-E13) | I13: =IF(OR(C13="",E13<=0,F13<=0),0,H13/F13) | J13: 25 | K13: =IF(OR(C13="",E13<=0),0,E13*J13) | L13: =IF(OR(C13="",E13<=0),"",IF(F13<=0,"Sin precio",IF(H13<0,"PÉRDIDA",IF(I13<MargenMin,"Margen bajo",IF(I13<MargenObjReal,"Aceptable","Rentable"))))) | N13: =IF(ISNUMBER(W13),RANK(W13,$W$7:$W$206),"") | W13: =IF(AND(C13<>"",E13>0,F13>0),H13+ROW()/1000000000,"") | X13: =IF(AND(C13<>"",E13>0,F13>0,OR(CatSel="Todas",D13=CatSel)),H13+ROW()/1000000000,"")
B14: CE-103 | C14: Cable USB-C 1 m | D14: Electrónica y celulares | E14: 9000 | F14: 8500 | G14: =IF(OR(C14="",E14<=0,DivMargen<=0),0,IF(Redondeo>0,CEILING(E14/DivMargen,Redondeo),E14/DivMargen)) | H14: =IF(OR(C14="",E14<=0,F14<=0),0,F14*DivBase-E14) | I14: =IF(OR(C14="",E14<=0,F14<=0),0,H14/F14) | J14: 80 | K14: =IF(OR(C14="",E14<=0),0,E14*J14) | L14: =IF(OR(C14="",E14<=0),"",IF(F14<=0,"Sin precio",IF(H14<0,"PÉRDIDA",IF(I14<MargenMin,"Margen bajo",IF(I14<MargenObjReal,"Aceptable","Rentable"))))) | N14: =IF(ISNUMBER(W14),RANK(W14,$W$7:$W$206),"") | W14: =IF(AND(C14<>"",E14>0,F14>0),H14+ROW()/1000000000,"") | X14: =IF(AND(C14<>"",E14>0,F14>0,OR(CatSel="Todas",D14=CatSel)),H14+ROW()/1000000000,"")
B15: CE-104 | C15: Soporte para celular | D15: Electrónica y celulares | E15: 12000 | F15: 30000 | G15: =IF(OR(C15="",E15<=0,DivMargen<=0),0,IF(Redondeo>0,CEILING(E15/DivMargen,Redondeo),E15/DivMargen)) | H15: =IF(OR(C15="",E15<=0,F15<=0),0,F15*DivBase-E15) | I15: =IF(OR(C15="",E15<=0,F15<=0),0,H15/F15) | J15: 60 | K15: =IF(OR(C15="",E15<=0),0,E15*J15) | L15: =IF(OR(C15="",E15<=0),"",IF(F15<=0,"Sin precio",IF(H15<0,"PÉRDIDA",IF(I15<MargenMin,"Margen bajo",IF(I15<MargenObjReal,"Aceptable","Rentable"))))) | N15: =IF(ISNUMBER(W15),RANK(W15,$W$7:$W$206),"") | W15: =IF(AND(C15<>"",E15>0,F15>0),H15+ROW()/1000000000,"") | X15: =IF(AND(C15<>"",E15>0,F15>0,OR(CatSel="Todas",D15=CatSel)),H15+ROW()/1000000000,"")
B16: HG-200 | C16: Set de ollas antiadherentes | D16: Hogar y decoración | E16: 210000 | F16: 340000 | G16: =IF(OR(C16="",E16<=0,DivMargen<=0),0,IF(Redondeo>0,CEILING(E16/DivMargen,Redondeo),E16/DivMargen)) | H16: =IF(OR(C16="",E16<=0,F16<=0),0,F16*DivBase-E16) | I16: =IF(OR(C16="",E16<=0,F16<=0),0,H16/F16) | J16: 8 | K16: =IF(OR(C16="",E16<=0),0,E16*J16) | L16: =IF(OR(C16="",E16<=0),"",IF(F16<=0,"Sin precio",IF(H16<0,"PÉRDIDA",IF(I16<MargenMin,"Margen bajo",IF(I16<MargenObjReal,"Aceptable","Rentable"))))) | N16: =IF(ISNUMBER(W16),RANK(W16,$W$7:$W$206),"") | W16: =IF(AND(C16<>"",E16>0,F16>0),H16+ROW()/1000000000,"") | X16: =IF(AND(C16<>"",E16>0,F16>0,OR(CatSel="Todas",D16=CatSel)),H16+ROW()/1000000000,"")
B17: HG-201 | C17: Almohadón decorativo | D17: Hogar y decoración | E17: 22000 | F17: 45000 | G17: =IF(OR(C17="",E17<=0,DivMargen<=0),0,IF(Redondeo>0,CEILING(E17/DivMargen,Redondeo),E17/DivMargen)) | H17: =IF(OR(C17="",E17<=0,F17<=0),0,F17*DivBase-E17) | I17: =IF(OR(C17="",E17<=0,F17<=0),0,H17/F17) | J17: 35 | K17: =IF(OR(C17="",E17<=0),0,E17*J17) | L17: =IF(OR(C17="",E17<=0),"",IF(F17<=0,"Sin precio",IF(H17<0,"PÉRDIDA",IF(I17<MargenMin,"Margen bajo",IF(I17<MargenObjReal,"Aceptable","Rentable"))))) | N17: =IF(ISNUMBER(W17),RANK(W17,$W$7:$W$206),"") | W17: =IF(AND(C17<>"",E17>0,F17>0),H17+ROW()/1000000000,"") | X17: =IF(AND(C17<>"",E17>0,F17>0,OR(CatSel="Todas",D17=CatSel)),H17+ROW()/1000000000,"")
B18: HG-202 | C18: Lámpara de mesa LED | D18: Hogar y decoración | E18: 48000 | F18: 79000 | G18: =IF(OR(C18="",E18<=0,DivMargen<=0),0,IF(Redondeo>0,CEILING(E18/DivMargen,Redondeo),E18/DivMargen)) | H18: =IF(OR(C18="",E18<=0,F18<=0),0,F18*DivBase-E18) | I18: =IF(OR(C18="",E18<=0,F18<=0),0,H18/F18) | J18: 18 | K18: =IF(OR(C18="",E18<=0),0,E18*J18) | L18: =IF(OR(C18="",E18<=0),"",IF(F18<=0,"Sin precio",IF(H18<0,"PÉRDIDA",IF(I18<MargenMin,"Margen bajo",IF(I18<MargenObjReal,"Aceptable","Rentable"))))) | N18: =IF(ISNUMBER(W18),RANK(W18,$W$7:$W$206),"") | W18: =IF(AND(C18<>"",E18>0,F18>0),H18+ROW()/1000000000,"") | X18: =IF(AND(C18<>"",E18>0,F18>0,OR(CatSel="Todas",D18=CatSel)),H18+ROW()/1000000000,"")
... B36: SV-800 | C36: Diseño de logo (servicio) | D36: Servicios | E36: 120000 | F36: 300000 | G36: =IF(OR(C36="",E36<=0,DivMargen<=0),0,IF(Redondeo>0,CEILING(E36/DivMargen,Redondeo),E36/DivMargen)) | H36: =IF(OR(C36="",E36<=0,F36<=0),0,F36*DivBase-E36) | I36: =IF(OR(C36="",E36<=0,F36<=0),0,H36/F36) | J36: 0 | K36: =IF(OR(C36="",E36<=0),0,E36*J36) | L36: =IF(OR(C36="",E36<=0),"",IF(F36<=0,"Sin precio",IF(H36<0,"PÉRDIDA",IF(I36<MargenMin,"Margen bajo",IF(I36<MargenObjReal,"Aceptable","Rentable"))))) | N36: =IF(ISNUMBER(W36),RANK(W36,$W$7:$W$206),"") | W36: =IF(AND(C36<>"",E36>0,F36>0),H36+ROW()/1000000000,"") | X36: =IF(AND(C36<>"",E36>0,F36>0,OR(CatSel="Todas",D36=CatSel)),H36+ROW()/1000000000,"")
G37: =IF(OR(C37="",E37<=0,DivMargen<=0),0,IF(Redondeo>0,CEILING(E37/DivMargen,Redondeo),E37/DivMargen)) | H37: =IF(OR(C37="",E37<=0,F37<=0),0,F37*DivBase-E37) | I37: =IF(OR(C37="",E37<=0,F37<=0),0,H37/F37) | K37: =IF(OR(C37="",E37<=0),0,E37*J37) | L37: =IF(OR(C37="",E37<=0),"",IF(F37<=0,"Sin precio",IF(H37<0,"PÉRDIDA",IF(I37<MargenMin,"Margen bajo",IF(I37<MargenObjReal,"Aceptable","Rentable"))))) | N37: =IF(ISNUMBER(W37),RANK(W37,$W$7:$W$206),"") | W37: =IF(AND(C37<>"",E37>0,F37>0),H37+ROW()/1000000000,"") | X37: =IF(AND(C37<>"",E37>0,F37>0,OR(CatSel="Todas",D37=CatSel)),H37+ROW()/1000000000,"")
G38: =IF(OR(C38="",E38<=0,DivMargen<=0),0,IF(Redondeo>0,CEILING(E38/DivMargen,Redondeo),E38/DivMargen)) | H38: =IF(OR(C38="",E38<=0,F38<=0),0,F38*DivBase-E38) | I38: =IF(OR(C38="",E38<=0,F38<=0),0,H38/F38) | K38: =IF(OR(C38="",E38<=0),0,E38*J38) | L38: =IF(OR(C38="",E38<=0),"",IF(F38<=0,"Sin precio",IF(H38<0,"PÉRDIDA",IF(I38<MargenMin,"Margen bajo",IF(I38<MargenObjReal,"Aceptable","Rentable"))))) | N38: =IF(ISNUMBER(W38),RANK(W38,$W$7:$W$206),"") | W38: =IF(AND(C38<>"",E38>0,F38>0),H38+ROW()/1000000000,"") | X38: =IF(AND(C38<>"",E38>0,F38>0,OR(CatSel="Todas",D38=CatSel)),H38+ROW()/1000000000,"")
G39: =IF(OR(C39="",E39<=0,DivMargen<=0),0,IF(Redondeo>0,CEILING(E39/DivMargen,Redondeo),E39/DivMargen)) | H39: =IF(OR(C39="",E39<=0,F39<=0),0,F39*DivBase-E39) | I39: =IF(OR(C39="",E39<=0,F39<=0),0,H39/F39) | K39: =IF(OR(C39="",E39<=0),0,E39*J39) | L39: =IF(OR(C39="",E39<=0),"",IF(F39<=0,"Sin precio",IF(H39<0,"PÉRDIDA",IF(I39<MargenMin,"Margen bajo",IF(I39<MargenObjReal,"Aceptable","Rentable"))))) | N39: =IF(ISNUMBER(W39),RANK(W39,$W$7:$W$206),"") | W39: =IF(AND(C39<>"",E39>0,F39>0),H39+ROW()/1000000000,"") | X39: =IF(AND(C39<>"",E39>0,F39>0,OR(CatSel="Todas",D39=CatSel)),H39+ROW()/1000000000,"")
G40: =IF(OR(C40="",E40<=0,DivMargen<=0),0,IF(Redondeo>0,CEILING(E40/DivMargen,Redondeo),E40/DivMargen)) | H40: =IF(OR(C40="",E40<=0,F40<=0),0,F40*DivBase-E40) | I40: =IF(OR(C40="",E40<=0,F40<=0),0,H40/F40) | K40: =IF(OR(C40="",E40<=0),0,E40*J40) | L40: =IF(OR(C40="",E40<=0),"",IF(F40<=0,"Sin precio",IF(H40<0,"PÉRDIDA",IF(I40<MargenMin,"Margen bajo",IF(I40<MargenObjReal,"Aceptable","Rentable"))))) | N40: =IF(ISNUMBER(W40),RANK(W40,$W$7:$W$206),"") | W40: =IF(AND(C40<>"",E40>0,F40>0),H40+ROW()/1000000000,"") | X40: =IF(AND(C40<>"",E40>0,F40>0,OR(CatSel="Todas",D40=CatSel)),H40+ROW()/1000000000,"")
G41: =IF(OR(C41="",E41<=0,DivMargen<=0),0,IF(Redondeo>0,CEILING(E41/DivMargen,Redondeo),E41/DivMargen)) | H41: =IF(OR(C41="",E41<=0,F41<=0),0,F41*DivBase-E41) | I41: =IF(OR(C41="",E41<=0,F41<=0),0,H41/F41) | K41: =IF(OR(C41="",E41<=0),0,E41*J41) | L41: =IF(OR(C41="",E41<=0),"",IF(F41<=0,"Sin precio",IF(H41<0,"PÉRDIDA",IF(I41<MargenMin,"Margen bajo",IF(I41<MargenObjReal,"Aceptable","Rentable"))))) | N41: =IF(ISNUMBER(W41),RANK(W41,$W$7:$W$206),"") | W41: =IF(AND(C41<>"",E41>0,F41>0),H41+ROW()/1000000000,"") | X41: =IF(AND(C41<>"",E41>0,F41>0,OR(CatSel="Todas",D41=CatSel)),H41+ROW()/1000000000,"")
G42: =IF(OR(C42="",E42<=0,DivMargen<=0),0,IF(Redondeo>0,CEILING(E42/DivMargen,Redondeo),E42/DivMargen)) | H42: =IF(OR(C42="",E42<=0,F42<=0),0,F42*DivBase-E42) | I42: =IF(OR(C42="",E42<=0,F42<=0),0,H42/F42) | K42: =IF(OR(C42="",E42<=0),0,E42*J42) | L42: =IF(OR(C42="",E42<=0),"",IF(F42<=0,"Sin precio",IF(H42<0,"PÉRDIDA",IF(I42<MargenMin,"Margen bajo",IF(I42<MargenObjReal,"Aceptable","Rentable"))))) | N42: =IF(ISNUMBER(W42),RANK(W42,$W$7:$W$206),"") | W42: =IF(AND(C42<>"",E42>0,F42>0),H42+ROW()/1000000000,"") | X42: =IF(AND(C42<>"",E42>0,F42>0,OR(CatSel="Todas",D42=CatSel)),H42+ROW()/1000000000,"")
G43: =IF(OR(C43="",E43<=0,DivMargen<=0),0,IF(Redondeo>0,CEILING(E43/DivMargen,Redondeo),E43/DivMargen)) | H43: =IF(OR(C43="",E43<=0,F43<=0),0,F43*DivBase-E43) | I43: =IF(OR(C43="",E43<=0,F43<=0),0,H43/F43) | K43: =IF(OR(C43="",E43<=0),0,E43*J43) | L43: =IF(OR(C43="",E43<=0),"",IF(F43<=0,"Sin precio",IF(H43<0,"PÉRDIDA",IF(I43<MargenMin,"Margen bajo",IF(I43<MargenObjReal,"Aceptable","Rentable"))))) | N43: =IF(ISNUMBER(W43),RANK(W43,$W$7:$W$206),"") | W43: =IF(AND(C43<>"",E43>0,F43>0),H43+ROW()/1000000000,"") | X43: =IF(AND(C43<>"",E43>0,F43>0,OR(CatSel="Todas",D43=CatSel)),H43+ROW()/1000000000,"")
G44: =IF(OR(C44="",E44<=0,DivMargen<=0),0,IF(Redondeo>0,CEILING(E44/DivMargen,Redondeo),E44/DivMargen)) | H44: =IF(OR(C44="",E44<=0,F44<=0),0,F44*DivBase-E44) | I44: =IF(OR(C44="",E44<=0,F44<=0),0,H44/F44) | K44: =IF(OR(C44="",E44<=0),0,E44*J44) | L44: =IF(OR(C44="",E44<=0),"",IF(F44<=0,"Sin precio",IF(H44<0,"PÉRDIDA",IF(I44<MargenMin,"Margen bajo",IF(I44<MargenObjReal,"Aceptable","Rentable"))))) | N44: =IF(ISNUMBER(W44),RANK(W44,$W$7:$W$206),"") | W44: =IF(AND(C44<>"",E44>0,F44>0),H44+ROW()/1000000000,"") | X44: =IF(AND(C44<>"",E44>0,F44>0,OR(CatSel="Todas",D44=CatSel)),H44+ROW()/1000000000,"")
G45: =IF(OR(C45="",E45<=0,DivMargen<=0),0,IF(Redondeo>0,CEILING(E45/DivMargen,Redondeo),E45/DivMargen)) | H45: =IF(OR(C45="",E45<=0,F45<=0),0,F45*DivBase-E45) | I45: =IF(OR(C45="",E45<=0,F45<=0),0,H45/F45) | K45: =IF(OR(C45="",E45<=0),0,E45*J45) | L45: =IF(OR(C45="",E45<=0),"",IF(F45<=0,"Sin precio",IF(H45<0,"PÉRDIDA",IF(I45<MargenMin,"Margen bajo",IF(I45<MargenObjReal,"Aceptable","Rentable"))))) | N45: =IF(ISNUMBER(W45),RANK(W45,$W$7:$W$206),"") | W45: =IF(AND(C45<>"",E45>0,F45>0),H45+ROW()/1000000000,"") | X45: =IF(AND(C45<>"",E45>0,F45>0,OR(CatSel="Todas",D45=CatSel)),H45+ROW()/1000000000,"")
G46: =IF(OR(C46="",E46<=0,DivMargen<=0),0,IF(Redondeo>0,CEILING(E46/DivMargen,Redondeo),E46/DivMargen)) | H46: =IF(OR(C46="",E46<=0,F46<=0),0,F46*DivBase-E46) | I46: =IF(OR(C46="",E46<=0,F46<=0),0,H46/F46) | K46: =IF(OR(C46="",E46<=0),0,E46*J46) | L46: =IF(OR(C46="",E46<=0),"",IF(F46<=0,"Sin precio",IF(H46<0,"PÉRDIDA",IF(I46<MargenMin,"Margen bajo",IF(I46<MargenObjReal,"Aceptable","Rentable"))))) | N46: =IF(ISNUMBER(W46),RANK(W46,$W$7:$W$206),"") | W46: =IF(AND(C46<>"",E46>0,F46>0),H46+ROW()/1000000000,"") | X46: =IF(AND(C46<>"",E46>0,F46>0,OR(CatSel="Todas",D46=CatSel)),H46+ROW()/1000000000,"")
G47: =IF(OR(C47="",E47<=0,DivMargen<=0),0,IF(Redondeo>0,CEILING(E47/DivMargen,Redondeo),E47/DivMargen)) | H47: =IF(OR(C47="",E47<=0,F47<=0),0,F47*DivBase-E47) | I47: =IF(OR(C47="",E47<=0,F47<=0),0,H47/F47) | K47: =IF(OR(C47="",E47<=0),0,E47*J47) | L47: =IF(OR(C47="",E47<=0),"",IF(F47<=0,"Sin precio",IF(H47<0,"PÉRDIDA",IF(I47<MargenMin,"Margen bajo",IF(I47<MargenObjReal,"Aceptable","Rentable"))))) | N47: =IF(ISNUMBER(W47),RANK(W47,$W$7:$W$206),"") | W47: =IF(AND(C47<>"",E47>0,F47>0),H47+ROW()/1000000000,"") | X47: =IF(AND(C47<>"",E47>0,F47>0,OR(CatSel="Todas",D47=CatSel)),H47+ROW()/1000000000,"")
G48: =IF(OR(C48="",E48<=0,DivMargen<=0),0,IF(Redondeo>0,CEILING(E48/DivMargen,Redondeo),E48/DivMargen)) | H48: =IF(OR(C48="",E48<=0,F48<=0),0,F48*DivBase-E48) | I48: =IF(OR(C48="",E48<=0,F48<=0),0,H48/F48) | K48: =IF(OR(C48="",E48<=0),0,E48*J48) | L48: =IF(OR(C48="",E48<=0),"",IF(F48<=0,"Sin precio",IF(H48<0,"PÉRDIDA",IF(I48<MargenMin,"Margen bajo",IF(I48<MargenObjReal,"Aceptable","Rentable"))))) | N48: =IF(ISNUMBER(W48),RANK(W48,$W$7:$W$206),"") | W48: =IF(AND(C48<>"",E48>0,F48>0),H48+ROW()/1000000000,"") | X48: =IF(AND(C48<>"",E48>0,F48>0,OR(CatSel="Todas",D48=CatSel)),H48+ROW()/1000000000,"")
... G206: =IF(OR(C206="",E206<=0,DivMargen<=0),0,IF(Redondeo>0,CEILING(E206/DivMargen,Redondeo),E206/DivMargen)) | H206: =IF(OR(C206="",E206<=0,F206<=0),0,F206*DivBase-E206) | I206: =IF(OR(C206="",E206<=0,F206<=0),0,H206/F206) | K206: =IF(OR(C206="",E206<=0),0,E206*J206) | L206: =IF(OR(C206="",E206<=0),"",IF(F206<=0,"Sin precio",IF(H206<0,"PÉRDIDA",IF(I206<MargenMin,"Margen bajo",IF(I206<MargenObjReal,"Aceptable","Rentable"))))) | N206: =IF(ISNUMBER(W206),RANK(W206,$W$7:$W$206),"") | W206: =IF(AND(C206<>"",E206>0,F206>0),H206+ROW()/1000000000,"") | X206: =IF(AND(C206<>"",E206>0,F206>0,OR(CatSel="Todas",D206=CatSel)),H206+ROW()/1000000000,"")
B209: MIX SHOP DIGITAL · Herramientas inteligentes que simplifican tu vida.
B210: Versión gratuita · Para gestionar todo tu negocio en un solo lugar, conocé Mi Negocio PY → mixshopdigital.com.py

Sheet COSTOS Y GASTOS
B1: MIX SHOP DIGITAL | E1: COSTOS Y GASTOS
B2: Herramientas inteligentes que simplifican tu vida. | E2: Los gastos que casi todos olvidan
B4: ← INICIO | C4: Completá solamente las celdas resaltadas. Cargá cada gasto y elegí cómo se reparte entre tus unidades vendidas.
B5: TOTAL DE GASTOS (EQUIVALENTE MENSUAL) | D5: COSTOS FIJOS | F5: COSTOS VARIABLES | H5: COSTO FIJO ASIGNADO POR UNIDAD
B6: =SUM(G13:G42) | D6: =SUMIFS(G13:G42,D13:D42,"Fijo") | F6: =SUMIFS(G13:G42,D13:D42,"Variable") | H6: =IF(N(C9)>0,SUMIFS(G13:G42,D13:D42,"Fijo",H13:H42,"Por unidad vendida")/C9,0)
B7: ="por mes · "&Moneda | D7: no cambian con las ventas | F7: cambian con las ventas | H7: se suma en la CALCULADORA si elegís «Sí»
B8: ="Directos: "&FIXED(SUMIFS(G13:G42,C13:C42,"Directo"),0)&" · Indirectos: "&FIXED(SUMIFS(G13:G42,C13:C42,"Indirecto"),0)&" "&Moneda
B9: Unidades estimadas a vender por mes | C9: 100 | D9: ← Sirve para repartir los costos fijos. Solo se reparten los fijos marcados «Por unidad vendida».
B10: Nota: los costos variables por unidad (envío, empaque, comisiones) se cargan directamente en la CALCULADORA.
B11: REGISTRO DE GASTOS
B12: Concepto del gasto | C12: Tipo | D12: Comportamiento | E12: Monto | F12: Periodicidad | G12: Equivalente mensual | H12: Criterio de asignación | I12: Observaciones
B13: Alquiler del local | C13: Indirecto | D13: Fijo | E13: 1500000 | F13: Mensual | G13: =IF(N(E13)<=0,0,IF(F13="",E13,IFERROR(E13*CHOOSE(MATCH(F13,{"Diaria","Semanal","Mensual","Trimestral","Semestral","Anual"},0),30,52/12,1,1/3,1/6,1/12),E13))) | H13: Por unidad vendida | I13: Ejemplo
B14: Servicios (luz, agua, internet) | C14: Indirecto | D14: Fijo | E14: 450000 | F14: Mensual | G14: =IF(N(E14)<=0,0,IF(F14="",E14,IFERROR(E14*CHOOSE(MATCH(F14,{"Diaria","Semanal","Mensual","Trimestral","Semestral","Anual"},0),30,52/12,1,1/3,1/6,1/12),E14))) | H14: Por unidad vendida | I14: Ejemplo
B15: Mano de obra | C15: Directo | D15: Fijo | E15: 2200000 | F15: Mensual | G15: =IF(N(E15)<=0,0,IF(F15="",E15,IFERROR(E15*CHOOSE(MATCH(F15,{"Diaria","Semanal","Mensual","Trimestral","Semestral","Anual"},0),30,52/12,1,1/3,1/6,1/12),E15))) | H15: Por unidad vendida | I15: Ejemplo
B16: Publicidad | C16: Indirecto | D16: Variable | E16: 300000 | F16: Mensual | G16: =IF(N(E16)<=0,0,IF(F16="",E16,IFERROR(E16*CHOOSE(MATCH(F16,{"Diaria","Semanal","Mensual","Trimestral","Semestral","Anual"},0),30,52/12,1,1/3,1/6,1/12),E16))) | H16: No asignar | I16: Ejemplo
B17: Medios de pago | C17: Directo | D17: Variable | E17: 120000 | F17: Mensual | G17: =IF(N(E17)<=0,0,IF(F17="",E17,IFERROR(E17*CHOOSE(MATCH(F17,{"Diaria","Semanal","Mensual","Trimestral","Semestral","Anual"},0),30,52/12,1,1/3,1/6,1/12),E17))) | H17: No asignar | I17: Ya considerados como % en la comisión
B18: Transporte de compra | C18: Directo | D18: Variable | E18: 150000 | F18: Mensual | G18: =IF(N(E18)<=0,0,IF(F18="",E18,IFERROR(E18*CHOOSE(MATCH(F18,{"Diaria","Semanal","Mensual","Trimestral","Semestral","Anual"},0),30,52/12,1,1/3,1/6,1/12),E18))) | H18: No asignar | I18: Ejemplo
G19: =IF(N(E19)<=0,0,IF(F19="",E19,IFERROR(E19*CHOOSE(MATCH(F19,{"Diaria","Semanal","Mensual","Trimestral","Semestral","Anual"},0),30,52/12,1,1/3,1/6,1/12),E19)))
G20: =IF(N(E20)<=0,0,IF(F20="",E20,IFERROR(E20*CHOOSE(MATCH(F20,{"Diaria","Semanal","Mensual","Trimestral","Semestral","Anual"},0),30,52/12,1,1/3,1/6,1/12),E20)))
G21: =IF(N(E21)<=0,0,IF(F21="",E21,IFERROR(E21*CHOOSE(MATCH(F21,{"Diaria","Semanal","Mensual","Trimestral","Semestral","Anual"},0),30,52/12,1,1/3,1/6,1/12),E21)))
G22: =IF(N(E22)<=0,0,IF(F22="",E22,IFERROR(E22*CHOOSE(MATCH(F22,{"Diaria","Semanal","Mensual","Trimestral","Semestral","Anual"},0),30,52/12,1,1/3,1/6,1/12),E22)))
G23: =IF(N(E23)<=0,0,IF(F23="",E23,IFERROR(E23*CHOOSE(MATCH(F23,{"Diaria","Semanal","Mensual","Trimestral","Semestral","Anual"},0),30,52/12,1,1/3,1/6,1/12),E23)))
G24: =IF(N(E24)<=0,0,IF(F24="",E24,IFERROR(E24*CHOOSE(MATCH(F24,{"Diaria","Semanal","Mensual","Trimestral","Semestral","Anual"},0),30,52/12,1,1/3,1/6,1/12),E24)))
G25: =IF(N(E25)<=0,0,IF(F25="",E25,IFERROR(E25*CHOOSE(MATCH(F25,{"Diaria","Semanal","Mensual","Trimestral","Semestral","Anual"},0),30,52/12,1,1/3,1/6,1/12),E25)))
G26: =IF(N(E26)<=0,0,IF(F26="",E26,IFERROR(E26*CHOOSE(MATCH(F26,{"Diaria","Semanal","Mensual","Trimestral","Semestral","Anual"},0),30,52/12,1,1/3,1/6,1/12),E26)))
G27: =IF(N(E27)<=0,0,IF(F27="",E27,IFERROR(E27*CHOOSE(MATCH(F27,{"Diaria","Semanal","Mensual","Trimestral","Semestral","Anual"},0),30,52/12,1,1/3,1/6,1/12),E27)))
G28: =IF(N(E28)<=0,0,IF(F28="",E28,IFERROR(E28*CHOOSE(MATCH(F28,{"Diaria","Semanal","Mensual","Trimestral","Semestral","Anual"},0),30,52/12,1,1/3,1/6,1/12),E28)))
G29: =IF(N(E29)<=0,0,IF(F29="",E29,IFERROR(E29*CHOOSE(MATCH(F29,{"Diaria","Semanal","Mensual","Trimestral","Semestral","Anual"},0),30,52/12,1,1/3,1/6,1/12),E29)))
G30: =IF(N(E30)<=0,0,IF(F30="",E30,IFERROR(E30*CHOOSE(MATCH(F30,{"Diaria","Semanal","Mensual","Trimestral","Semestral","Anual"},0),30,52/12,1,1/3,1/6,1/12),E30)))
... G42: =IF(N(E42)<=0,0,IF(F42="",E42,IFERROR(E42*CHOOSE(MATCH(F42,{"Diaria","Semanal","Mensual","Trimestral","Semestral","Anual"},0),30,52/12,1,1/3,1/6,1/12),E42)))
B45: MIX SHOP DIGITAL · Herramientas inteligentes que simplifican tu vida.
B46: Versión gratuita · Para gestionar todo tu negocio en un solo lugar, conocé Mi Negocio PY → mixshopdigital.com.py

Sheet SIMULADOR DE PRECIOS
B1: MIX SHOP DIGITAL | E1: SIMULADOR DE PRECIOS
B2: Herramientas inteligentes que simplifican tu vida. | E2: Probá escenarios y promociones antes de aplicarlos
B4: ← INICIO | C4: Completá solamente las celdas resaltadas. Los resultados se actualizan al instante.
B6: DATOS A SIMULAR | C6: Tu dato | D6: Se usa | F6: RESULTADO DE LA SIMULACIÓN
B7: Costo del producto (por unidad) | C7: 28500 | D7: =N(C7) | F7: Precio final (con descuento) | G7: =D8*(1-D9)
B8: Precio de venta | C8: 60000 | D8: =N(C8) | F8: Ganancia neta por unidad | G8: =G7*(1-D10-D11)-D7 | H8: =IF(D7<=0,"",IF(G8<0,"✖ Pérdida","✔ Ganancia"))
B9: Descuento a aplicar (%) | C9: 0.1 | D9: =IF(C9="",0,C9) | F9: Margen real sobre la venta | G9: =IF(G7=0,0,G8/G7) | H9: =IF(D7<=0,"",IF(G9<0,"✖ Pérdida",IF(G9<MargenMin,"⚠ Margen insuficiente","✔ Saludable")))
B10: Comisión (%) | D10: =IF(C10="",Comision,C10) | F10: Rentabilidad sobre el costo | G10: =IF(D7=0,0,G8/D7)
B11: Impuestos o retenciones (%) | D11: =IF(C11="",Impuesto,C11) | F11: Precio mínimo (sin pérdida) | G11: =IF(OR(D7<=0,1-D10-D11<=0),0,D7/(1-D10-D11))
B12: Margen deseado (%) | D12: =IF(C12="",MargenObj,C12) | F12: Precio para tu margen deseado | G12: =IF(D7<=0,0,IF(Metodo="Margen sobre venta",IF(1-D10-D11-D12<=0,0,D7/(1-D10-D11-D12)),IF(1-D10-D11<=0,0,D7*(1+D12)/(1-D10-D11))))
B13: Unidades a vender | C13: 100 | D13: =IF(C13="",0,C13) | F13: Ganancia total según unidades | G13: =G8*D13
B14: Si dejás vacíos comisión, impuestos o margen, se usan los valores de CONFIGURACIÓN.
B15: ="Método activo: "&Metodo
B17: ESCENARIOS: CONSERVADOR · RECOMENDADO · OPTIMISTA
B18: Escenario | C18: Ajuste de margen (puntos) | D18: Unidades estimadas | E18: Margen aplicado | F18: Precio de venta | G18: Ganancia neta por unidad | H18: Ganancia total | I18: Margen real | J18: Estado
B19: Conservador | C19: -0.1 | D19: 60 | E19: =MAX(0.005,$D$12+C19) | F19: =IF($D$7<=0,0,IF(Metodo="Margen sobre venta",IF(1-$D$10-$D$11-E19<=0,0,$D$7/(1-$D$10-$D$11-E19)),IF(1-$D$10-$D$11<=0,0,$D$7*(1+E19)/(1-$D$10-$D$11)))) | G19: =IF(F19=0,0,F19*(1-$D$10-$D$11)-$D$7) | H19: =G19*D19 | I19: =IF(F19=0,0,G19/F19) | J19: =IF(F19=0,"",IF(G19<0,"✖ Pérdida",IF(I19<MargenMin,"⚠ Margen bajo","✔ Rentable")))
B20: Recomendado | C20: 0 | D20: 100 | E20: =MAX(0.005,$D$12+C20) | F20: =IF($D$7<=0,0,IF(Metodo="Margen sobre venta",IF(1-$D$10-$D$11-E20<=0,0,$D$7/(1-$D$10-$D$11-E20)),IF(1-$D$10-$D$11<=0,0,$D$7*(1+E20)/(1-$D$10-$D$11)))) | G20: =IF(F20=0,0,F20*(1-$D$10-$D$11)-$D$7) | H20: =G20*D20 | I20: =IF(F20=0,0,G20/F20) | J20: =IF(F20=0,"",IF(G20<0,"✖ Pérdida",IF(I20<MargenMin,"⚠ Margen bajo","✔ Rentable")))
B21: Optimista | C21: 0.1 | D21: 140 | E21: =MAX(0.005,$D$12+C21) | F21: =IF($D$7<=0,0,IF(Metodo="Margen sobre venta",IF(1-$D$10-$D$11-E21<=0,0,$D$7/(1-$D$10-$D$11-E21)),IF(1-$D$10-$D$11<=0,0,$D$7*(1+E21)/(1-$D$10-$D$11)))) | G21: =IF(F21=0,0,F21*(1-$D$10-$D$11)-$D$7) | H21: =G21*D21 | I21: =IF(F21=0,0,G21/F21) | J21: =IF(F21=0,"",IF(G21<0,"✖ Pérdida",IF(I21<MargenMin,"⚠ Margen bajo","✔ Rentable")))
B39: SIMULADOR DE PROMOCIONES (sobre el precio de venta y costo de arriba)
B40: Promoción | C40: Dato 1 | D40: Dato 2 | E40: Unidades que recibe el cliente | F40: Qué representa cada dato | G40: Ingreso por compra | H40: Costo por compra | I40: Ganancia neta por compra | J40: ¿Sigue siendo rentable?
B41: Sin promoción (precio de lista) | C41: — | D41: — | E41: =1 | F41: — | G41: =D8 | H41: =$D$7*E41 | I41: =G41*(1-$D$10-$D$11)-H41 | J41: =IF(OR($D$7<=0,$D$8<=0),"",IF(G41=0,"Completá los datos",IF(I41<0,"✖ NO conviene: pérdida",IF(I41/G41<MargenMin,"⚠ Poco rentable","✔ Rentable"))))
B42: Descuento A | C42: 0.1 | D42: — | E42: =1 | F42: Dato 1 = % de descuento | G42: =IF(C42="",0,D8*(1-C42)) | H42: =$D$7*E42 | I42: =G42*(1-$D$10-$D$11)-H42 | J42: =IF(OR($D$7<=0,$D$8<=0),"",IF(G42=0,"Completá los datos",IF(I42<0,"✖ NO conviene: pérdida",IF(I42/G42<MargenMin,"⚠ Poco rentable","✔ Rentable"))))
B43: Descuento B | C43: 0.15 | D43: — | E43: =1 | F43: Dato 1 = % de descuento | G43: =IF(C43="",0,D8*(1-C43)) | H43: =$D$7*E43 | I43: =G43*(1-$D$10-$D$11)-H43 | J43: =IF(OR($D$7<=0,$D$8<=0),"",IF(G43=0,"Completá los datos",IF(I43<0,"✖ NO conviene: pérdida",IF(I43/G43<MargenMin,"⚠ Poco rentable","✔ Rentable"))))
B44: Descuento C | C44: 0.2 | D44: — | E44: =1 | F44: Dato 1 = % de descuento | G44: =IF(C44="",0,D8*(1-C44)) | H44: =$D$7*E44 | I44: =G44*(1-$D$10-$D$11)-H44 | J44: =IF(OR($D$7<=0,$D$8<=0),"",IF(G44=0,"Completá los datos",IF(I44<0,"✖ NO conviene: pérdida",IF(I44/G44<MargenMin,"⚠ Poco rentable","✔ Rentable"))))
B45: 2x1 (llevás 2, pagás 1) | C45: — | D45: — | E45: =2 | F45: Se cobra el precio de una unidad | G45: =D8 | H45: =$D$7*E45 | I45: =G45*(1-$D$10-$D$11)-H45 | J45: =IF(OR($D$7<=0,$D$8<=0),"",IF(G45=0,"Completá los datos",IF(I45<0,"✖ NO conviene: pérdida",IF(I45/G45<MargenMin,"⚠ Poco rentable","✔ Rentable"))))
B46: Combo | C46: 3 | D46: 150000 | E46: =IF(C46="",0,C46) | F46: Dato 1 = unidades · Dato 2 = precio del combo | G46: =IF(D46="",0,D46) | H46: =$D$7*E46 | I46: =G46*(1-$D$10-$D$11)-H46 | J46: =IF(OR($D$7<=0,$D$8<=0),"",IF(G46=0,"Completá los datos",IF(I46<0,"✖ NO conviene: pérdida",IF(I46/G46<MargenMin,"⚠ Poco rentable","✔ Rentable"))))
B47: Precio especial por cantidad | C47: 6 | D47: 50000 | E47: =IF(C47="",0,C47) | F47: Dato 1 = unidades · Dato 2 = precio por unidad | G47: =IF(OR(C47="",D47=""),0,C47*D47) | H47: =$D$7*E47 | I47: =G47*(1-$D$10-$D$11)-H47 | J47: =IF(OR($D$7<=0,$D$8<=0),"",IF(G47=0,"Completá los datos",IF(I47<0,"✖ NO conviene: pérdida",IF(I47/G47<MargenMin,"⚠ Poco rentable","✔ Rentable"))))
B48: El 2x1, el combo y el precio por cantidad se evalúan sobre el total de la compra: ingreso − costo de todas las unidades − comisión e impuestos.
B51: MIX SHOP DIGITAL · Herramientas inteligentes que simplifican tu vida.
B52: Versión gratuita · Para gestionar todo tu negocio en un solo lugar, conocé Mi Negocio PY → mixshopdigital.com.py

Sheet DASHBOARD
B1: MIX SHOP DIGITAL | F1: DASHBOARD
B2: Herramientas inteligentes que simplifican tu vida. | F2: Panel de control de tu negocio
B4: ← INICIO | C4: Se actualiza automáticamente con lo que cargás en el COMPARADOR, la CALCULADORA y el SIMULADOR. No hace falta escribir nada acá, salvo el filtro.
B6: Filtrar por categoría: | D6: Todas | F6: ← los indicadores y el ranking se filtran. (El filtro por período no aplica: la planilla no registra fechas.)
B8: PRODUCTOS REGISTRADOS | E8: INVERSIÓN TOTAL EN PRODUCTOS | H8: VALOR DEL INVENTARIO | K8: GANANCIA POTENCIAL
B9: =SUMPRODUCT(((('COMPARADOR DE PRODUCTOS'!$D$7:$D$206=CatSel)+(CatSel="Todas"))>0)*('COMPARADOR DE PRODUCTOS'!$C$7:$C$206<>"")*('COMPARADOR DE PRODUCTOS'!$E$7:$E$206>0)) | E9: =SUMPRODUCT(((('COMPARADOR DE PRODUCTOS'!$D$7:$D$206=CatSel)+(CatSel="Todas"))>0)*('COMPARADOR DE PRODUCTOS'!$C$7:$C$206<>"")*('COMPARADOR DE PRODUCTOS'!$E$7:$E$206>0)*'COMPARADOR DE PRODUCTOS'!$E$7:$E$206*'COMPARADOR DE PRODUCTOS'!$J$7:$J$206) | H9: =SUMPRODUCT(((('COMPARADOR DE PRODUCTOS'!$D$7:$D$206=CatSel)+(CatSel="Todas"))>0)*('COMPARADOR DE PRODUCTOS'!$C$7:$C$206<>"")*('COMPARADOR DE PRODUCTOS'!$E$7:$E$206>0)*'COMPARADOR DE PRODUCTOS'!$F$7:$F$206*'COMPARADOR DE PRODUCTOS'!$J$7:$J$206) | K9: =SUMPRODUCT(((('COMPARADOR DE PRODUCTOS'!$D$7:$D$206=CatSel)+(CatSel="Todas"))>0)*('COMPARADOR DE PRODUCTOS'!$C$7:$C$206<>"")*('COMPARADOR DE PRODUCTOS'!$E$7:$E$206>0)*'COMPARADOR DE PRODUCTOS'!$H$7:$H$206*'COMPARADOR DE PRODUCTOS'!$J$7:$J$206)
B10: en el comparador | E10: ="costo × stock · "&Moneda | H10: ="a precio de venta · "&Moneda | K10: ="neta, si vendés todo el stock · "&Moneda
B12: MARGEN PROMEDIO | E12: PRODUCTOS RENTABLES | H12: PRODUCTOS CON MARGEN BAJO | K12: PRODUCTOS CON PÉRDIDA
B13: =IFERROR(SUMPRODUCT(((('COMPARADOR DE PRODUCTOS'!$D$7:$D$206=CatSel)+(CatSel="Todas"))>0)*('COMPARADOR DE PRODUCTOS'!$C$7:$C$206<>"")*('COMPARADOR DE PRODUCTOS'!$E$7:$E$206>0)*('COMPARADOR DE PRODUCTOS'!$F$7:$F$206>0)*'COMPARADOR DE PRODUCTOS'!$I$7:$I$206)/SUMPRODUCT(((('COMPARADOR DE PRODUCTOS'!$D$7:$D$206=CatSel)+(CatSel="Todas"))>0)*('COMPARADOR DE PRODUCTOS'!$C$7:$C$206<>"")*('COMPARADOR DE PRODUCTOS'!$E$7:$E$206>0)*('COMPARADOR DE PRODUCTOS'!$F$7:$F$206>0)),0) | E13: =SUMPRODUCT(((('COMPARADOR DE PRODUCTOS'!$D$7:$D$206=CatSel)+(CatSel="Todas"))>0)*('COMPARADOR DE PRODUCTOS'!$C$7:$C$206<>"")*('COMPARADOR DE PRODUCTOS'!$E$7:$E$206>0)*(('COMPARADOR DE PRODUCTOS'!$L$7:$L$206="Rentable")+('COMPARADOR DE PRODUCTOS'!$L$7:$L$206="Aceptable"))) | H13: =SUMPRODUCT(((('COMPARADOR DE PRODUCTOS'!$D$7:$D$206=CatSel)+(CatSel="Todas"))>0)*('COMPARADOR DE PRODUCTOS'!$C$7:$C$206<>"")*('COMPARADOR DE PRODUCTOS'!$E$7:$E$206>0)*('COMPARADOR DE PRODUCTOS'!$L$7:$L$206="Margen bajo")) | K13: =SUMPRODUCT(((('COMPARADOR DE PRODUCTOS'!$D$7:$D$206=CatSel)+(CatSel="Todas"))>0)*('COMPARADOR DE PRODUCTOS'!$C$7:$C$206<>"")*('COMPARADOR DE PRODUCTOS'!$E$7:$E$206>0)*('COMPARADOR DE PRODUCTOS'!$L$7:$L$206="PÉRDIDA"))
B14: sobre precio de venta | E14: margen igual o mayor al mínimo | H14: ganan, pero menos del mínimo | K14: se venden por debajo del costo
B16: RANKING: LOS 10 PRODUCTOS CON MAYOR GANANCIA POR UNIDAD
B17: # | C17: Producto | D17: Costo | E17: Precio | F17: Ganancia por unidad | G17: Margen | H17: Estado
B18: =IF(ISNUMBER(F18),1,"") | C18: =IFERROR(INDEX('COMPARADOR DE PRODUCTOS'!$C$7:$C$206,MATCH(LARGE('COMPARADOR DE PRODUCTOS'!$X$7:$X$206,1),'COMPARADOR DE PRODUCTOS'!$X$7:$X$206,0)),"") | D18: =IFERROR(INDEX('COMPARADOR DE PRODUCTOS'!$E$7:$E$206,MATCH(LARGE('COMPARADOR DE PRODUCTOS'!$X$7:$X$206,1),'COMPARADOR DE PRODUCTOS'!$X$7:$X$206,0)),"") | E18: =IFERROR(INDEX('COMPARADOR DE PRODUCTOS'!$F$7:$F$206,MATCH(LARGE('COMPARADOR DE PRODUCTOS'!$X$7:$X$206,1),'COMPARADOR DE PRODUCTOS'!$X$7:$X$206,0)),"") | F18: =IFERROR(INDEX('COMPARADOR DE PRODUCTOS'!$H$7:$H$206,MATCH(LARGE('COMPARADOR DE PRODUCTOS'!$X$7:$X$206,1),'COMPARADOR DE PRODUCTOS'!$X$7:$X$206,0)),"") | G18: =IFERROR(INDEX('COMPARADOR DE PRODUCTOS'!$I$7:$I$206,MATCH(LARGE('COMPARADOR DE PRODUCTOS'!$X$7:$X$206,1),'COMPARADOR DE PRODUCTOS'!$X$7:$X$206,0)),"") | H18: =IFERROR(INDEX('COMPARADOR DE PRODUCTOS'!$L$7:$L$206,MATCH(LARGE('COMPARADOR DE PRODUCTOS'!$X$7:$X$206,1),'COMPARADOR DE PRODUCTOS'!$X$7:$X$206,0)),"") | J18: Cómo leer el ranking:
B19: =IF(ISNUMBER(F19),2,"") | C19: =IFERROR(INDEX('COMPARADOR DE PRODUCTOS'!$C$7:$C$206,MATCH(LARGE('COMPARADOR DE PRODUCTOS'!$X$7:$X$206,2),'COMPARADOR DE PRODUCTOS'!$X$7:$X$206,0)),"") | D19: =IFERROR(INDEX('COMPARADOR DE PRODUCTOS'!$E$7:$E$206,MATCH(LARGE('COMPARADOR DE PRODUCTOS'!$X$7:$X$206,2),'COMPARADOR DE PRODUCTOS'!$X$7:$X$206,0)),"") | E19: =IFERROR(INDEX('COMPARADOR DE PRODUCTOS'!$F$7:$F$206,MATCH(LARGE('COMPARADOR DE PRODUCTOS'!$X$7:$X$206,2),'COMPARADOR DE PRODUCTOS'!$X$7:$X$206,0)),"") | F19: =IFERROR(INDEX('COMPARADOR DE PRODUCTOS'!$H$7:$H$206,MATCH(LARGE('COMPARADOR DE PRODUCTOS'!$X$7:$X$206,2),'COMPARADOR DE PRODUCTOS'!$X$7:$X$206,0)),"") | G19: =IFERROR(INDEX('COMPARADOR DE PRODUCTOS'!$I$7:$I$206,MATCH(LARGE('COMPARADOR DE PRODUCTOS'!$X$7:$X$206,2),'COMPARADOR DE PRODUCTOS'!$X$7:$X$206,0)),"") | H19: =IFERROR(INDEX('COMPARADOR DE PRODUCTOS'!$L$7:$L$206,MATCH(LARGE('COMPARADOR DE PRODUCTOS'!$X$7:$X$206,2),'COMPARADOR DE PRODUCTOS'!$X$7:$X$206,0)),"") | J19: Los productos de arriba son los que más dinero te dejan por cada unidad vendida. Revisá los de abajo: si están cerca del costo, conviene subir el precio o bajar el costo.
B20: =IF(ISNUMBER(F20),3,"") | C20: =IFERROR(INDEX('COMPARADOR DE PRODUCTOS'!$C$7:$C$206,MATCH(LARGE('COMPARADOR DE PRODUCTOS'!$X$7:$X$206,3),'COMPARADOR DE PRODUCTOS'!$X$7:$X$206,0)),"") | D20: =IFERROR(INDEX('COMPARADOR DE PRODUCTOS'!$E$7:$E$206,MATCH(LARGE('COMPARADOR DE PRODUCTOS'!$X$7:$X$206,3),'COMPARADOR DE PRODUCTOS'!$X$7:$X$206,0)),"") | E20: =IFERROR(INDEX('COMPARADOR DE PRODUCTOS'!$F$7:$F$206,MATCH(LARGE('COMPARADOR DE PRODUCTOS'!$X$7:$X$206,3),'COMPARADOR DE PRODUCTOS'!$X$7:$X$206,0)),"") | F20: =IFERROR(INDEX('COMPARADOR DE PRODUCTOS'!$H$7:$H$206,MATCH(LARGE('COMPARADOR DE PRODUCTOS'!$X$7:$X$206,3),'COMPARADOR DE PRODUCTOS'!$X$7:$X$206,0)),"") | G20: =IFERROR(INDEX('COMPARADOR DE PRODUCTOS'!$I$7:$I$206,MATCH(LARGE('COMPARADOR DE PRODUCTOS'!$X$7:$X$206,3),'COMPARADOR DE PRODUCTOS'!$X$7:$X$206,0)),"") | H20: =IFERROR(INDEX('COMPARADOR DE PRODUCTOS'!$L$7:$L$206,MATCH(LARGE('COMPARADOR DE PRODUCTOS'!$X$7:$X$206,3),'COMPARADOR DE PRODUCTOS'!$X$7:$X$206,0)),"")
B21: =IF(ISNUMBER(F21),4,"") | C21: =IFERROR(INDEX('COMPARADOR DE PRODUCTOS'!$C$7:$C$206,MATCH(LARGE('COMPARADOR DE PRODUCTOS'!$X$7:$X$206,4),'COMPARADOR DE PRODUCTOS'!$X$7:$X$206,0)),"") | D21: =IFERROR(INDEX('COMPARADOR DE PRODUCTOS'!$E$7:$E$206,MATCH(LARGE('COMPARADOR DE PRODUCTOS'!$X$7:$X$206,4),'COMPARADOR DE PRODUCTOS'!$X$7:$X$206,0)),"") | E21: =IFERROR(INDEX('COMPARADOR DE PRODUCTOS'!$F$7:$F$206,MATCH(LARGE('COMPARADOR DE PRODUCTOS'!$X$7:$X$206,4),'COMPARADOR DE PRODUCTOS'!$X$7:$X$206,0)),"") | F21: =IFERROR(INDEX('COMPARADOR DE PRODUCTOS'!$H$7:$H$206,MATCH(LARGE('COMPARADOR DE PRODUCTOS'!$X$7:$X$206,4),'COMPARADOR DE PRODUCTOS'!$X$7:$X$206,0)),"") | G21: =IFERROR(INDEX('COMPARADOR DE PRODUCTOS'!$I$7:$I$206,MATCH(LARGE('COMPARADOR DE PRODUCTOS'!$X$7:$X$206,4),'COMPARADOR DE PRODUCTOS'!$X$7:$X$206,0)),"") | H21: =IFERROR(INDEX('COMPARADOR DE PRODUCTOS'!$L$7:$L$206,MATCH(LARGE('COMPARADOR DE PRODUCTOS'!$X$7:$X$206,4),'COMPARADOR DE PRODUCTOS'!$X$7:$X$206,0)),"")
B22: =IF(ISNUMBER(F22),5,"") | C22: =IFERROR(INDEX('COMPARADOR DE PRODUCTOS'!$C$7:$C$206,MATCH(LARGE('COMPARADOR DE PRODUCTOS'!$X$7:$X$206,5),'COMPARADOR DE PRODUCTOS'!$X$7:$X$206,0)),"") | D22: =IFERROR(INDEX('COMPARADOR DE PRODUCTOS'!$E$7:$E$206,MATCH(LARGE('COMPARADOR DE PRODUCTOS'!$X$7:$X$206,5),'COMPARADOR DE PRODUCTOS'!$X$7:$X$206,0)),"") | E22: =IFERROR(INDEX('COMPARADOR DE PRODUCTOS'!$F$7:$F$206,MATCH(LARGE('COMPARADOR DE PRODUCTOS'!$X$7:$X$206,5),'COMPARADOR DE PRODUCTOS'!$X$7:$X$206,0)),"") | F22: =IFERROR(INDEX('COMPARADOR DE PRODUCTOS'!$H$7:$H$206,MATCH(LARGE('COMPARADOR DE PRODUCTOS'!$X$7:$X$206,5),'COMPARADOR DE PRODUCTOS'!$X$7:$X$206,0)),"") | G22: =IFERROR(INDEX('COMPARADOR DE PRODUCTOS'!$I$7:$I$206,MATCH(LARGE('COMPARADOR DE PRODUCTOS'!$X$7:$X$206,5),'COMPARADOR DE PRODUCTOS'!$X$7:$X$206,0)),"") | H22: =IFERROR(INDEX('COMPARADOR DE PRODUCTOS'!$L$7:$L$206,MATCH(LARGE('COMPARADOR DE PRODUCTOS'!$X$7:$X$206,5),'COMPARADOR DE PRODUCTOS'!$X$7:$X$206,0)),"")
B23: =IF(ISNUMBER(F23),6,"") | C23: =IFERROR(INDEX('COMPARADOR DE PRODUCTOS'!$C$7:$C$206,MATCH(LARGE('COMPARADOR DE PRODUCTOS'!$X$7:$X$206,6),'COMPARADOR DE PRODUCTOS'!$X$7:$X$206,0)),"") | D23: =IFERROR(INDEX('COMPARADOR DE PRODUCTOS'!$E$7:$E$206,MATCH(LARGE('COMPARADOR DE PRODUCTOS'!$X$7:$X$206,6),'COMPARADOR DE PRODUCTOS'!$X$7:$X$206,0)),"") | E23: =IFERROR(INDEX('COMPARADOR DE PRODUCTOS'!$F$7:$F$206,MATCH(LARGE('COMPARADOR DE PRODUCTOS'!$X$7:$X$206,6),'COMPARADOR DE PRODUCTOS'!$X$7:$X$206,0)),"") | F23: =IFERROR(INDEX('COMPARADOR DE PRODUCTOS'!$H$7:$H$206,MATCH(LARGE('COMPARADOR DE PRODUCTOS'!$X$7:$X$206,6),'COMPARADOR DE PRODUCTOS'!$X$7:$X$206,0)),"") | G23: =IFERROR(INDEX('COMPARADOR DE PRODUCTOS'!$I$7:$I$206,MATCH(LARGE('COMPARADOR DE PRODUCTOS'!$X$7:$X$206,6),'COMPARADOR DE PRODUCTOS'!$X$7:$X$206,0)),"") | H23: =IFERROR(INDEX('COMPARADOR DE PRODUCTOS'!$L$7:$L$206,MATCH(LARGE('COMPARADOR DE PRODUCTOS'!$X$7:$X$206,6),'COMPARADOR DE PRODUCTOS'!$X$7:$X$206,0)),"")
B24: =IF(ISNUMBER(F24),7,"") | C24: =IFERROR(INDEX('COMPARADOR DE PRODUCTOS'!$C$7:$C$206,MATCH(LARGE('COMPARADOR DE PRODUCTOS'!$X$7:$X$206,7),'COMPARADOR DE PRODUCTOS'!$X$7:$X$206,0)),"") | D24: =IFERROR(INDEX('COMPARADOR DE PRODUCTOS'!$E$7:$E$206,MATCH(LARGE('COMPARADOR DE PRODUCTOS'!$X$7:$X$206,7),'COMPARADOR DE PRODUCTOS'!$X$7:$X$206,0)),"") | E24: =IFERROR(INDEX('COMPARADOR DE PRODUCTOS'!$F$7:$F$206,MATCH(LARGE('COMPARADOR DE PRODUCTOS'!$X$7:$X$206,7),'COMPARADOR DE PRODUCTOS'!$X$7:$X$206,0)),"") | F24: =IFERROR(INDEX('COMPARADOR DE PRODUCTOS'!$H$7:$H$206,MATCH(LARGE('COMPARADOR DE PRODUCTOS'!$X$7:$X$206,7),'COMPARADOR DE PRODUCTOS'!$X$7:$X$206,0)),"") | G24: =IFERROR(INDEX('COMPARADOR DE PRODUCTOS'!$I$7:$I$206,MATCH(LARGE('COMPARADOR DE PRODUCTOS'!$X$7:$X$206,7),'COMPARADOR DE PRODUCTOS'!$X$7:$X$206,0)),"") | H24: =IFERROR(INDEX('COMPARADOR DE PRODUCTOS'!$L$7:$L$206,MATCH(LARGE('COMPARADOR DE PRODUCTOS'!$X$7:$X$206,7),'COMPARADOR DE PRODUCTOS'!$X$7:$X$206,0)),"")
B25: =IF(ISNUMBER(F25),8,"") | C25: =IFERROR(INDEX('COMPARADOR DE PRODUCTOS'!$C$7:$C$206,MATCH(LARGE('COMPARADOR DE PRODUCTOS'!$X$7:$X$206,8),'COMPARADOR DE PRODUCTOS'!$X$7:$X$206,0)),"") | D25: =IFERROR(INDEX('COMPARADOR DE PRODUCTOS'!$E$7:$E$206,MATCH(LARGE('COMPARADOR DE PRODUCTOS'!$X$7:$X$206,8),'COMPARADOR DE PRODUCTOS'!$X$7:$X$206,0)),"") | E25: =IFERROR(INDEX('COMPARADOR DE PRODUCTOS'!$F$7:$F$206,MATCH(LARGE('COMPARADOR DE PRODUCTOS'!$X$7:$X$206,8),'COMPARADOR DE PRODUCTOS'!$X$7:$X$206,0)),"") | F25: =IFERROR(INDEX('COMPARADOR DE PRODUCTOS'!$H$7:$H$206,MATCH(LARGE('COMPARADOR DE PRODUCTOS'!$X$7:$X$206,8),'COMPARADOR DE PRODUCTOS'!$X$7:$X$206,0)),"") | G25: =IFERROR(INDEX('COMPARADOR DE PRODUCTOS'!$I$7:$I$206,MATCH(LARGE('COMPARADOR DE PRODUCTOS'!$X$7:$X$206,8),'COMPARADOR DE PRODUCTOS'!$X$7:$X$206,0)),"") | H25: =IFERROR(INDEX('COMPARADOR DE PRODUCTOS'!$L$7:$L$206,MATCH(LARGE('COMPARADOR DE PRODUCTOS'!$X$7:$X$206,8),'COMPARADOR DE PRODUCTOS'!$X$7:$X$206,0)),"")
B26: =IF(ISNUMBER(F26),9,"") | C26: =IFERROR(INDEX('COMPARADOR DE PRODUCTOS'!$C$7:$C$206,MATCH(LARGE('COMPARADOR DE PRODUCTOS'!$X$7:$X$206,9),'COMPARADOR DE PRODUCTOS'!$X$7:$X$206,0)),"") | D26: =IFERROR(INDEX('COMPARADOR DE PRODUCTOS'!$E$7:$E$206,MATCH(LARGE('COMPARADOR DE PRODUCTOS'!$X$7:$X$206,9),'COMPARADOR DE PRODUCTOS'!$X$7:$X$206,0)),"") | E26: =IFERROR(INDEX('COMPARADOR DE PRODUCTOS'!$F$7:$F$206,MATCH(LARGE('COMPARADOR DE PRODUCTOS'!$X$7:$X$206,9),'COMPARADOR DE PRODUCTOS'!$X$7:$X$206,0)),"") | F26: =IFERROR(INDEX('COMPARADOR DE PRODUCTOS'!$H$7:$H$206,MATCH(LARGE('COMPARADOR DE PRODUCTOS'!$X$7:$X$206,9),'COMPARADOR DE PRODUCTOS'!$X$7:$X$206,0)),"") | G26: =IFERROR(INDEX('COMPARADOR DE PRODUCTOS'!$I$7:$I$206,MATCH(LARGE('COMPARADOR DE PRODUCTOS'!$X$7:$X$206,9),'COMPARADOR DE PRODUCTOS'!$X$7:$X$206,0)),"") | H26: =IFERROR(INDEX('COMPARADOR DE PRODUCTOS'!$L$7:$L$206,MATCH(LARGE('COMPARADOR DE PRODUCTOS'!$X$7:$X$206,9),'COMPARADOR DE PRODUCTOS'!$X$7:$X$206,0)),"")
B27: =IF(ISNUMBER(F27),10,"") | C27: =IFERROR(INDEX('COMPARADOR DE PRODUCTOS'!$C$7:$C$206,MATCH(LARGE('COMPARADOR DE PRODUCTOS'!$X$7:$X$206,10),'COMPARADOR DE PRODUCTOS'!$X$7:$X$206,0)),"") | D27: =IFERROR(INDEX('COMPARADOR DE PRODUCTOS'!$E$7:$E$206,MATCH(LARGE('COMPARADOR DE PRODUCTOS'!$X$7:$X$206,10),'COMPARADOR DE PRODUCTOS'!$X$7:$X$206,0)),"") | E27: =IFERROR(INDEX('COMPARADOR DE PRODUCTOS'!$F$7:$F$206,MATCH(LARGE('COMPARADOR DE PRODUCTOS'!$X$7:$X$206,10),'COMPARADOR DE PRODUCTOS'!$X$7:$X$206,0)),"") | F27: =IFERROR(INDEX('COMPARADOR DE PRODUCTOS'!$H$7:$H$206,MATCH(LARGE('COMPARADOR DE PRODUCTOS'!$X$7:$X$206,10),'COMPARADOR DE PRODUCTOS'!$X$7:$X$206,0)),"") | G27: =IFERROR(INDEX('COMPARADOR DE PRODUCTOS'!$I$7:$I$206,MATCH(LARGE('COMPARADOR DE PRODUCTOS'!$X$7:$X$206,10),'COMPARADOR DE PRODUCTOS'!$X$7:$X$206,0)),"") | H27: =IFERROR(INDEX('COMPARADOR DE PRODUCTOS'!$L$7:$L$206,MATCH(LARGE('COMPARADOR DE PRODUCTOS'!$X$7:$X$206,10),'COMPARADOR DE PRODUCTOS'!$X$7:$X$206,0)),"")
B29: GRÁFICOS PARA DECIDIR
H62: 6. Ranking de productos más rentables: tabla de arriba (se actualiza sola).
H64: ="El gráfico 5 usa los escenarios del SIMULADOR DE PRECIOS. El gráfico 4 muestra de qué se compone el costo del producto que estás analizando en la CALCULADORA."
B79: MIX SHOP DIGITAL · Herramientas inteligentes que simplifican tu vida.
B80: Versión gratuita · Para gestionar todo tu negocio en un solo lugar, conocé Mi Negocio PY → mixshopdigital.com.py

Sheet GUÍA DE USO
B1: MIX SHOP DIGITAL | E1: GUÍA DE USO
B2: Herramientas inteligentes que simplifican tu vida. | E2: Aprendé a usarla en 5 minutos
B4: ← INICIO | C4: Leé esta hoja una vez. Después ya no la vas a necesitar.
B6: ¿PARA QUÉ SIRVE?
B7: Esta herramienta te dice cuánto te cuesta realmente vender un producto, cuál es el precio mínimo para no perder dinero, qué precio te conviene poner y cuánto ganás por unidad. Funciona sin Internet y no necesitás saber Excel.
B9: EMPEZÁ EN 3 PASOS
B10: 1) En CONFIGURACIÓN, completá los datos de tu negocio y tus porcentajes habituales (comisión, impuestos, margen que querés ganar).
B11: 2) En CALCULADORA, cargá un producto: cuánto pagaste, cuántas unidades compraste y tus costos de envío, empaque y otros. Los resultados aparecen solos arriba y a la derecha.
B12: 3) En COMPARADOR cargá todos tus productos y mirá el DASHBOARD para saber cuáles te dejan más ganancia y cuáles te hacen perder.
B14: COLORES
B15: Azul claro: celdas que completás vos. Gris: información automática (bloqueada). Naranja: advertencia. Verde: resultado favorable. Rojo: pérdida o precio por debajo del costo.
B16: Completá solamente las celdas resaltadas en azul claro. El resto está protegido para que no borres fórmulas sin querer.
B18: MARGEN Y RECARGO: NO SON LO MISMO
B19: Margen sobre venta: qué parte del precio final es ganancia. Recargo sobre costo (markup): cuánto le sumás al costo. Ejemplo con costo de 100: un recargo del 30 % da un precio de 130 y un margen real de 23,1 %. Para ganar 30 % de margen real, el precio debe ser 142,86 (recargo de 42,9 %).
B20: Por eso la planilla calcula con una fórmula exacta y no «suma porcentajes al costo». Podés elegir el método en CONFIGURACIÓN (recomendado: margen sobre venta).
... B51: Versión gratuita · Para gestionar todo tu negocio en un solo lugar, conocé Mi Negocio PY → mixshopdigital.com.py
